[META]
version=2.0
spawnOnBlockType=3,2
spawnSunlight=True
spawnDarkness=True
spawnWater=False
spawnLava=False
underFill=True
randomRotation=True
dig=True
tree=False
branch=False
needsFoundation=True
rarity=500
collisionPercentage=15
spawnElevationMin=0
spawnElevationMax=120
spawnInBiome=Urwald,Forest,Extremne Hills
[DATA]
0,0,0:17.1
-1,1,0:17.1
-1,-1,0:17.1
1,-1,0:17.1
1,1,0:17.1
0,0,1:17.1
0,0,2:17.1
0,2,2:106
0,0,3:17.1
0,2,3:106
0,0,4:17.1
0,-1,4:17.1
0,-2,4:17.1
0,2,4:106
-1,-2,4:18.1
1,-3,4:18.1
0,0,5:17.1
0,-2,5:17.1
0,2,5:106
-1,1,5:18.1
0,0,6:17.1
0,1,6:17.1
-1,2,6:17.1
0,2,6:106
-2,3,6:18.1
1,0,6:18.1
-1,-1,6:18.1
0,0,7:17.1
0,2,7:17.1
0,0,8:17.1
0,-1,8:18.1
-1,-2,8:18.1
0,0,9:17.1
1,-3,9:106
0,0,10:17.1
-1,-1,10:17.1
1,1,10:17.1
1,-1,10:17.1
2,-2,10:17.1
-2,-2,10:17.1
-1,1,10:17.1
-1,-3,10:18.1
-3,-1,10:18.1
3,-1,10:18.1
2,-3,10:18.1
1,2,10:18.1
-2,2,10:18.1
1,-3,10:106
0,0,11:17.1
-1,1,11:17.1
2,-2,11:17.1
2,2,11:17.1
-2,-2,11:17.1
-2,2,11:17.1
1,-3,11:106
-2,3,11:18.1
-2,2,12:17.1
-2,-2,12:17.1
2,-3,12:17.1
3,2,12:17.1
2,2,12:17.1
2,-2,12:17.1
-1,1,12:17.1
-3,-3,12:17.1
0,0,12:17.1
-2,-3,12:18.1
-1,0,12:18.1
1,-1,12:18.1
2,1,12:18.1
1,1,12:18.1
1,-3,12:106
-2,3,12:18.1
3,-2,12:18.1
-3,-3,13:17.1
2,-3,13:17.1
-2,2,13:17.1
3,2,13:17.1
0,0,13:17.1
0,-1,13:17.1
1,0,13:17.1
3,-3,13:18.1
1,-3,13:18.1
-2,-3,13:18.1
-3,-4,13:18.1
-3,-2,13:18.1
-2,1,13:18.1
-1,2,13:18.1
-3,2,13:18.1
-1,1,13:18.1
2,-2,13:18.1
-2,-2,13:18.1
2,2,13:18.1
3,1,13:18.1
3,3,13:18.1
-2,2,14:17.1
-3,-3,14:17.1
2,-3,14:17.1
3,2,14:17.1
0,0,14:17.1
0,-2,14:17.1
2,0,14:17.1
-3,2,14:18.1
-3,-4,14:18.1
3,-3,14:18.1
2,2,14:18.1
-3,-3,15:17.1
2,-3,15:17.1
-2,2,15:17.1
3,2,15:17.1
2,0,15:17.1
0,-2,15:17.1
0,0,15:17.1
-2,0,15:17.1
-2,0,16:17.1
0,0,16:17.1
0,-2,16:17.1
2,0,16:17.1
-3,-3,16:18.1
-2,2,16:18.1
3,2,16:18.1
2,-3,16:18.1
-1,-2,16:18.1
0,-3,16:18.1
0,1,16:18.1
0,0,17:17.1
0,-1,17:18.1
-1,0,17:18.1
0,1,17:18.1
1,0,17:18.1
1,-3,17:18.1
2,-4,17:18.1
3,-3,17:18.1
2,-2,17:18.1
-2,-3,17:18.1
-3,-4,17:18.1
-4,-3,17:18.1
-3,-2,17:18.1
-2,1,17:18.1
-3,2,17:18.1
-1,2,17:18.1
-2,3,17:18.1
3,0,17:18.1
3,1,17:18.1
4,2,17:18.1
2,2,17:18.1
3,3,17:18.1
0,0,18:18.1
-2,-3,18:18.1
2,2,18:18.1
2,-2,18:18.1
-2,3,18:18.1
