[META]
version=2.0
spawnOnBlockType=3,2
spawnSunlight=True
spawnDarkness=True
spawnWater=False
spawnLava=False
underFill=True
randomRotation=True
dig=True
tree=False
branch=False
needsFoundation=True
rarity=10
collisionPercentage=2
spawnElevationMin=0
spawnElevationMax=128
spawnInBiome=Forest
[DATA]
-1,0,0:17.1
-1,1,0:17.1
0,1,0:17.1
0,0,0:17.1
-1,0,1:17.1
-1,1,1:17.1
0,1,1:17.1
0,0,1:17.1
-1,0,2:17.1
-1,1,2:17.1
0,1,2:17.1
0,0,2:17.1
2,0,2:18.1
3,0,2:18.1
4,0,2:18.1
0,3,2:18.1
0,4,2:18.1
0,5,2:18.1
-3,1,2:18.1
-4,1,2:18.1
-5,1,2:18.1
-1,-2,2:18.1
-1,-3,2:18.1
-1,-4,2:18.1
-1,0,3:17.1
-1,1,3:17.1
0,1,3:17.1
0,0,3:17.1
2,0,3:17.1
3,0,3:17.1
0,3,3:17.1
0,4,3:17.1
-3,1,3:17.1
-4,1,3:17.1
-1,-3,3:17.1
-1,-2,3:17.1
-1,-4,3:17.1
-5,1,3:17.1
0,5,3:17.1
4,0,3:17.1
-1,-5,3:18.1
-6,1,3:18.1
0,6,3:18.1
5,0,3:18.1
-1,0,4:17.1
-1,1,4:17.1
0,1,4:17.1
0,0,4:17.1
0,3,4:17.1
0,6,4:17.1
2,0,4:17.1
5,0,4:17.1
-1,-2,4:17.1
-1,-5,4:17.1
-3,1,4:17.1
-6,1,4:17.1
-7,1,4:17.1
-1,-6,4:17.1
0,7,4:17.1
6,0,4:17.1
-8,1,4:18.1
-1,-7,4:18.1
7,0,4:18.1
0,8,4:18.1
-1,0,5:17.1
-1,1,5:17.1
0,1,5:17.1
0,0,5:17.1
-1,-1,5:17.1
-1,-7,5:17.1
-2,1,5:17.1
0,2,5:17.1
1,0,5:17.1
-8,1,5:17.1
0,8,5:17.1
-9,1,5:18.1
-1,-8,5:18.1
8,0,5:18.1
0,9,5:18.1
7,0,5:17.1
-1,0,6:17.1
-1,1,6:17.1
0,1,6:17.1
0,0,6:17.1
-1,0,7:17.1
-1,1,7:17.1
0,1,7:17.1
0,0,7:17.1
-1,0,8:17.1
-1,1,8:17.1
0,1,8:17.1
0,0,8:17.1
-5,1,8:18.1
-1,-4,8:18.1
4,0,8:18.1
0,5,8:18.1
-4,1,8:18.1
-3,1,8:18.1
-1,-3,8:18.1
-1,-2,8:18.1
3,0,8:18.1
2,0,8:18.1
0,4,8:18.1
0,3,8:18.1
-1,0,9:17.1
-1,1,9:17.1
0,1,9:17.1
0,0,9:17.1
2,0,9:17.1
3,0,9:17.1
0,3,9:17.1
0,4,9:17.1
-3,1,9:17.1
-4,1,9:17.1
-1,-3,9:17.1
-1,-2,9:17.1
-1,-4,9:17.1
-5,1,9:17.1
0,5,9:17.1
4,0,9:17.1
-6,1,9:18.1
-1,-5,9:18.1
0,6,9:18.1
5,0,9:18.1
-1,0,10:17.1
-1,1,10:17.1
0,1,10:17.1
0,0,10:17.1
-1,-1,10:17.1
-2,1,10:17.1
1,0,10:17.1
0,2,10:17.1
0,6,10:17.1
-6,1,10:17.1
-1,-5,10:17.1
5,0,10:17.1
-7,1,10:18.1
-1,-6,10:18.1
6,0,10:18.1
0,7,10:18.1
-2,-1,10:18.1
0,-1,10:18.1
-2,0,10:18.1
-2,2,10:18.1
-1,2,10:18.1
1,2,10:18.1
1,1,10:18.1
1,-1,10:18.1
-1,0,-1:17.1
-1,1,-1:17.1
0,1,-1:17.1
0,0,-1:17.1
1,-1,-1:17.1
1,2,-1:17.1
-2,2,-1:17.1
-2,-1,-1:17.1
-1,0,11:17.1
0,1,11:17.1
0,0,11:17.1
0,0,12:17.1
2,0,12:18.1
0,2,12:18.1
-2,0,12:18.1
0,-2,12:18.1
0,0,13:17.1
2,0,13:17.1
0,-2,13:17.1
-2,0,13:17.1
0,2,13:17.1
0,3,13:18.1
-3,0,13:18.1
0,-3,13:18.1
3,0,13:18.1
0,0,14:17.1
0,-1,14:17.1
0,-3,14:17.1
0,1,14:17.1
0,3,14:17.1
-1,0,14:17.1
-3,0,14:17.1
1,0,14:17.1
3,0,14:17.1
-4,0,14:18.1
0,-4,14:18.1
4,0,14:18.1
0,4,14:18.1
0,0,15:17.1
0,0,16:17.1
0,0,17:17.1
0,-2,17:18.1
-2,0,17:18.1
0,2,17:18.1
2,0,17:18.1
0,0,18:17.1
0,-1,18:18.1
-1,0,18:18.1
1,0,18:18.1
0,1,18:18.1
0,-3,18:18.1
-3,0,18:18.1
0,3,18:18.1
3,0,18:18.1
0,0,19:18.1
0,0,20:18.1
