[META]
version=2.0
spawnOnBlockType=3,2
spawnSunlight=True
spawnDarkness=True
spawnWater=False
spawnLava=False
underFill=True
randomRotation=True
dig=True
tree=True
branch=False
needsFoundation=True
rarity=100
collisionPercentage=2
spawnElevationMin=0
spawnElevationMax=100
spawnInBiome=Urwald,Forest,Rain Forest,Seasonal Forest,Shrubland,Taiga,Tundra
[DATA]
0,0,0:17.0
0,-1,0:17.0
0,1,0:17.0
-1,0,0:17.0
1,0,0:17.0
-1,-1,0:17.0
1,1,0:17.0
1,-1,0:17.0
-1,1,0:17.0
0,-2,0:17.0
-2,0,0:17.0
2,0,0:17.0
0,2,0:17.0
-1,0,1:17.0
0,-1,1:17.0
0,0,1:17.0
0,1,1:17.0
1,0,1:17.0
0,-2,1:17.0
-2,0,1:17.0
0,2,1:17.0
2,0,1:17.0
-1,0,2:17.0
0,-1,2:17.0
1,0,2:17.0
0,1,2:17.0
0,0,2:17.0
-1,0,3:17.0
0,0,3:17.0
0,-1,3:17.0
0,1,3:17.0
1,0,3:17.0
-1,0,4:17.0
0,0,4:17.0
0,-1,4:17.0
1,0,4:17.0
0,1,4:17.0
-1,0,5:17.0
0,0,5:17.0
0,1,5:17.0
1,0,5:17.0
0,-1,5:17.0
-1,0,6:17.0
0,0,6:17.0
1,0,6:17.0
0,-1,6:17.0
0,1,6:17.0
-1,0,7:17.0
0,-1,7:17.0
0,0,7:17.0
0,1,7:17.0
1,0,7:17.0
0,2,7:17.0
0,3,7:17.0
-1,4,7:17.0
0,-2,7:17.0
1,-3,7:17.0
-2,0,7:17.0
-2,5,7:18.0
-1,5,7:18.0
2,1,7:18.0
2,0,7:18.0
3,0,7:18.0
1,-4,7:18.0
2,-4,7:18.0
2,-3,7:18.0
-3,0,7:18.0
-4,0,7:18.0
-2,-1,7:18.0
-1,2,7:18.0
-1,-3,7:18.0
-1,0,8:17.0
0,0,8:17.0
0,-1,8:17.0
0,1,8:17.0
1,0,8:17.0
-3,0,8:18.0
0,-2,8:18.0
-1,-4,8:18.0
0,-3,8:18.0
1,-3,8:18.0
2,-1,8:18.0
3,1,8:18.0
2,0,8:18.0
0,3,8:18.0
-1,4,8:18.0
-1,5,8:18.0
0,6,8:18.0
-2,3,8:18.0
-4,1,8:18.0
-1,0,9:17.0
0,-1,9:17.0
0,0,9:17.0
1,0,9:17.0
0,1,9:17.0
-1,0,10:17.0
0,0,10:17.0
0,-1,10:17.0
0,1,10:17.0
1,0,10:17.0
-1,0,11:17.0
0,0,11:17.0
0,-1,11:17.0
0,1,11:17.0
1,0,11:17.0
-1,0,12:17.0
0,0,12:17.0
0,-1,12:17.0
1,0,12:17.0
0,1,12:17.0
-1,0,13:17.0
-2,0,13:17.0
0,0,13:17.0
1,0,13:17.0
0,-1,13:17.0
0,1,13:17.0
0,2,13:17.0
0,3,13:17.0
-3,0,13:17.0
-1,2,13:18.0
-1,3,13:18.0
0,4,13:18.0
1,3,13:18.0
-4,0,13:18.0
-3,1,13:18.0
-3,-1,13:18.0
2,0,13:18.0
0,-2,13:18.0
0,3,14:18.0
-3,0,14:18.0
-4,0,14:18.0
0,-1,14:18.0
0,-2,14:18.0
1,0,14:18.0
2,0,14:18.0
3,0,14:18.0
2,-1,14:18.0
-1,-2,14:18.0
-1,4,14:18.0
0,4,14:18.0
-4,1,14:18.0
-3,-1,14:18.0
0,0,14:17.0
0,0,15:17.0
0,0,16:17.0
0,-1,16:17.0
1,-2,16:17.0
2,-3,16:17.0
-1,1,16:17.0
-2,2,16:17.0
-3,2,16:18.0
-1,-1,16:17.0
-2,-2,16:17.0
1,1,16:17.0
-3,3,16:18.0
-4,3,16:18.0
-4,2,16:18.0
-4,1,16:18.0
-3,1,16:18.0
-5,2,16:18.0
1,2,16:18.0
2,2,16:18.0
2,1,16:18.0
3,-3,16:18.0
2,-4,16:18.0
3,-4,16:18.0
-2,-3,16:18.0
-3,-3,16:18.0
-3,-2,16:18.0
-2,-1,16:18.0
-1,0,16:18.0
-3,2,17:18.0
-4,2,17:18.0
-3,1,17:18.0
1,2,17:18.0
1,1,17:18.0
-2,-2,17:18.0
-2,-3,17:18.0
2,-3,17:18.0
2,-2,17:18.0
3,-3,17:18.0
-2,-1,17:18.0
0,0,17:17.0
0,0,18:17.0
0,0,19:17.0
-1,1,19:17.0
0,-1,19:17.0
0,-2,19:17.0
0,-3,19:17.0
1,1,19:17.0
2,2,19:17.0
3,3,19:17.0
4,4,19:17.0
-1,-3,19:17.0
-1,-4,19:17.0
-2,-5,19:17.0
1,-2,19:17.0
2,-3,19:17.0
3,-4,19:17.0
-2,2,19:17.0
-3,3,19:17.0
-4,2,19:17.0
-5,2,19:17.0
-2,-2,19:17.0
-3,-2,19:17.0
-4,-2,19:17.0
2,-1,19:17.0
3,-1,19:17.0
4,-4,19:17.0
4,-5,19:17.0
5,-6,19:17.0
5,-5,19:17.0
3,4,19:18.0
4,3,19:18.0
3,3,20:18.0
3,4,20:18.0
4,4,20:18.0
5,5,20:18.0
5,4,20:18.0
3,5,20:18.0
4,3,20:18.0
5,2,20:18.0
1,2,20:18.0
-2,1,20:18.0
-3,0,20:18.0
-4,2,20:18.0
-5,2,20:18.0
-6,2,20:18.0
-6,1,20:18.0
-7,2,20:18.0
-3,3,20:18.0
-3,4,20:18.0
-3,5,20:18.0
-4,4,20:18.0
-2,4,20:18.0
-3,-2,20:18.0
-4,-3,20:18.0
-4,-2,20:18.0
-5,-2,20:18.0
-5,-3,20:18.0
-6,-2,20:18.0
-5,-1,20:18.0
-2,-4,20:18.0
-2,-5,20:18.0
-2,-6,20:18.0
-3,-6,20:18.0
-2,-7,20:18.0
-1,-6,20:18.0
-1,-4,20:18.0
1,-4,20:18.0
3,-5,20:18.0
4,-5,20:18.0
5,-5,20:18.0
6,-5,20:18.0
5,-6,20:18.0
5,-7,20:18.0
6,-7,20:18.0
2,-6,20:18.0
4,-4,20:18.0
4,-3,20:18.0
5,-2,20:18.0
3,-1,20:18.0
3,0,20:18.0
4,0,20:18.0
-2,2,20:18.0
-1,3,20:18.0
-4,6,20:18.0
6,5,20:18.0
-6,-4,20:18.0
0,0,20:17.0
0,0,21:17.0
0,0,22:17.0
0,0,23:17.0
-1,-1,23:17.0
1,0,23:17.0
2,1,23:17.0
-1,1,23:17.0
-1,2,23:17.0
-2,3,23:18.0
-2,-2,23:18.0
3,2,23:18.0
3,1,23:18.0
-2,1,23:18.0
1,-1,23:18.0
2,-2,23:18.0
-3,-3,24:18.0
3,-3,24:18.0
2,0,24:18.0
0,1,24:18.0
-1,2,24:18.0
-2,3,24:18.0
-2,1,24:18.0
-3,0,24:18.0
-4,0,24:18.0
3,2,24:18.0
4,2,24:18.0
4,-3,24:18.0
2,-4,24:18.0
-2,-4,24:18.0
-4,-3,24:18.0
0,-2,24:18.0
0,-3,24:18.0
1,2,24:18.0
1,3,24:18.0
1,4,24:18.0
-1,-5,24:18.0
3,-5,24:18.0
-5,-4,24:18.0
0,0,24:17.0
0,0,25:17.0
0,0,26:17.0
0,-1,26:18.0
1,1,26:18.0
-1,1,26:18.0
0,0,27:18.0
0,0,28:18.0
-1,0,28:18.0
1,-1,28:18.0
0,0,29:18.0
-1,-1,29:18.0
-1,-2,29:18.0
-2,-3,29:18.0
1,1,29:18.0
0,2,29:18.0
1,3,29:18.0
-1,1,29:18.0
-2,2,30:18.0
0,-2,30:18.0
2,0,30:18.0
-2,0,30:18.0
-1,-4,30:18.0
0,4,30:18.0
0,0,30:18.0
0,0,31:18.0
0,1,31:18.0
-1,-1,31:18.0
1,-1,31:18.0
0,0,32:18.0
