[META]
version=2.0
spawnOnBlockType=3,2
spawnSunlight=True
spawnDarkness=True
spawnWater=False
spawnLava=False
underFill=True
randomRotation=True
dig=True
tree=True
branch=False
needsFoundation=True
rarity=500
collisionPercentage=20
spawnElevationMin=0
spawnElevationMax=128
spawnInBiome=Urwald
[DATA]
0,-1,0:17.1
0,0,0:17.1
0,1,0:17.1
0,2,0:17.1
1,0,0:17.1
2,0,0:17.1
3,0,0:17.1
-1,0,0:17.1
-2,0,0:17.1
-3,0,0:17.1
-4,0,0:17.1
4,0,0:17.1
-1,-1,0:17.1
1,1,0:17.1
1,-1,0:17.1
0,3,0:17.1
-1,1,0:17.1
0,-2,0:17.1
0,-3,0:17.1
0,-4,0:17.1
0,4,0:17.1
-3,0,1:17.1
-2,0,1:17.1
-1,0,1:17.1
0,-3,1:17.1
0,-1,1:17.1
0,-2,1:17.1
-1,-1,1:17.1
-1,1,1:17.1
0,1,1:17.1
0,0,1:17.1
1,-1,1:17.1
1,0,1:17.1
1,1,1:17.1
2,0,1:17.1
3,0,1:17.1
0,2,1:17.1
0,3,1:17.1
-2,0,2:17.1
-1,0,2:17.1
0,-2,2:17.1
0,-1,2:17.1
0,1,2:17.1
0,2,2:17.1
1,0,2:17.1
2,0,2:17.1
0,0,2:17.1
-1,0,3:17.1
0,0,3:17.1
0,-1,3:17.1
0,1,3:17.1
1,0,3:17.1
-1,0,4:17.1
0,0,4:17.1
0,-1,4:17.1
1,0,4:17.1
0,1,4:17.1
-1,0,5:17.1
0,0,5:17.1
0,-1,5:17.1
0,1,5:17.1
1,0,5:17.1
-1,0,6:17.1
0,0,6:17.1
0,-1,6:17.1
0,1,6:17.1
1,0,6:17.1
-3,2,6:106
2,-2,6:106
-1,0,7:17.1
0,0,7:17.1
0,-1,7:17.1
0,1,7:17.1
1,0,7:17.1
0,-4,7:106
2,-2,7:106
3,1,7:106
-3,2,7:106
-1,0,8:17.1
0,0,8:17.1
0,-1,8:17.1
0,1,8:17.1
1,0,8:17.1
-2,-3,8:106
0,-4,8:106
2,-2,8:106
3,1,8:106
0,3,8:106
-1,3,8:106
-3,2,8:106
-1,0,9:17.1
0,0,9:17.1
0,-1,9:17.1
0,1,9:17.1
1,0,9:17.1
-3,2,9:106
0,3,9:106
-1,3,9:106
2,-2,9:106
0,-4,9:106
-2,-3,9:106
3,1,9:106
-1,0,10:17.1
0,-1,10:17.1
0,1,10:17.1
1,0,10:17.1
0,0,10:17.1
-3,2,10:106
-2,-3,10:106
2,-2,10:106
3,1,10:106
0,3,10:106
-1,3,10:106
0,-4,10:106
2,0,11:17.1
0,2,11:17.1
-2,0,11:17.1
0,-2,11:17.1
0,0,11:17.1
-1,0,11:18.1
0,-1,11:18.1
0,1,11:18.1
1,0,11:18.1
-3,2,11:106
0,3,11:106
3,1,11:106
2,-2,11:106
0,-4,11:106
-2,-3,11:106
-1,3,11:106
1,-3,12:17.1
-1,-3,12:17.1
-3,-1,12:17.1
-3,1,12:17.1
-1,3,12:17.1
1,3,12:17.1
3,1,12:17.1
3,-1,12:17.1
0,0,12:17.1
-2,0,12:18.1
0,-2,12:18.1
2,0,12:18.1
0,2,12:18.1
-3,2,12:106
-2,-3,12:106
0,-4,12:106
2,-2,12:106
0,3,12:106
-1,-1,13:17.1
1,1,13:17.1
-2,4,13:17.1
2,4,13:17.1
4,2,13:17.1
4,-2,13:17.1
2,-4,13:17.1
-2,-4,13:17.1
-4,-2,13:17.1
-4,2,13:17.1
-1,1,13:17.1
1,-1,13:17.1
-3,-1,13:18.1
-3,1,13:18.1
-1,3,13:18.1
1,3,13:18.1
3,1,13:18.1
3,-1,13:18.1
1,-3,13:18.1
-1,-3,13:18.1
0,0,13:18.1
-3,2,13:106
-2,-3,13:106
0,-4,13:106
2,-2,13:106
0,3,13:106
-3,5,14:17.1
-1,5,14:17.1
1,5,14:17.1
3,5,14:17.1
5,3,14:17.1
5,1,14:17.1
5,-1,14:17.1
5,-3,14:17.1
3,-5,14:17.1
1,-5,14:17.1
-1,-5,14:17.1
-3,-5,14:17.1
-5,-3,14:17.1
-5,-1,14:17.1
-5,1,14:17.1
-5,3,14:17.1
-1,-2,14:17.1
-2,-1,14:17.1
-2,1,14:17.1
-1,2,14:17.1
1,2,14:17.1
2,1,14:17.1
2,-1,14:17.1
1,-2,14:17.1
-3,-3,14:17.1
-3,3,14:17.1
3,3,14:17.1
3,-3,14:17.1
0,-4,14:17.1
0,4,14:17.1
0,0,14:18.1
2,-4,14:18.1
4,-2,14:18.1
-2,-4,14:18.1
-4,-2,14:18.1
-4,2,14:18.1
-2,4,14:18.1
2,4,14:18.1
4,2,14:18.1
-1,1,14:18.1
1,1,14:18.1
1,-1,14:18.1
-1,-1,14:18.1
-3,2,14:106
-2,-3,14:106
2,-2,14:106
0,3,14:106
-5,-3,15:17.1
-3,-5,15:17.1
-3,-3,15:17.1
-5,-1,15:17.1
-5,1,15:17.1
-5,3,15:17.1
-3,5,15:17.1
-1,5,15:17.1
1,5,15:17.1
0,4,15:17.1
-1,-5,15:17.1
1,-5,15:17.1
0,-4,15:17.1
3,-5,15:17.1
5,-3,15:17.1
5,-1,15:17.1
5,1,15:17.1
5,3,15:17.1
3,5,15:17.1
3,-3,15:17.1
3,3,15:17.1
-3,3,15:17.1
-1,-2,15:17.1
-1,2,15:17.1
1,2,15:17.1
1,-2,15:17.1
-2,-1,15:18.1
-2,1,15:18.1
2,1,15:18.1
2,-1,15:18.1
0,0,15:18.1
-3,2,15:106
0,3,15:106
-2,-3,15:106
2,-2,15:106
-5,-3,16:18.1
-5,-4,16:18.1
-6,-3,16:18.1
-5,-1,16:18.1
-6,-1,16:18.1
-5,1,16:18.1
-6,1,16:18.1
-6,2,16:18.1
-5,3,16:18.1
-5,4,16:18.1
-3,2,16:18.1
-3,3,16:18.1
-1,5,16:18.1
-2,4,16:18.1
1,5,16:18.1
1,6,16:18.1
-3,6,16:18.1
-3,5,16:18.1
3,5,16:18.1
2,4,16:18.1
3,3,16:18.1
2,2,16:18.1
0,0,16:18.1
-1,2,16:18.1
-2,1,16:18.1
-3,-3,16:18.1
-3,-5,16:18.1
-1,-6,16:18.1
1,-5,16:18.1
2,-6,16:18.1
3,-5,16:18.1
4,-5,16:18.1
4,-3,16:18.1
3,-3,16:18.1
5,-1,16:18.1
6,-3,16:18.1
5,-3,16:18.1
5,1,16:18.1
5,3,16:18.1
4,2,16:18.1
1,-2,16:18.1
-1,-2,16:18.1
0,-3,16:18.1
-1,-5,16:18.1
0,-5,16:18.1
0,-4,16:18.1
-2,-1,16:18.1
2,-1,16:18.1
2,1,16:18.1
1,2,16:18.1
0,4,16:18.1
-4,-6,16:18.1
-2,-3,16:106
0,3,16:106
2,-2,16:106
-5,-5,17:18.1
-4,-5,17:18.1
-4,-7,17:18.1
-3,-6,17:18.1
-1,-7,17:18.1
0,-6,17:18.1
-2,-5,17:18.1
1,-4,17:18.1
2,-5,17:18.1
3,-6,17:18.1
4,-6,17:18.1
5,-5,17:18.1
4,-4,17:18.1
2,-3,17:18.1
3,-2,17:18.1
5,-2,17:18.1
7,-2,17:18.1
7,-4,17:18.1
6,-1,17:18.1
4,0,17:18.1
6,2,17:18.1
4,3,17:18.1
5,4,17:18.1
6,5,17:18.1
3,6,17:18.1
3,4,17:18.1
2,5,17:18.1
0,6,17:18.1
1,7,17:18.1
0,3,17:18.1
-1,6,17:18.1
-2,6,17:18.1
-2,5,17:18.1
-4,4,17:18.1
-4,5,17:18.1
-4,7,17:18.1
-6,5,17:18.1
-5,4,17:18.1
-4,2,17:18.1
-6,3,17:18.1
-7,2,17:18.1
-6,0,17:18.1
-7,-2,17:18.1
-5,-3,17:18.1
-2,-3,17:106
2,-2,17:106
-3,-7,18:18.1
-4,-6,18:18.1
-5,-8,18:18.1
-3,-5,18:18.1
0,-7,18:18.1
0,-5,18:18.1
-1,-6,18:18.1
2,-6,18:18.1
2,-5,18:18.1
4,-7,18:18.1
3,-5,18:18.1
5,-6,18:18.1
5,-4,18:18.1
7,-5,18:18.1
8,-4,18:18.1
7,-3,18:18.1
7,-1,18:18.1
8,-1,18:18.1
7,2,18:18.1
6,1,18:18.1
6,3,18:18.1
7,4,18:18.1
6,6,18:18.1
4,6,18:18.1
4,7,18:18.1
3,7,18:18.1
1,8,18:18.1
1,6,18:18.1
0,7,18:18.1
-2,7,18:18.1
-1,5,18:18.1
-3,5,18:18.1
-3,7,18:18.1
-5,8,18:18.1
-1,8,18:18.1
-5,6,18:18.1
-6,4,18:18.1
-7,5,18:18.1
-8,2,18:18.1
-7,1,18:18.1
-6,2,18:18.1
-4,3,18:18.1
-5,-1,18:18.1
-7,-1,18:18.1
-7,-3,18:18.1
-8,-2,18:18.1
-6,-3,18:18.1
-4,-2,18:18.1
-4,-3,18:18.1
-5,-4,18:18.1
-6,-5,18:18.1
0,-8,18:18.1
2,-8,18:18.1
2,-7,18:18.1
4,-3,18:18.1
5,4,18:18.1
5,5,18:18.1
7,6,18:18.1
4,8,18:18.1
-2,-3,18:18.1
2,-2,18:18.1
-3,-3,18:18.1
