[META]
version=2.0
spawnOnBlockType=1
spawnSunlight=True
spawnDarkness=True
spawnWater=false
spawnLava=true
spawnAboveGround=False
spawnUnderGround=true
underFill=False
randomRotation=True
dig=false
tree=False
branch=False
needsFoundation=false
rarity=450
collisionPercentage=100
collisionBlockType=All
spawnElevationMin=5
spawnElevationMax=50
spawnInBiome=Beach,Desert,DesertHills,DesertOasis,Extreme Hills Edge, Extreme Hills, Forest,ForestHills,FrozenOcean,FrozenRiver,Glacier,Ice Mountains,Ice Plains,Jungle,JungleHills,Ocean2,Ocean,Plains,River2,River,Summits2,Summits,Swampland,Taiga,TaigaHills,Urwald2,Urwald
[DATA]
2,-22,1:1.0
3,-22,1:1.0
4,-22,1:1.0
5,-22,1:1.0
6,-22,1:1.0
7,-22,1:1.0
1,-21,1:1.0
2,-21,1:1.0
3,-21,1:1.0
4,-21,1:1.0
5,-21,1:1.0
6,-21,1:1.0
7,-21,1:1.0
8,-21,1:1.0
9,-21,1:1.0
10,-21,1:1.0
11,-21,1:1.0
12,-21,1:1.0
13,-21,1:1.0
0,-20,1:1.0
1,-20,1:1.0
2,-20,1:1.0
3,-20,1:1.0
4,-20,1:1.0
5,-20,1:1.0
6,-20,1:1.0
7,-20,1:1.0
8,-20,1:1.0
9,-20,1:1.0
10,-20,1:1.0
11,-20,1:1.0
12,-20,1:1.0
13,-20,1:1.0
14,-20,1:1.0
15,-20,1:1.0
16,-20,1:1.0
-1,-19,1:1.0
0,-19,1:1.0
1,-19,1:1.0
2,-19,1:1.0
3,-19,1:1.0
4,-19,1:1.0
5,-19,1:1.0
6,-19,1:1.0
7,-19,1:1.0
8,-19,1:1.0
9,-19,1:1.0
10,-19,1:1.0
11,-19,1:1.0
12,-19,1:1.0
13,-19,1:1.0
14,-19,1:1.0
15,-19,1:1.0
16,-19,1:1.0
17,-19,1:1.0
-1,-18,1:1.0
0,-18,1:1.0
1,-18,1:1.0
2,-18,1:1.0
3,-18,1:1.0
4,-18,1:1.0
5,-18,1:1.0
6,-18,1:1.0
7,-18,1:1.0
8,-18,1:1.0
9,-18,1:1.0
10,-18,1:1.0
11,-18,1:1.0
12,-18,1:1.0
13,-18,1:1.0
14,-18,1:1.0
15,-18,1:1.0
16,-18,1:1.0
17,-18,1:1.0
18,-18,1:1.0
19,-18,1:1.0
20,-18,1:1.0
-2,-17,1:1.0
-1,-17,1:1.0
0,-17,1:1.0
1,-17,1:1.0
2,-17,1:1.0
3,-17,1:1.0
4,-17,1:1.0
5,-17,1:1.0
6,-17,1:1.0
7,-17,1:1.0
8,-17,1:1.0
9,-17,1:1.0
10,-17,1:1.0
11,-17,1:1.0
12,-17,1:1.0
13,-17,1:1.0
14,-17,1:1.0
15,-17,1:1.0
16,-17,1:1.0
17,-17,1:1.0
18,-17,1:1.0
19,-17,1:1.0
20,-17,1:1.0
-6,-16,1:1.0
-5,-16,1:1.0
-4,-16,1:1.0
-3,-16,1:1.0
-2,-16,1:1.0
-1,-16,1:1.0
0,-16,1:1.0
1,-16,1:1.0
2,-16,1:1.0
3,-16,1:1.0
4,-16,1:1.0
5,-16,1:1.0
6,-16,1:1.0
7,-16,1:1.0
8,-16,1:1.0
9,-16,1:1.0
10,-16,1:1.0
11,-16,1:1.0
12,-16,1:1.0
13,-16,1:1.0
14,-16,1:1.0
15,-16,1:1.0
16,-16,1:1.0
17,-16,1:1.0
18,-16,1:1.0
19,-16,1:1.0
20,-16,1:1.0
-7,-15,1:1.0
-6,-15,1:1.0
-5,-15,1:1.0
-4,-15,1:1.0
-3,-15,1:1.0
-2,-15,1:1.0
-1,-15,1:1.0
0,-15,1:1.0
1,-15,1:1.0
2,-15,1:1.0
3,-15,1:1.0
4,-15,1:1.0
5,-15,1:1.0
6,-15,1:1.0
7,-15,1:1.0
8,-15,1:1.0
9,-15,1:1.0
10,-15,1:1.0
11,-15,1:1.0
12,-15,1:1.0
13,-15,1:1.0
14,-15,1:1.0
15,-15,1:1.0
16,-15,1:1.0
17,-15,1:1.0
18,-15,1:1.0
19,-15,1:1.0
20,-15,1:1.0
21,-15,1:1.0
-11,-14,1:1.0
-10,-14,1:1.0
-9,-14,1:1.0
-8,-14,1:1.0
-7,-14,1:1.0
-6,-14,1:1.0
-5,-14,1:1.0
-4,-14,1:1.0
-3,-14,1:1.0
-2,-14,1:1.0
-1,-14,1:1.0
0,-14,1:1.0
1,-14,1:1.0
2,-14,1:1.0
3,-14,1:1.0
4,-14,1:1.0
5,-14,1:1.0
6,-14,1:1.0
7,-14,1:1.0
8,-14,1:1.0
9,-14,1:1.0
10,-14,1:1.0
11,-14,1:1.0
12,-14,1:1.0
13,-14,1:1.0
14,-14,1:1.0
15,-14,1:1.0
16,-14,1:1.0
17,-14,1:1.0
18,-14,1:1.0
19,-14,1:1.0
20,-14,1:1.0
21,-14,1:1.0
-12,-13,1:1.0
-11,-13,1:1.0
-10,-13,1:1.0
-9,-13,1:1.0
-8,-13,1:1.0
-7,-13,1:1.0
-6,-13,1:1.0
-5,-13,1:1.0
-4,-13,1:1.0
-3,-13,1:1.0
-2,-13,1:1.0
-1,-13,1:1.0
0,-13,1:1.0
1,-13,1:1.0
2,-13,1:1.0
3,-13,1:1.0
4,-13,1:1.0
5,-13,1:1.0
6,-13,1:1.0
7,-13,1:1.0
8,-13,1:1.0
9,-13,1:1.0
10,-13,1:1.0
11,-13,1:1.0
12,-13,1:1.0
13,-13,1:1.0
14,-13,1:1.0
15,-13,1:1.0
16,-13,1:1.0
17,-13,1:1.0
18,-13,1:1.0
19,-13,1:1.0
20,-13,1:1.0
21,-13,1:1.0
-13,-12,1:1.0
-12,-12,1:1.0
-11,-12,1:1.0
-10,-12,1:1.0
-9,-12,1:1.0
-8,-12,1:1.0
-7,-12,1:1.0
-6,-12,1:1.0
-5,-12,1:1.0
-4,-12,1:1.0
-3,-12,1:1.0
-2,-12,1:1.0
-1,-12,1:1.0
0,-12,1:1.0
1,-12,1:1.0
2,-12,1:1.0
3,-12,1:1.0
4,-12,1:1.0
5,-12,1:1.0
6,-12,1:1.0
7,-12,1:1.0
8,-12,1:1.0
9,-12,1:1.0
10,-12,1:1.0
11,-12,1:1.0
12,-12,1:1.0
13,-12,1:1.0
14,-12,1:1.0
15,-12,1:1.0
16,-12,1:1.0
17,-12,1:1.0
18,-12,1:1.0
19,-12,1:1.0
20,-12,1:1.0
21,-12,1:1.0
-14,-11,1:1.0
-13,-11,1:1.0
-12,-11,1:1.0
-11,-11,1:1.0
-10,-11,1:1.0
-9,-11,1:1.0
-8,-11,1:1.0
-7,-11,1:1.0
-6,-11,1:1.0
-5,-11,1:1.0
-4,-11,1:1.0
-3,-11,1:1.0
-2,-11,1:1.0
-1,-11,1:1.0
0,-11,1:1.0
1,-11,1:1.0
2,-11,1:1.0
3,-11,1:1.0
4,-11,1:1.0
5,-11,1:1.0
6,-11,1:1.0
7,-11,1:1.0
8,-11,1:1.0
9,-11,1:1.0
10,-11,1:1.0
11,-11,1:1.0
12,-11,1:1.0
13,-11,1:1.0
14,-11,1:1.0
15,-11,1:1.0
16,-11,1:1.0
17,-11,1:1.0
18,-11,1:1.0
19,-11,1:1.0
20,-11,1:1.0
21,-11,1:1.0
-14,-10,1:1.0
-13,-10,1:1.0
-12,-10,1:1.0
-11,-10,1:1.0
-10,-10,1:1.0
-9,-10,1:1.0
-8,-10,1:1.0
-7,-10,1:1.0
-6,-10,1:1.0
-5,-10,1:1.0
-4,-10,1:1.0
-3,-10,1:1.0
-2,-10,1:1.0
-1,-10,1:1.0
0,-10,1:1.0
1,-10,1:1.0
2,-10,1:1.0
3,-10,1:1.0
4,-10,1:1.0
5,-10,1:1.0
6,-10,1:1.0
7,-10,1:1.0
8,-10,1:1.0
9,-10,1:1.0
10,-10,1:1.0
11,-10,1:1.0
12,-10,1:1.0
13,-10,1:1.0
14,-10,1:1.0
15,-10,1:1.0
16,-10,1:1.0
17,-10,1:1.0
18,-10,1:1.0
19,-10,1:1.0
20,-10,1:1.0
21,-10,1:1.0
-15,-9,1:1.0
-14,-9,1:1.0
-13,-9,1:1.0
-12,-9,1:1.0
-11,-9,1:1.0
-10,-9,1:1.0
-9,-9,1:1.0
-8,-9,1:1.0
-7,-9,1:1.0
-6,-9,1:1.0
-5,-9,1:1.0
-4,-9,1:1.0
-3,-9,1:1.0
-2,-9,1:1.0
-1,-9,1:1.0
0,-9,1:1.0
1,-9,1:1.0
2,-9,1:1.0
3,-9,1:1.0
4,-9,1:1.0
5,-9,1:1.0
6,-9,1:1.0
7,-9,1:1.0
8,-9,1:1.0
9,-9,1:1.0
10,-9,1:1.0
11,-9,1:1.0
12,-9,1:1.0
13,-9,1:1.0
14,-9,1:1.0
15,-9,1:1.0
16,-9,1:1.0
17,-9,1:1.0
18,-9,1:1.0
19,-9,1:1.0
20,-9,1:1.0
21,-9,1:1.0
22,-9,1:1.0
-15,-8,1:1.0
-14,-8,1:1.0
-13,-8,1:1.0
-12,-8,1:1.0
-11,-8,1:1.0
-10,-8,1:1.0
-9,-8,1:1.0
-8,-8,1:1.0
-7,-8,1:1.0
-6,-8,1:1.0
-5,-8,1:1.0
-4,-8,1:1.0
-3,-8,1:1.0
-2,-8,1:1.0
-1,-8,1:1.0
0,-8,1:1.0
1,-8,1:1.0
2,-8,1:1.0
3,-8,1:1.0
4,-8,1:1.0
5,-8,1:1.0
6,-8,1:1.0
7,-8,1:1.0
8,-8,1:1.0
9,-8,1:1.0
10,-8,1:1.0
11,-8,1:1.0
12,-8,1:1.0
13,-8,1:1.0
14,-8,1:1.0
15,-8,1:1.0
16,-8,1:1.0
17,-8,1:1.0
18,-8,1:1.0
19,-8,1:1.0
20,-8,1:1.0
21,-8,1:1.0
22,-8,1:1.0
-15,-7,1:1.0
-14,-7,1:1.0
-13,-7,1:1.0
-12,-7,1:1.0
-11,-7,1:1.0
-10,-7,1:1.0
-9,-7,1:1.0
-8,-7,1:1.0
-7,-7,1:1.0
-6,-7,1:1.0
-5,-7,1:1.0
-4,-7,1:1.0
-3,-7,1:1.0
-2,-7,1:1.0
-1,-7,1:1.0
0,-7,1:1.0
1,-7,1:1.0
2,-7,1:1.0
3,-7,1:1.0
4,-7,1:1.0
5,-7,1:1.0
6,-7,1:1.0
7,-7,1:1.0
8,-7,1:1.0
9,-7,1:1.0
10,-7,1:1.0
11,-7,1:1.0
12,-7,1:1.0
13,-7,1:1.0
14,-7,1:1.0
15,-7,1:1.0
16,-7,1:1.0
17,-7,1:1.0
18,-7,1:1.0
19,-7,1:1.0
20,-7,1:1.0
21,-7,1:1.0
22,-7,1:1.0
-16,-6,1:1.0
-15,-6,1:1.0
-14,-6,1:1.0
-13,-6,1:1.0
-12,-6,1:1.0
-11,-6,1:1.0
-10,-6,1:1.0
-9,-6,1:1.0
-8,-6,1:1.0
-7,-6,1:1.0
-6,-6,1:1.0
-5,-6,1:1.0
-4,-6,1:1.0
-3,-6,1:1.0
-2,-6,1:1.0
-1,-6,1:1.0
0,-6,1:1.0
1,-6,1:1.0
2,-6,1:1.0
3,-6,1:1.0
4,-6,1:1.0
5,-6,1:1.0
6,-6,1:1.0
7,-6,1:1.0
8,-6,1:1.0
9,-6,1:1.0
10,-6,1:1.0
11,-6,1:1.0
12,-6,1:1.0
13,-6,1:1.0
14,-6,1:1.0
15,-6,1:1.0
16,-6,1:1.0
17,-6,1:1.0
18,-6,1:1.0
19,-6,1:1.0
20,-6,1:1.0
21,-6,1:1.0
22,-6,1:1.0
-16,-5,1:1.0
-15,-5,1:1.0
-14,-5,1:1.0
-13,-5,1:1.0
-12,-5,1:1.0
-11,-5,1:1.0
-10,-5,1:1.0
-9,-5,1:1.0
-8,-5,1:1.0
-7,-5,1:1.0
-6,-5,1:1.0
-5,-5,1:1.0
-4,-5,1:1.0
-3,-5,1:1.0
-2,-5,1:1.0
-1,-5,1:1.0
0,-5,1:1.0
1,-5,1:1.0
2,-5,1:1.0
3,-5,1:1.0
4,-5,1:1.0
5,-5,1:1.0
6,-5,1:1.0
7,-5,1:1.0
8,-5,1:1.0
9,-5,1:1.0
10,-5,1:1.0
11,-5,1:1.0
12,-5,1:1.0
13,-5,1:1.0
14,-5,1:1.0
15,-5,1:1.0
16,-5,1:1.0
17,-5,1:1.0
18,-5,1:1.0
19,-5,1:1.0
20,-5,1:1.0
21,-5,1:1.0
-16,-4,1:1.0
-15,-4,1:1.0
-14,-4,1:1.0
-13,-4,1:1.0
-12,-4,1:1.0
-11,-4,1:1.0
-10,-4,1:1.0
-9,-4,1:1.0
-8,-4,1:1.0
-7,-4,1:1.0
-6,-4,1:1.0
-5,-4,1:1.0
-4,-4,1:1.0
-3,-4,1:1.0
-2,-4,1:1.0
-1,-4,1:1.0
0,-4,1:1.0
1,-4,1:1.0
2,-4,1:1.0
3,-4,1:1.0
4,-4,1:1.0
5,-4,1:1.0
6,-4,1:1.0
7,-4,1:1.0
8,-4,1:1.0
9,-4,1:1.0
10,-4,1:1.0
11,-4,1:1.0
12,-4,1:1.0
13,-4,1:1.0
14,-4,1:1.0
15,-4,1:1.0
16,-4,1:1.0
17,-4,1:1.0
18,-4,1:1.0
19,-4,1:1.0
20,-4,1:1.0
21,-4,1:1.0
-17,-3,1:1.0
-16,-3,1:1.0
-15,-3,1:1.0
-14,-3,1:1.0
-13,-3,1:1.0
-12,-3,1:1.0
-11,-3,1:1.0
-10,-3,1:1.0
-9,-3,1:1.0
-8,-3,1:1.0
-7,-3,1:1.0
-6,-3,1:1.0
-5,-3,1:1.0
-4,-3,1:1.0
-3,-3,1:1.0
-2,-3,1:1.0
-1,-3,1:1.0
0,-3,1:1.0
1,-3,1:1.0
2,-3,1:1.0
3,-3,1:1.0
4,-3,1:1.0
5,-3,1:1.0
6,-3,1:1.0
7,-3,1:1.0
8,-3,1:1.0
9,-3,1:1.0
10,-3,1:1.0
11,-3,1:1.0
12,-3,1:1.0
13,-3,1:1.0
14,-3,1:1.0
15,-3,1:1.0
16,-3,1:1.0
17,-3,1:1.0
18,-3,1:1.0
19,-3,1:1.0
20,-3,1:1.0
21,-3,1:1.0
-18,-2,1:1.0
-17,-2,1:1.0
-16,-2,1:1.0
-15,-2,1:1.0
-14,-2,1:1.0
-13,-2,1:1.0
-12,-2,1:1.0
-11,-2,1:1.0
-10,-2,1:1.0
-9,-2,1:1.0
-8,-2,1:1.0
-7,-2,1:1.0
-6,-2,1:1.0
-5,-2,1:1.0
-4,-2,1:1.0
-3,-2,1:1.0
-2,-2,1:1.0
-1,-2,1:1.0
0,-2,1:1.0
1,-2,1:1.0
2,-2,1:1.0
3,-2,1:1.0
4,-2,1:1.0
5,-2,1:1.0
6,-2,1:1.0
7,-2,1:1.0
8,-2,1:1.0
9,-2,1:1.0
10,-2,1:1.0
11,-2,1:1.0
12,-2,1:1.0
13,-2,1:1.0
14,-2,1:1.0
15,-2,1:1.0
16,-2,1:1.0
17,-2,1:1.0
18,-2,1:1.0
19,-2,1:1.0
20,-2,1:1.0
-18,-1,1:1.0
-17,-1,1:1.0
-16,-1,1:1.0
-15,-1,1:1.0
-14,-1,1:1.0
-13,-1,1:1.0
-12,-1,1:1.0
-11,-1,1:1.0
-10,-1,1:1.0
-9,-1,1:1.0
-8,-1,1:1.0
-7,-1,1:1.0
-6,-1,1:1.0
-5,-1,1:1.0
-4,-1,1:1.0
-3,-1,1:1.0
-2,-1,1:1.0
-1,-1,1:1.0
0,-1,1:1.0
1,-1,1:1.0
2,-1,1:1.0
3,-1,1:1.0
4,-1,1:1.0
5,-1,1:1.0
6,-1,1:1.0
7,-1,1:1.0
8,-1,1:1.0
9,-1,1:1.0
10,-1,1:1.0
11,-1,1:1.0
12,-1,1:1.0
13,-1,1:1.0
14,-1,1:1.0
15,-1,1:1.0
16,-1,1:1.0
17,-1,1:1.0
18,-1,1:1.0
19,-1,1:1.0
20,-1,1:1.0
-18,0,1:1.0
-17,0,1:1.0
-16,0,1:1.0
-15,0,1:1.0
-14,0,1:1.0
-13,0,1:1.0
-12,0,1:1.0
-11,0,1:1.0
-10,0,1:1.0
-9,0,1:1.0
-8,0,1:1.0
-7,0,1:1.0
-6,0,1:1.0
-5,0,1:1.0
-4,0,1:1.0
-3,0,1:1.0
-2,0,1:1.0
-1,0,1:1.0
0,0,1:1.0
1,0,1:1.0
2,0,1:1.0
3,0,1:1.0
4,0,1:1.0
5,0,1:1.0
6,0,1:1.0
7,0,1:1.0
8,0,1:1.0
9,0,1:1.0
10,0,1:1.0
11,0,1:1.0
12,0,1:1.0
13,0,1:1.0
14,0,1:1.0
15,0,1:1.0
16,0,1:1.0
17,0,1:1.0
18,0,1:1.0
19,0,1:1.0
20,0,1:1.0
-19,1,1:1.0
-18,1,1:1.0
-17,1,1:1.0
-16,1,1:1.0
-15,1,1:1.0
-14,1,1:1.0
-13,1,1:1.0
-12,1,1:1.0
-11,1,1:1.0
-10,1,1:1.0
-9,1,1:1.0
-8,1,1:1.0
-7,1,1:1.0
-6,1,1:1.0
-5,1,1:1.0
-4,1,1:1.0
-3,1,1:1.0
-2,1,1:1.0
-1,1,1:1.0
0,1,1:1.0
1,1,1:1.0
2,1,1:1.0
3,1,1:1.0
4,1,1:1.0
5,1,1:1.0
6,1,1:1.0
7,1,1:1.0
8,1,1:1.0
9,1,1:1.0
10,1,1:1.0
11,1,1:1.0
12,1,1:1.0
13,1,1:1.0
14,1,1:1.0
15,1,1:1.0
16,1,1:1.0
17,1,1:1.0
18,1,1:1.0
19,1,1:1.0
20,1,1:1.0
-19,2,1:1.0
-18,2,1:1.0
-17,2,1:1.0
-16,2,1:1.0
-15,2,1:1.0
-14,2,1:1.0
-13,2,1:1.0
-12,2,1:1.0
-11,2,1:1.0
-10,2,1:1.0
-9,2,1:1.0
-8,2,1:1.0
-7,2,1:1.0
-6,2,1:1.0
-5,2,1:1.0
-4,2,1:1.0
-3,2,1:1.0
-2,2,1:1.0
-1,2,1:1.0
0,2,1:1.0
1,2,1:1.0
2,2,1:1.0
3,2,1:1.0
4,2,1:1.0
5,2,1:1.0
6,2,1:1.0
7,2,1:1.0
8,2,1:1.0
9,2,1:1.0
10,2,1:1.0
11,2,1:1.0
12,2,1:1.0
13,2,1:1.0
14,2,1:1.0
15,2,1:1.0
16,2,1:1.0
17,2,1:1.0
18,2,1:1.0
19,2,1:1.0
20,2,1:1.0
-19,3,1:1.0
-18,3,1:1.0
-17,3,1:1.0
-16,3,1:1.0
-15,3,1:1.0
-14,3,1:1.0
-13,3,1:1.0
-12,3,1:1.0
-11,3,1:1.0
-10,3,1:1.0
-9,3,1:1.0
-8,3,1:1.0
-7,3,1:1.0
-6,3,1:1.0
-5,3,1:1.0
-4,3,1:1.0
-3,3,1:1.0
-2,3,1:1.0
-1,3,1:1.0
0,3,1:1.0
1,3,1:1.0
2,3,1:1.0
3,3,1:1.0
4,3,1:1.0
5,3,1:1.0
6,3,1:1.0
7,3,1:1.0
8,3,1:1.0
9,3,1:1.0
10,3,1:1.0
11,3,1:1.0
12,3,1:1.0
13,3,1:1.0
14,3,1:1.0
15,3,1:1.0
16,3,1:1.0
17,3,1:1.0
18,3,1:1.0
19,3,1:1.0
20,3,1:1.0
-21,4,1:1.0
-20,4,1:1.0
-19,4,1:1.0
-18,4,1:1.0
-17,4,1:1.0
-16,4,1:1.0
-15,4,1:1.0
-14,4,1:1.0
-13,4,1:1.0
-12,4,1:1.0
-11,4,1:1.0
-10,4,1:1.0
-9,4,1:1.0
-8,4,1:1.0
-7,4,1:1.0
-6,4,1:1.0
-5,4,1:1.0
-4,4,1:1.0
-3,4,1:1.0
-2,4,1:1.0
-1,4,1:1.0
0,4,1:1.0
1,4,1:1.0
2,4,1:1.0
3,4,1:1.0
4,4,1:1.0
5,4,1:1.0
6,4,1:1.0
7,4,1:1.0
8,4,1:1.0
9,4,1:1.0
10,4,1:1.0
11,4,1:1.0
12,4,1:1.0
13,4,1:1.0
14,4,1:1.0
15,4,1:1.0
16,4,1:1.0
17,4,1:1.0
18,4,1:1.0
19,4,1:1.0
-22,5,1:1.0
-21,5,1:1.0
-20,5,1:1.0
-19,5,1:1.0
-18,5,1:1.0
-17,5,1:1.0
-16,5,1:1.0
-15,5,1:1.0
-14,5,1:1.0
-13,5,1:1.0
-12,5,1:1.0
-11,5,1:1.0
-10,5,1:1.0
-9,5,1:1.0
-8,5,1:1.0
-7,5,1:1.0
-6,5,1:1.0
-5,5,1:1.0
-4,5,1:1.0
-3,5,1:1.0
-2,5,1:1.0
-1,5,1:1.0
0,5,1:1.0
1,5,1:1.0
2,5,1:1.0
3,5,1:1.0
4,5,1:1.0
5,5,1:1.0
6,5,1:1.0
7,5,1:1.0
8,5,1:1.0
9,5,1:1.0
10,5,1:1.0
11,5,1:1.0
12,5,1:1.0
13,5,1:1.0
14,5,1:1.0
15,5,1:1.0
16,5,1:1.0
17,5,1:1.0
18,5,1:1.0
-22,6,1:1.0
-21,6,1:1.0
-20,6,1:1.0
-19,6,1:1.0
-18,6,1:1.0
-17,6,1:1.0
-16,6,1:1.0
-15,6,1:1.0
-14,6,1:1.0
-13,6,1:1.0
-12,6,1:1.0
-11,6,1:1.0
-10,6,1:1.0
-9,6,1:1.0
-8,6,1:1.0
-7,6,1:1.0
-6,6,1:1.0
-5,6,1:1.0
-4,6,1:1.0
-3,6,1:1.0
-2,6,1:1.0
-1,6,1:1.0
0,6,1:1.0
1,6,1:1.0
2,6,1:1.0
3,6,1:1.0
4,6,1:1.0
5,6,1:1.0
6,6,1:1.0
7,6,1:1.0
8,6,1:1.0
9,6,1:1.0
10,6,1:1.0
11,6,1:1.0
12,6,1:1.0
13,6,1:1.0
14,6,1:1.0
15,6,1:1.0
16,6,1:1.0
17,6,1:1.0
18,6,1:1.0
-22,7,1:1.0
-21,7,1:1.0
-20,7,1:1.0
-19,7,1:1.0
-18,7,1:1.0
-17,7,1:1.0
-16,7,1:1.0
-15,7,1:1.0
-14,7,1:1.0
-13,7,1:1.0
-12,7,1:1.0
-11,7,1:1.0
-10,7,1:1.0
-9,7,1:1.0
-8,7,1:1.0
-7,7,1:1.0
-6,7,1:1.0
-5,7,1:1.0
-4,7,1:1.0
-3,7,1:1.0
-2,7,1:1.0
-1,7,1:1.0
0,7,1:1.0
1,7,1:1.0
2,7,1:1.0
3,7,1:1.0
4,7,1:1.0
5,7,1:1.0
6,7,1:1.0
7,7,1:1.0
8,7,1:1.0
9,7,1:1.0
10,7,1:1.0
11,7,1:1.0
12,7,1:1.0
13,7,1:1.0
14,7,1:1.0
15,7,1:1.0
16,7,1:1.0
17,7,1:1.0
18,7,1:1.0
-22,8,1:1.0
-21,8,1:1.0
-20,8,1:1.0
-19,8,1:1.0
-18,8,1:1.0
-17,8,1:1.0
-16,8,1:1.0
-15,8,1:1.0
-14,8,1:1.0
-13,8,1:1.0
-12,8,1:1.0
-11,8,1:1.0
-10,8,1:1.0
-9,8,1:1.0
-8,8,1:1.0
-7,8,1:1.0
-6,8,1:1.0
-5,8,1:1.0
-4,8,1:1.0
-3,8,1:1.0
-2,8,1:1.0
-1,8,1:1.0
0,8,1:1.0
1,8,1:1.0
2,8,1:1.0
3,8,1:1.0
4,8,1:1.0
5,8,1:1.0
6,8,1:1.0
7,8,1:1.0
8,8,1:1.0
9,8,1:1.0
10,8,1:1.0
11,8,1:1.0
12,8,1:1.0
13,8,1:1.0
14,8,1:1.0
15,8,1:1.0
-22,9,1:1.0
-21,9,1:1.0
-20,9,1:1.0
-19,9,1:1.0
-18,9,1:1.0
-17,9,1:1.0
-16,9,1:1.0
-15,9,1:1.0
-14,9,1:1.0
-13,9,1:1.0
-12,9,1:1.0
-11,9,1:1.0
-10,9,1:1.0
-9,9,1:1.0
-8,9,1:1.0
-7,9,1:1.0
-6,9,1:1.0
-5,9,1:1.0
-4,9,1:1.0
-3,9,1:1.0
-2,9,1:1.0
-1,9,1:1.0
0,9,1:1.0
1,9,1:1.0
2,9,1:1.0
3,9,1:1.0
4,9,1:1.0
5,9,1:1.0
6,9,1:1.0
7,9,1:1.0
8,9,1:1.0
9,9,1:1.0
10,9,1:1.0
11,9,1:1.0
12,9,1:1.0
13,9,1:1.0
14,9,1:1.0
-22,10,1:1.0
-21,10,1:1.0
-20,10,1:1.0
-19,10,1:1.0
-18,10,1:1.0
-17,10,1:1.0
-16,10,1:1.0
-15,10,1:1.0
-14,10,1:1.0
-13,10,1:1.0
-12,10,1:1.0
-11,10,1:1.0
-10,10,1:1.0
-9,10,1:1.0
-8,10,1:1.0
-7,10,1:1.0
-6,10,1:1.0
-5,10,1:1.0
-4,10,1:1.0
-3,10,1:1.0
-2,10,1:1.0
-1,10,1:1.0
0,10,1:1.0
1,10,1:1.0
2,10,1:1.0
3,10,1:1.0
4,10,1:1.0
5,10,1:1.0
6,10,1:1.0
7,10,1:1.0
8,10,1:1.0
9,10,1:1.0
10,10,1:1.0
11,10,1:1.0
12,10,1:1.0
13,10,1:1.0
14,10,1:1.0
-21,11,1:1.0
-20,11,1:1.0
-19,11,1:1.0
-18,11,1:1.0
-17,11,1:1.0
-16,11,1:1.0
-15,11,1:1.0
-14,11,1:1.0
-13,11,1:1.0
-12,11,1:1.0
-11,11,1:1.0
-10,11,1:1.0
-9,11,1:1.0
-8,11,1:1.0
-7,11,1:1.0
-6,11,1:1.0
-5,11,1:1.0
-4,11,1:1.0
-3,11,1:1.0
-2,11,1:1.0
-1,11,1:1.0
0,11,1:1.0
1,11,1:1.0
2,11,1:1.0
3,11,1:1.0
4,11,1:1.0
5,11,1:1.0
6,11,1:1.0
7,11,1:1.0
8,11,1:1.0
9,11,1:1.0
10,11,1:1.0
11,11,1:1.0
12,11,1:1.0
13,11,1:1.0
14,11,1:1.0
-21,12,1:1.0
-20,12,1:1.0
-19,12,1:1.0
-18,12,1:1.0
-17,12,1:1.0
-16,12,1:1.0
-15,12,1:1.0
-14,12,1:1.0
-13,12,1:1.0
-12,12,1:1.0
-11,12,1:1.0
-10,12,1:1.0
-9,12,1:1.0
-8,12,1:1.0
-7,12,1:1.0
-6,12,1:1.0
-5,12,1:1.0
-4,12,1:1.0
-3,12,1:1.0
-2,12,1:1.0
-1,12,1:1.0
0,12,1:1.0
1,12,1:1.0
2,12,1:1.0
3,12,1:1.0
4,12,1:1.0
5,12,1:1.0
6,12,1:1.0
7,12,1:1.0
8,12,1:1.0
9,12,1:1.0
10,12,1:1.0
11,12,1:1.0
12,12,1:1.0
13,12,1:1.0
-21,13,1:1.0
-20,13,1:1.0
-19,13,1:1.0
-18,13,1:1.0
-17,13,1:1.0
-16,13,1:1.0
-15,13,1:1.0
-14,13,1:1.0
-13,13,1:1.0
-12,13,1:1.0
-11,13,1:1.0
-10,13,1:1.0
-9,13,1:1.0
-8,13,1:1.0
-7,13,1:1.0
-6,13,1:1.0
-5,13,1:1.0
-4,13,1:1.0
-3,13,1:1.0
-2,13,1:1.0
-1,13,1:1.0
0,13,1:1.0
1,13,1:1.0
2,13,1:1.0
3,13,1:1.0
4,13,1:1.0
5,13,1:1.0
6,13,1:1.0
7,13,1:1.0
8,13,1:1.0
9,13,1:1.0
10,13,1:1.0
11,13,1:1.0
12,13,1:1.0
13,13,1:1.0
-21,14,1:1.0
-20,14,1:1.0
-19,14,1:1.0
-18,14,1:1.0
-17,14,1:1.0
-16,14,1:1.0
-15,14,1:1.0
-14,14,1:1.0
-13,14,1:1.0
-12,14,1:1.0
-11,14,1:1.0
-10,14,1:1.0
-9,14,1:1.0
-8,14,1:1.0
-7,14,1:1.0
-6,14,1:1.0
-5,14,1:1.0
-4,14,1:1.0
-3,14,1:1.0
-2,14,1:1.0
-1,14,1:1.0
0,14,1:1.0
1,14,1:1.0
2,14,1:1.0
3,14,1:1.0
4,14,1:1.0
5,14,1:1.0
-20,15,1:1.0
-19,15,1:1.0
-18,15,1:1.0
-17,15,1:1.0
-16,15,1:1.0
-15,15,1:1.0
-14,15,1:1.0
-13,15,1:1.0
-12,15,1:1.0
-11,15,1:1.0
-10,15,1:1.0
-9,15,1:1.0
-8,15,1:1.0
-7,15,1:1.0
-6,15,1:1.0
-5,15,1:1.0
-4,15,1:1.0
-3,15,1:1.0
-2,15,1:1.0
-1,15,1:1.0
0,15,1:1.0
1,15,1:1.0
2,15,1:1.0
3,15,1:1.0
4,15,1:1.0
5,15,1:1.0
-18,16,1:1.0
-17,16,1:1.0
-16,16,1:1.0
-15,16,1:1.0
-14,16,1:1.0
-13,16,1:1.0
-12,16,1:1.0
-11,16,1:1.0
-10,16,1:1.0
-9,16,1:1.0
-8,16,1:1.0
-7,16,1:1.0
-6,16,1:1.0
-5,16,1:1.0
-4,16,1:1.0
-3,16,1:1.0
-2,16,1:1.0
-1,16,1:1.0
0,16,1:1.0
1,16,1:1.0
2,16,1:1.0
3,16,1:1.0
-16,17,1:1.0
-15,17,1:1.0
-14,17,1:1.0
-13,17,1:1.0
-12,17,1:1.0
-11,17,1:1.0
-10,17,1:1.0
-9,17,1:1.0
-8,17,1:1.0
-7,17,1:1.0
-6,17,1:1.0
-5,17,1:1.0
-4,17,1:1.0
-3,17,1:1.0
-2,17,1:1.0
-1,17,1:1.0
0,17,1:1.0
1,17,1:1.0
-14,18,1:1.0
-13,18,1:1.0
-12,18,1:1.0
-11,18,1:1.0
-10,18,1:1.0
-9,18,1:1.0
-8,18,1:1.0
-7,18,1:1.0
-6,18,1:1.0
-5,18,1:1.0
-4,18,1:1.0
-3,18,1:1.0
-2,18,1:1.0
-1,18,1:1.0
0,18,1:1.0
1,18,1:1.0
-11,19,1:1.0
-10,19,1:1.0
-9,19,1:1.0
-8,19,1:1.0
-7,19,1:1.0
-6,19,1:1.0
-5,19,1:1.0
-4,19,1:1.0
-3,19,1:1.0
-2,19,1:1.0
-1,19,1:1.0
0,19,1:1.0
1,19,1:1.0
-8,20,1:1.0
-7,20,1:1.0
-6,20,1:1.0
-5,20,1:1.0
-4,20,1:1.0
-3,20,1:1.0
-2,20,1:1.0
-1,20,1:1.0
0,20,1:1.0
2,-22,2:1.0
3,-22,2:1.0
4,-22,2:1.0
5,-22,2:1.0
6,-22,2:1.0
7,-22,2:1.0
8,-22,2:1.0
9,-22,2:1.0
10,-22,2:1.0
11,-22,2:1.0
12,-22,2:1.0
13,-22,2:1.0
0,-21,2:1.0
1,-21,2:1.0
2,-21,2:9.0
3,-21,2:9.0
4,-21,2:9.0
5,-21,2:9.0
6,-21,2:9.0
7,-21,2:9.0
8,-21,2:9.0
9,-21,2:9.0
10,-21,2:9.0
11,-21,2:9.0
12,-21,2:9.0
13,-21,2:9.0
14,-21,2:1.0
15,-21,2:1.0
16,-21,2:1.0
-1,-20,2:1.0
0,-20,2:9.0
1,-20,2:9.0
2,-20,2:9.0
3,-20,2:9.0
4,-20,2:9.0
5,-20,2:110.0
6,-20,2:110.0
7,-20,2:110.0
8,-20,2:110.0
9,-20,2:9.0
10,-20,2:9.0
11,-20,2:9.0
12,-20,2:9.0
13,-20,2:9.0
14,-20,2:9.0
15,-20,2:9.0
16,-20,2:9.0
17,-20,2:1.0
18,-20,2:1.0
-1,-19,2:1.0
0,-19,2:9.0
1,-19,2:9.0
2,-19,2:9.0
3,-19,2:110.0
4,-19,2:110.0
5,-19,2:110.0
6,-19,2:110.0
7,-19,2:3.0
8,-19,2:110.0
9,-19,2:110.0
10,-19,2:110.0
11,-19,2:9.0
12,-19,2:110.0
13,-19,2:110.0
14,-19,2:110.0
15,-19,2:9.0
16,-19,2:9.0
17,-19,2:9.0
18,-19,2:1.0
19,-19,2:1.0
20,-19,2:1.0
-2,-18,2:1.0
-1,-18,2:9.0
0,-18,2:9.0
1,-18,2:110.0
2,-18,2:110.0
3,-18,2:3.0
4,-18,2:110.0
5,-18,2:110.0
6,-18,2:110.0
7,-18,2:110.0
8,-18,2:110.0
9,-18,2:110.0
10,-18,2:3.0
11,-18,2:110.0
12,-18,2:110.0
13,-18,2:110.0
14,-18,2:110.0
15,-18,2:110.0
16,-18,2:9.0
17,-18,2:9.0
18,-18,2:9.0
19,-18,2:9.0
20,-18,2:9.0
21,-18,2:1.0
-2,-17,2:1.0
-1,-17,2:9.0
0,-17,2:9.0
1,-17,2:110.0
2,-17,2:110.0
3,-17,2:110.0
4,-17,2:110.0
5,-17,2:110.0
6,-17,2:3.0
7,-17,2:110.0
8,-17,2:110.0
9,-17,2:110.0
10,-17,2:110.0
11,-17,2:110.0
12,-17,2:110.0
13,-17,2:110.0
14,-17,2:3.0
15,-17,2:110.0
16,-17,2:110.0
17,-17,2:9.0
18,-17,2:9.0
19,-17,2:9.0
20,-17,2:9.0
21,-17,2:1.0
-6,-16,2:1.0
-5,-16,2:1.0
-4,-16,2:1.0
-3,-16,2:1.0
-2,-16,2:9.0
-1,-16,2:9.0
0,-16,2:9.0
1,-16,2:110.0
2,-16,2:110.0
3,-16,2:110.0
4,-16,2:3.0
5,-16,2:110.0
6,-16,2:110.0
7,-16,2:110.0
8,-16,2:110.0
9,-16,2:3.0
10,-16,2:110.0
11,-16,2:110.0
12,-16,2:3.0
13,-16,2:110.0
14,-16,2:110.0
15,-16,2:110.0
16,-16,2:110.0
17,-16,2:110.0
18,-16,2:110.0
19,-16,2:9.0
20,-16,2:9.0
21,-16,2:1.0
-7,-15,2:1.0
-6,-15,2:1.0
-5,-15,2:110.0
-4,-15,2:9.0
-3,-15,2:9.0
-2,-15,2:9.0
-1,-15,2:9.0
0,-15,2:110.0
1,-15,2:110.0
2,-15,2:3.0
3,-15,2:110.0
4,-15,2:110.0
5,-15,2:110.0
6,-15,2:110.0
7,-15,2:110.0
8,-15,2:110.0
9,-15,2:110.0
10,-15,2:110.0
11,-15,2:110.0
12,-15,2:110.0
13,-15,2:110.0
14,-15,2:110.0
15,-15,2:110.0
16,-15,2:110.0
17,-15,2:3.0
18,-15,2:110.0
19,-15,2:9.0
20,-15,2:9.0
21,-15,2:1.0
-11,-14,2:1.0
-10,-14,2:1.0
-9,-14,2:1.0
-8,-14,2:1.0
-7,-14,2:1.0
-6,-14,2:110.0
-5,-14,2:110.0
-4,-14,2:110.0
-3,-14,2:9.0
-2,-14,2:9.0
-1,-14,2:9.0
0,-14,2:110.0
1,-14,2:110.0
2,-14,2:110.0
3,-14,2:110.0
4,-14,2:3.0
5,-14,2:110.0
6,-14,2:110.0
7,-14,2:3.0
8,-14,2:110.0
9,-14,2:110.0
10,-14,2:3.0
11,-14,2:110.0
12,-14,2:110.0
13,-14,2:110.0
14,-14,2:110.0
15,-14,2:3.0
16,-14,2:110.0
17,-14,2:110.0
18,-14,2:110.0
19,-14,2:9.0
20,-14,2:9.0
21,-14,2:1.0
-12,-13,2:1.0
-11,-13,2:1.0
-10,-13,2:1.0
-9,-13,2:110.0
-8,-13,2:110.0
-7,-13,2:110.0
-6,-13,2:3.0
-5,-13,2:110.0
-4,-13,2:3.0
-3,-13,2:9.0
-2,-13,2:9.0
-1,-13,2:110.0
0,-13,2:110.0
1,-13,2:110.0
2,-13,2:3.0
3,-13,2:110.0
4,-13,2:110.0
5,-13,2:110.0
6,-13,2:110.0
7,-13,2:110.0
8,-13,2:110.0
9,-13,2:110.0
10,-13,2:110.0
11,-13,2:110.0
12,-13,2:110.0
13,-13,2:3.0
14,-13,2:110.0
15,-13,2:110.0
16,-13,2:110.0
17,-13,2:3.0
18,-13,2:110.0
19,-13,2:110.0
20,-13,2:9.0
21,-13,2:1.0
-13,-12,2:1.0
-12,-12,2:1.0
-11,-12,2:1.0
-10,-12,2:1.0
-9,-12,2:110.0
-8,-12,2:110.0
-7,-12,2:3.0
-6,-12,2:110.0
-5,-12,2:110.0
-4,-12,2:110.0
-3,-12,2:9.0
-2,-12,2:9.0
-1,-12,2:110.0
0,-12,2:3.0
1,-12,2:110.0
2,-12,2:110.0
3,-12,2:110.0
4,-12,2:110.0
5,-12,2:110.0
6,-12,2:110.0
7,-12,2:110.0
8,-12,2:110.0
9,-12,2:110.0
10,-12,2:110.0
11,-12,2:3.0
12,-12,2:110.0
13,-12,2:110.0
14,-12,2:110.0
15,-12,2:110.0
16,-12,2:110.0
17,-12,2:110.0
18,-12,2:110.0
19,-12,2:9.0
20,-12,2:9.0
21,-12,2:1.0
-14,-11,2:1.0
-13,-11,2:1.0
-12,-11,2:1.0
-11,-11,2:1.0
-10,-11,2:110.0
-9,-11,2:3.0
-8,-11,2:110.0
-7,-11,2:110.0
-6,-11,2:110.0
-5,-11,2:9.0
-4,-11,2:9.0
-3,-11,2:9.0
-2,-11,2:9.0
-1,-11,2:110.0
0,-11,2:110.0
1,-11,2:110.0
2,-11,2:3.0
3,-11,2:110.0
4,-11,2:110.0
5,-11,2:110.0
6,-11,2:3.0
7,-11,2:110.0
8,-11,2:110.0
9,-11,2:3.0
10,-11,2:110.0
11,-11,2:110.0
12,-11,2:110.0
13,-11,2:110.0
14,-11,2:3.0
15,-11,2:110.0
16,-11,2:110.0
17,-11,2:110.0
18,-11,2:3.0
19,-11,2:9.0
20,-11,2:9.0
21,-11,2:1.0
-14,-10,2:1.0
-13,-10,2:1.0
-12,-10,2:110.0
-11,-10,2:110.0
-10,-10,2:110.0
-9,-10,2:110.0
-8,-10,2:110.0
-7,-10,2:3.0
-6,-10,2:110.0
-5,-10,2:9.0
-4,-10,2:9.0
-3,-10,2:9.0
-2,-10,2:9.0
-1,-10,2:110.0
0,-10,2:3.0
1,-10,2:110.0
2,-10,2:110.0
3,-10,2:110.0
4,-10,2:100.15
5,-10,2:110.0
6,-10,2:110.0
7,-10,2:110.0
8,-10,2:110.0
9,-10,2:110.0
10,-10,2:110.0
11,-10,2:110.0
12,-10,2:3.0
13,-10,2:110.0
14,-10,2:110.0
15,-10,2:100.15
16,-10,2:3.0
17,-10,2:110.0
18,-10,2:110.0
19,-10,2:9.0
20,-10,2:9.0
21,-10,2:1.0
-15,-9,2:1.0
-14,-9,2:1.0
-13,-9,2:1.0
-12,-9,2:110.0
-11,-9,2:110.0
-10,-9,2:3.0
-9,-9,2:110.0
-8,-9,2:110.0
-7,-9,2:3.0
-6,-9,2:110.0
-5,-9,2:9.0
-4,-9,2:9.0
-3,-9,2:9.0
-2,-9,2:110.0
-1,-9,2:110.0
0,-9,2:110.0
1,-9,2:110.0
2,-9,2:110.0
3,-9,2:110.0
4,-9,2:110.0
5,-9,2:100.15
6,-9,2:100.15
7,-9,2:110.0
8,-9,2:3.0
9,-9,2:110.0
10,-9,2:110.0
11,-9,2:110.0
12,-9,2:110.0
13,-9,2:110.0
14,-9,2:3.0
15,-9,2:110.0
16,-9,2:110.0
17,-9,2:110.0
18,-9,2:110.0
19,-9,2:9.0
20,-9,2:9.0
21,-9,2:9.0
22,-9,2:1.0
-15,-8,2:1.0
-14,-8,2:1.0
-13,-8,2:1.0
-12,-8,2:110.0
-11,-8,2:3.0
-10,-8,2:110.0
-9,-8,2:110.0
-8,-8,2:110.0
-7,-8,2:110.0
-6,-8,2:110.0
-5,-8,2:9.0
-4,-8,2:9.0
-3,-8,2:110.0
-2,-8,2:3.0
-1,-8,2:110.0
0,-8,2:110.0
1,-8,2:110.0
2,-8,2:3.0
3,-8,2:110.0
4,-8,2:3.0
5,-8,2:110.0
6,-8,2:100.15
7,-8,2:110.0
8,-8,2:110.0
9,-8,2:100.15
10,-8,2:110.0
11,-8,2:110.0
12,-8,2:110.0
13,-8,2:110.0
14,-8,2:110.0
15,-8,2:110.0
16,-8,2:110.0
17,-8,2:110.0
18,-8,2:3.0
19,-8,2:110.0
20,-8,2:110.0
21,-8,2:9.0
22,-8,2:1.0
-15,-7,2:1.0
-14,-7,2:1.0
-13,-7,2:110.0
-12,-7,2:110.0
-11,-7,2:110.0
-10,-7,2:110.0
-9,-7,2:3.0
-8,-7,2:110.0
-7,-7,2:110.0
-6,-7,2:9.0
-5,-7,2:9.0
-4,-7,2:9.0
-3,-7,2:110.0
-2,-7,2:110.0
-1,-7,2:110.0
0,-7,2:110.0
1,-7,2:110.0
2,-7,2:110.0
3,-7,2:110.0
4,-7,2:110.0
5,-7,2:110.0
6,-7,2:100.15
7,-7,2:110.0
8,-7,2:100.15
9,-7,2:110.0
10,-7,2:110.0
11,-7,2:110.0
12,-7,2:100.15
13,-7,2:110.0
14,-7,2:110.0
15,-7,2:110.0
16,-7,2:110.0
17,-7,2:3.0
18,-7,2:110.0
19,-7,2:110.0
20,-7,2:110.0
21,-7,2:9.0
22,-7,2:1.0
-16,-6,2:1.0
-15,-6,2:1.0
-14,-6,2:1.0
-13,-6,2:3.0
-12,-6,2:110.0
-11,-6,2:3.0
-10,-6,2:110.0
-9,-6,2:110.0
-8,-6,2:110.0
-7,-6,2:110.0
-6,-6,2:9.0
-5,-6,2:9.0
-4,-6,2:9.0
-3,-6,2:110.0
-2,-6,2:110.0
-1,-6,2:110.0
0,-6,2:110.0
1,-6,2:3.0
2,-6,2:110.0
3,-6,2:110.0
4,-6,2:110.0
5,-6,2:3.0
6,-6,2:110.0
7,-6,2:3.0
8,-6,2:110.0
9,-6,2:3.0
10,-6,2:110.0
11,-6,2:100.15
12,-6,2:110.0
13,-6,2:110.0
14,-6,2:3.0
15,-6,2:110.0
16,-6,2:110.0
17,-6,2:110.0
18,-6,2:110.0
19,-6,2:9.0
20,-6,2:9.0
21,-6,2:9.0
22,-6,2:1.0
-16,-5,2:1.0
-15,-5,2:1.0
-14,-5,2:110.0
-13,-5,2:110.0
-12,-5,2:110.0
-11,-5,2:110.0
-10,-5,2:110.0
-9,-5,2:3.0
-8,-5,2:110.0
-7,-5,2:9.0
-6,-5,2:9.0
-5,-5,2:9.0
-4,-5,2:9.0
-3,-5,2:9.0
-2,-5,2:110.0
-1,-5,2:110.0
0,-5,2:110.0
1,-5,2:110.0
2,-5,2:110.0
3,-5,2:110.0
4,-5,2:100.15
5,-5,2:110.0
6,-5,2:3.0
7,-5,2:3.0
8,-5,2:3.0
9,-5,2:110.0
10,-5,2:100.15
11,-5,2:110.0
12,-5,2:110.0
13,-5,2:110.0
14,-5,2:110.0
15,-5,2:110.0
16,-5,2:3.0
17,-5,2:110.0
18,-5,2:110.0
19,-5,2:9.0
20,-5,2:9.0
21,-5,2:1.0
-16,-4,2:1.0
-15,-4,2:1.0
-14,-4,2:110.0
-13,-4,2:3.0
-12,-4,2:110.0
-11,-4,2:110.0
-10,-4,2:110.0
-9,-4,2:110.0
-8,-4,2:9.0
-7,-4,2:9.0
-6,-4,2:9.0
-5,-4,2:9.0
-4,-4,2:9.0
-3,-4,2:9.0
-2,-4,2:9.0
-1,-4,2:110.0
0,-4,2:110.0
1,-4,2:110.0
2,-4,2:110.0
3,-4,2:100.15
4,-4,2:110.0
5,-4,2:3.0
6,-4,2:3.0
7,-4,2:3.0
8,-4,2:3.0
9,-4,2:3.0
10,-4,2:110.0
11,-4,2:110.0
12,-4,2:110.0
13,-4,2:3.0
14,-4,2:110.0
15,-4,2:3.0
16,-4,2:110.0
17,-4,2:110.0
18,-4,2:110.0
19,-4,2:9.0
20,-4,2:9.0
21,-4,2:1.0
-17,-3,2:1.0
-16,-3,2:1.0
-15,-3,2:1.0
-14,-3,2:110.0
-13,-3,2:110.0
-12,-3,2:110.0
-11,-3,2:3.0
-10,-3,2:110.0
-9,-3,2:9.0
-8,-3,2:9.0
-7,-3,2:9.0
-6,-3,2:9.0
-5,-3,2:9.0
-4,-3,2:9.0
-3,-3,2:9.0
-2,-3,2:9.0
-1,-3,2:9.0
0,-3,2:110.0
1,-3,2:3.0
2,-3,2:110.0
3,-3,2:110.0
4,-3,2:100.15
5,-3,2:110.0
6,-3,2:3.0
7,-3,2:3.0
8,-3,2:3.0
9,-3,2:110.0
10,-3,2:100.15
11,-3,2:110.0
12,-3,2:110.0
13,-3,2:110.0
14,-3,2:110.0
15,-3,2:110.0
16,-3,2:110.0
17,-3,2:110.0
18,-3,2:110.0
19,-3,2:9.0
20,-3,2:9.0
21,-3,2:1.0
-18,-2,2:1.0
-17,-2,2:1.0
-16,-2,2:1.0
-15,-2,2:1.0
-14,-2,2:110.0
-13,-2,2:110.0
-12,-2,2:3.0
-11,-2,2:110.0
-10,-2,2:9.0
-9,-2,2:9.0
-8,-2,2:9.0
-7,-2,2:9.0
-6,-2,2:9.0
-5,-2,2:9.0
-4,-2,2:9.0
-3,-2,2:9.0
-2,-2,2:9.0
-1,-2,2:9.0
0,-2,2:9.0
1,-2,2:110.0
2,-2,2:110.0
3,-2,2:110.0
4,-2,2:3.0
5,-2,2:110.0
6,-2,2:3.0
7,-2,2:3.0
8,-2,2:110.0
9,-2,2:3.0
10,-2,2:110.0
11,-2,2:110.0
12,-2,2:110.0
13,-2,2:3.0
14,-2,2:110.0
15,-2,2:110.0
16,-2,2:3.0
17,-2,2:110.0
18,-2,2:110.0
19,-2,2:9.0
20,-2,2:1.0
-18,-1,2:1.0
-17,-1,2:1.0
-16,-1,2:1.0
-15,-1,2:110.0
-14,-1,2:110.0
-13,-1,2:3.0
-12,-1,2:110.0
-11,-1,2:9.0
-10,-1,2:9.0
-9,-1,2:9.0
-8,-1,2:9.0
-7,-1,2:9.0
-6,-1,2:9.0
-5,-1,2:9.0
-4,-1,2:9.0
-3,-1,2:9.0
-2,-1,2:9.0
-1,-1,2:9.0
0,-1,2:110.0
1,-1,2:110.0
2,-1,2:110.0
3,-1,2:3.0
4,-1,2:110.0
5,-1,2:3.0
6,-1,2:100.15
7,-1,2:3.0
8,-1,2:110.0
9,-1,2:110.0
10,-1,2:110.0
11,-1,2:100.15
12,-1,2:110.0
13,-1,2:110.0
14,-1,2:110.0
15,-1,2:110.0
16,-1,2:110.0
17,-1,2:110.0
18,-1,2:110.0
19,-1,2:9.0
20,-1,2:1.0
-18,0,2:1.0
-17,0,2:1.0
-16,0,2:110.0
-15,0,2:110.0
-14,0,2:110.0
-13,0,2:110.0
-12,0,2:110.0
-11,0,2:9.0
-10,0,2:9.0
-9,0,2:9.0
-8,0,2:9.0
-7,0,2:9.0
-6,0,2:9.0
-5,0,2:9.0
-4,0,2:9.0
-3,0,2:9.0
-2,0,2:9.0
-1,0,2:110.0
0,0,2:3.0
1,0,2:110.0
2,0,2:110.0
3,0,2:110.0
4,0,2:110.0
5,0,2:100.15
6,0,2:110.0
7,0,2:3.0
8,0,2:100.15
9,0,2:110.0
10,0,2:100.15
11,0,2:110.0
12,0,2:110.0
13,0,2:110.0
14,0,2:110.0
15,0,2:3.0
16,0,2:110.0
17,0,2:110.0
18,0,2:9.0
19,0,2:9.0
20,0,2:1.0
-19,1,2:1.0
-18,1,2:1.0
-17,1,2:1.0
-16,1,2:110.0
-15,1,2:3.0
-14,1,2:3.0
-13,1,2:110.0
-12,1,2:3.0
-11,1,2:110.0
-10,1,2:9.0
-9,1,2:9.0
-8,1,2:9.0
-7,1,2:9.0
-6,1,2:9.0
-5,1,2:9.0
-4,1,2:9.0
-3,1,2:9.0
-2,1,2:110.0
-1,1,2:110.0
0,1,2:110.0
1,1,2:110.0
2,1,2:110.0
3,1,2:110.0
4,1,2:100.15
5,1,2:110.0
6,1,2:110.0
7,1,2:110.0
8,1,2:110.0
9,1,2:100.15
10,1,2:110.0
11,1,2:3.0
12,1,2:110.0
13,1,2:3.0
14,1,2:110.0
15,1,2:110.0
16,1,2:3.0
17,1,2:110.0
18,1,2:9.0
19,1,2:9.0
20,1,2:1.0
-19,2,2:1.0
-18,2,2:1.0
-17,2,2:110.0
-16,2,2:110.0
-15,2,2:110.0
-14,2,2:110.0
-13,2,2:110.0
-12,2,2:110.0
-11,2,2:110.0
-10,2,2:9.0
-9,2,2:9.0
-8,2,2:9.0
-7,2,2:9.0
-6,2,2:9.0
-5,2,2:9.0
-4,2,2:9.0
-3,2,2:110.0
-2,2,2:110.0
-1,2,2:110.0
0,2,2:3.0
1,2,2:110.0
2,2,2:3.0
3,2,2:110.0
4,2,2:110.0
5,2,2:3.0
6,2,2:110.0
7,2,2:110.0
8,2,2:3.0
9,2,2:110.0
10,2,2:110.0
11,2,2:110.0
12,2,2:110.0
13,2,2:110.0
14,2,2:3.0
15,2,2:110.0
16,2,2:110.0
17,2,2:110.0
18,2,2:110.0
19,2,2:9.0
20,2,2:1.0
-19,3,2:1.0
-18,3,2:1.0
-17,3,2:1.0
-16,3,2:110.0
-15,3,2:110.0
-14,3,2:110.0
-13,3,2:110.0
-12,3,2:110.0
-11,3,2:110.0
-10,3,2:110.0
-9,3,2:110.0
-8,3,2:9.0
-7,3,2:9.0
-6,3,2:9.0
-5,3,2:9.0
-4,3,2:110.0
-3,3,2:3.0
-2,3,2:110.0
-1,3,2:110.0
0,3,2:110.0
1,3,2:110.0
2,3,2:110.0
3,3,2:110.0
4,3,2:110.0
5,3,2:110.0
6,3,2:110.0
7,3,2:110.0
8,3,2:110.0
9,3,2:110.0
10,3,2:110.0
11,3,2:3.0
12,3,2:110.0
13,3,2:110.0
14,3,2:110.0
15,3,2:110.0
16,3,2:110.0
17,3,2:9.0
18,3,2:9.0
19,3,2:9.0
20,3,2:1.0
-21,4,2:1.0
-20,4,2:1.0
-19,4,2:1.0
-18,4,2:1.0
-17,4,2:1.0
-16,4,2:110.0
-15,4,2:110.0
-14,4,2:110.0
-13,4,2:110.0
-12,4,2:110.0
-11,4,2:110.0
-10,4,2:110.0
-9,4,2:110.0
-8,4,2:9.0
-7,4,2:9.0
-6,4,2:9.0
-5,4,2:110.0
-4,4,2:110.0
-3,4,2:110.0
-2,4,2:3.0
-1,4,2:110.0
0,4,2:3.0
1,4,2:110.0
2,4,2:110.0
3,4,2:3.0
4,4,2:110.0
5,4,2:110.0
6,4,2:3.0
7,4,2:3.0
8,4,2:110.0
9,4,2:3.0
10,4,2:110.0
11,4,2:110.0
12,4,2:110.0
13,4,2:3.0
14,4,2:110.0
15,4,2:3.0
16,4,2:110.0
17,4,2:9.0
18,4,2:9.0
19,4,2:1.0
-22,5,2:1.0
-21,5,2:1.0
-20,5,2:1.0
-19,5,2:1.0
-18,5,2:1.0
-17,5,2:110.0
-16,5,2:110.0
-15,5,2:110.0
-14,5,2:110.0
-13,5,2:110.0
-12,5,2:110.0
-11,5,2:110.0
-10,5,2:110.0
-9,5,2:110.0
-8,5,2:9.0
-7,5,2:9.0
-6,5,2:9.0
-5,5,2:110.0
-4,5,2:110.0
-3,5,2:110.0
-2,5,2:110.0
-1,5,2:110.0
0,5,2:110.0
1,5,2:110.0
2,5,2:3.0
3,5,2:110.0
4,5,2:110.0
5,5,2:110.0
6,5,2:110.0
7,5,2:3.0
8,5,2:110.0
9,5,2:110.0
10,5,2:110.0
11,5,2:3.0
12,5,2:110.0
13,5,2:110.0
14,5,2:110.0
15,5,2:9.0
16,5,2:110.0
17,5,2:9.0
18,5,2:1.0
-22,6,2:1.0
-21,6,2:1.0
-20,6,2:1.0
-19,6,2:110.0
-18,6,2:110.0
-17,6,2:110.0
-16,6,2:110.0
-15,6,2:110.0
-14,6,2:110.0
-13,6,2:110.0
-12,6,2:110.0
-11,6,2:110.0
-10,6,2:110.0
-9,6,2:110.0
-8,6,2:9.0
-7,6,2:9.0
-6,6,2:9.0
-5,6,2:9.0
-4,6,2:110.0
-3,6,2:110.0
-2,6,2:110.0
-1,6,2:110.0
0,6,2:110.0
1,6,2:110.0
2,6,2:110.0
3,6,2:110.0
4,6,2:3.0
5,6,2:110.0
6,6,2:3.0
7,6,2:110.0
8,6,2:110.0
9,6,2:3.0
10,6,2:110.0
11,6,2:110.0
12,6,2:110.0
13,6,2:3.0
14,6,2:110.0
15,6,2:9.0
16,6,2:9.0
17,6,2:9.0
18,6,2:1.0
-22,7,2:1.0
-21,7,2:1.0
-20,7,2:110.0
-19,7,2:110.0
-18,7,2:110.0
-17,7,2:110.0
-16,7,2:110.0
-15,7,2:110.0
-14,7,2:110.0
-13,7,2:110.0
-12,7,2:110.0
-11,7,2:110.0
-10,7,2:110.0
-9,7,2:110.0
-8,7,2:3.0
-7,7,2:9.0
-6,7,2:9.0
-5,7,2:9.0
-4,7,2:9.0
-3,7,2:9.0
-2,7,2:9.0
-1,7,2:110.0
0,7,2:110.0
1,7,2:3.0
2,7,2:110.0
3,7,2:3.0
4,7,2:110.0
5,7,2:110.0
6,7,2:110.0
7,7,2:110.0
8,7,2:110.0
9,7,2:110.0
10,7,2:110.0
11,7,2:110.0
12,7,2:110.0
13,7,2:110.0
14,7,2:9.0
15,7,2:9.0
16,7,2:9.0
17,7,2:9.0
18,7,2:1.0
-22,8,2:1.0
-21,8,2:1.0
-20,8,2:110.0
-19,8,2:110.0
-18,8,2:110.0
-17,8,2:110.0
-16,8,2:110.0
-15,8,2:110.0
-14,8,2:110.0
-13,8,2:110.0
-12,8,2:110.0
-11,8,2:110.0
-10,8,2:110.0
-9,8,2:110.0
-8,8,2:110.0
-7,8,2:110.0
-6,8,2:110.0
-5,8,2:9.0
-4,8,2:9.0
-3,8,2:9.0
-2,8,2:9.0
-1,8,2:110.0
0,8,2:110.0
1,8,2:110.0
2,8,2:110.0
3,8,2:110.0
4,8,2:110.0
5,8,2:110.0
6,8,2:3.0
7,8,2:110.0
8,8,2:110.0
9,8,2:3.0
10,8,2:110.0
11,8,2:3.0
12,8,2:110.0
13,8,2:110.0
14,8,2:9.0
15,8,2:1.0
16,8,2:1.0
17,8,2:1.0
-22,9,2:1.0
-21,9,2:1.0
-20,9,2:1.0
-19,9,2:110.0
-18,9,2:110.0
-17,9,2:110.0
-16,9,2:110.0
-15,9,2:110.0
-14,9,2:110.0
-13,9,2:110.0
-12,9,2:110.0
-11,9,2:110.0
-10,9,2:110.0
-9,9,2:110.0
-8,9,2:110.0
-7,9,2:110.0
-6,9,2:110.0
-5,9,2:110.0
-4,9,2:3.0
-3,9,2:9.0
-2,9,2:9.0
-1,9,2:9.0
0,9,2:9.0
1,9,2:9.0
2,9,2:110.0
3,9,2:110.0
4,9,2:110.0
5,9,2:110.0
6,9,2:3.0
7,9,2:110.0
8,9,2:110.0
9,9,2:110.0
10,9,2:110.0
11,9,2:3.0
12,9,2:110.0
13,9,2:9.0
14,9,2:9.0
15,9,2:1.0
-22,10,2:1.0
-21,10,2:1.0
-20,10,2:1.0
-19,10,2:110.0
-18,10,2:110.0
-17,10,2:110.0
-16,10,2:110.0
-15,10,2:110.0
-14,10,2:110.0
-13,10,2:110.0
-12,10,2:110.0
-11,10,2:110.0
-10,10,2:110.0
-9,10,2:110.0
-8,10,2:110.0
-7,10,2:110.0
-6,10,2:3.0
-5,10,2:110.0
-4,10,2:110.0
-3,10,2:110.0
-2,10,2:110.0
-1,10,2:9.0
0,10,2:9.0
1,10,2:9.0
2,10,2:9.0
3,10,2:9.0
4,10,2:9.0
5,10,2:110.0
6,10,2:110.0
7,10,2:110.0
8,10,2:3.0
9,10,2:110.0
10,10,2:110.0
11,10,2:110.0
12,10,2:9.0
13,10,2:9.0
14,10,2:1.0
-21,11,2:1.0
-20,11,2:1.0
-19,11,2:110.0
-18,11,2:110.0
-17,11,2:110.0
-16,11,2:110.0
-15,11,2:110.0
-14,11,2:110.0
-13,11,2:110.0
-12,11,2:110.0
-11,11,2:110.0
-10,11,2:110.0
-9,11,2:110.0
-8,11,2:110.0
-7,11,2:110.0
-6,11,2:110.0
-5,11,2:110.0
-4,11,2:110.0
-3,11,2:110.0
-2,11,2:110.0
-1,11,2:110.0
0,11,2:110.0
1,11,2:110.0
2,11,2:9.0
3,11,2:9.0
4,11,2:9.0
5,11,2:9.0
6,11,2:9.0
7,11,2:110.0
8,11,2:110.0
9,11,2:110.0
10,11,2:110.0
11,11,2:9.0
12,11,2:9.0
13,11,2:9.0
14,11,2:1.0
-21,12,2:1.0
-20,12,2:1.0
-19,12,2:1.0
-18,12,2:110.0
-17,12,2:110.0
-16,12,2:110.0
-15,12,2:110.0
-14,12,2:110.0
-13,12,2:110.0
-12,12,2:110.0
-11,12,2:110.0
-10,12,2:110.0
-9,12,2:110.0
-8,12,2:110.0
-7,12,2:110.0
-6,12,2:110.0
-5,12,2:110.0
-4,12,2:110.0
-3,12,2:3.0
-2,12,2:110.0
-1,12,2:110.0
0,12,2:110.0
1,12,2:3.0
2,12,2:110.0
3,12,2:110.0
4,12,2:110.0
5,12,2:1.0
6,12,2:9.0
7,12,2:9.0
8,12,2:9.0
9,12,2:9.0
10,12,2:9.0
11,12,2:9.0
12,12,2:9.0
13,12,2:1.0
-21,13,2:1.0
-20,13,2:1.0
-19,13,2:1.0
-18,13,2:110.0
-17,13,2:110.0
-16,13,2:110.0
-15,13,2:3.0
-14,13,2:110.0
-13,13,2:110.0
-12,13,2:3.0
-11,13,2:110.0
-10,13,2:110.0
-9,13,2:110.0
-8,13,2:110.0
-7,13,2:110.0
-6,13,2:110.0
-5,13,2:3.0
-4,13,2:110.0
-3,13,2:110.0
-2,13,2:110.0
-1,13,2:3.0
0,13,2:110.0
1,13,2:110.0
2,13,2:110.0
3,13,2:110.0
4,13,2:110.0
5,13,2:1.0
6,13,2:1.0
7,13,2:1.0
8,13,2:1.0
9,13,2:1.0
10,13,2:1.0
11,13,2:1.0
12,13,2:1.0
13,13,2:1.0
-21,14,2:1.0
-20,14,2:1.0
-19,14,2:1.0
-18,14,2:1.0
-17,14,2:110.0
-16,14,2:110.0
-15,14,2:110.0
-14,14,2:110.0
-13,14,2:110.0
-12,14,2:110.0
-11,14,2:110.0
-10,14,2:3.0
-9,14,2:110.0
-8,14,2:110.0
-7,14,2:110.0
-6,14,2:110.0
-5,14,2:110.0
-4,14,2:110.0
-3,14,2:3.0
-2,14,2:110.0
-1,14,2:110.0
0,14,2:110.0
1,14,2:110.0
2,14,2:3.0
3,14,2:110.0
4,14,2:110.0
5,14,2:1.0
-20,15,2:1.0
-19,15,2:1.0
-18,15,2:1.0
-17,15,2:1.0
-16,15,2:1.0
-15,15,2:1.0
-14,15,2:110.0
-13,15,2:3.0
-12,15,2:110.0
-11,15,2:110.0
-10,15,2:110.0
-9,15,2:110.0
-8,15,2:3.0
-7,15,2:110.0
-6,15,2:110.0
-5,15,2:3.0
-4,15,2:110.0
-3,15,2:110.0
-2,15,2:110.0
-1,15,2:110.0
0,15,2:110.0
1,15,2:110.0
2,15,2:110.0
3,15,2:110.0
4,15,2:110.0
5,15,2:1.0
-18,16,2:1.0
-17,16,2:1.0
-16,16,2:1.0
-15,16,2:1.0
-14,16,2:110.0
-13,16,2:110.0
-12,16,2:110.0
-11,16,2:3.0
-10,16,2:110.0
-9,16,2:110.0
-8,16,2:110.0
-7,16,2:110.0
-6,16,2:110.0
-5,16,2:110.0
-4,16,2:110.0
-3,16,2:110.0
-2,16,2:3.0
-1,16,2:110.0
0,16,2:110.0
1,16,2:1.0
2,16,2:1.0
3,16,2:1.0
4,16,2:1.0
-16,17,2:1.0
-15,17,2:1.0
-14,17,2:1.0
-13,17,2:1.0
-12,17,2:1.0
-11,17,2:110.0
-10,17,2:110.0
-9,17,2:110.0
-8,17,2:110.0
-7,17,2:3.0
-6,17,2:110.0
-5,17,2:3.0
-4,17,2:110.0
-3,17,2:110.0
-2,17,2:110.0
-1,17,2:110.0
0,17,2:1.0
1,17,2:1.0
-14,18,2:1.0
-13,18,2:1.0
-12,18,2:1.0
-11,18,2:1.0
-10,18,2:1.0
-9,18,2:1.0
-8,18,2:110.0
-7,18,2:110.0
-6,18,2:110.0
-5,18,2:110.0
-4,18,2:110.0
-3,18,2:110.0
-2,18,2:110.0
-1,18,2:1.0
0,18,2:1.0
1,18,2:1.0
-11,19,2:1.0
-10,19,2:1.0
-9,19,2:1.0
-8,19,2:1.0
-7,19,2:1.0
-6,19,2:110.0
-5,19,2:110.0
-4,19,2:110.0
-3,19,2:3.0
-2,19,2:110.0
-1,19,2:1.0
0,19,2:1.0
1,19,2:1.0
2,19,2:1.0
3,19,2:1.0
-8,20,2:1.0
-7,20,2:1.0
-6,20,2:1.0
-5,20,2:1.0
-4,20,2:1.0
-3,20,2:1.0
-2,20,2:1.0
-1,20,2:1.0
0,20,2:1.0
2,-23,3:1.0
3,-23,3:1.0
4,-23,3:1.0
5,-23,3:1.0
6,-23,3:1.0
7,-23,3:1.0
8,-23,3:1.0
1,-22,3:1.0
8,-22,3:1.0
9,-22,3:1.0
10,-22,3:1.0
11,-22,3:1.0
12,-22,3:1.0
13,-22,3:1.0
14,-22,3:1.0
0,-21,3:1.0
14,-21,3:1.0
15,-21,3:1.0
16,-21,3:1.0
17,-21,3:1.0
-1,-20,3:1.0
17,-20,3:1.0
18,-20,3:1.0
-2,-19,3:1.0
7,-19,3:100.14
18,-19,3:1.0
19,-19,3:1.0
20,-19,3:1.0
21,-19,3:1.0
-2,-18,3:1.0
3,-18,3:99.14
10,-18,3:99.14
21,-18,3:1.0
22,-18,3:1.0
-7,-17,3:1.0
-6,-17,3:1.0
-5,-17,3:1.0
-4,-17,3:1.0
-3,-17,3:1.0
6,-17,3:99.14
14,-17,3:99.14
21,-17,3:1.0
-8,-16,3:1.0
-7,-16,3:1.0
-3,-16,3:1.0
4,-16,3:100.15
9,-16,3:100.14
12,-16,3:100.14
21,-16,3:1.0
22,-16,3:1.0
-11,-15,3:1.0
-10,-15,3:1.0
-9,-15,3:1.0
-8,-15,3:1.0
2,-15,3:99.14
17,-15,3:99.14
22,-15,3:1.0
-12,-14,3:1.0
4,-14,3:100.14
7,-14,3:99.14
10,-14,3:99.14
15,-14,3:99.14
22,-14,3:1.0
-13,-13,3:1.0
-6,-13,3:99.14
-4,-13,3:99.14
2,-13,3:100.14
13,-13,3:100.14
17,-13,3:99.14
22,-13,3:1.0
-14,-12,3:1.0
-7,-12,3:100.14
0,-12,3:99.14
11,-12,3:100.14
22,-12,3:1.0
-15,-11,3:1.0
-9,-11,3:99.14
2,-11,3:100.14
6,-11,3:99.14
9,-11,3:99.14
14,-11,3:99.14
18,-11,3:100.14
21,-11,3:1.0
22,-11,3:1.0
-15,-10,3:1.0
-7,-10,3:99.14
0,-10,3:100.14
12,-10,3:100.14
16,-10,3:99.14
22,-10,3:1.0
23,-10,3:1.0
-16,-9,3:1.0
-10,-9,3:100.14
-7,-9,3:100.14
8,-9,3:100.14
14,-9,3:100.15
23,-9,3:1.0
-16,-8,3:1.0
-11,-8,3:100.15
-2,-8,3:100.14
2,-8,3:100.14
4,-8,3:100.14
18,-8,3:99.14
23,-8,3:1.0
-17,-7,3:1.0
-16,-7,3:1.0
-9,-7,3:99.14
12,-7,3:100.15
17,-7,3:100.14
23,-7,3:1.0
-17,-6,3:1.0
-13,-6,3:99.14
-11,-6,3:100.14
1,-6,3:100.14
5,-6,3:100.15
7,-6,3:100.15
9,-6,3:100.15
14,-6,3:100.14
23,-6,3:1.0
-17,-5,3:1.0
-9,-5,3:99.14
6,-5,3:100.15
7,-5,3:100.15
8,-5,3:100.15
16,-5,3:99.14
22,-5,3:1.0
23,-5,3:1.0
-18,-4,3:1.0
-17,-4,3:1.0
-13,-4,3:100.14
5,-4,3:100.15
6,-4,3:100.15
7,-4,3:100.15
8,-4,3:100.15
9,-4,3:100.15
13,-4,3:99.14
15,-4,3:100.14
22,-4,3:1.0
-19,-3,3:1.0
-18,-3,3:1.0
-11,-3,3:100.14
1,-3,3:100.14
6,-3,3:100.15
7,-3,3:100.15
8,-3,3:100.15
22,-3,3:1.0
-19,-2,3:1.0
-12,-2,3:99.14
4,-2,3:100.15
6,-2,3:100.15
7,-2,3:100.15
9,-2,3:100.15
13,-2,3:100.14
16,-2,3:99.14
21,-2,3:1.0
22,-2,3:1.0
-19,-1,3:1.0
-13,-1,3:100.14
3,-1,3:100.14
5,-1,3:100.15
7,-1,3:100.15
21,-1,3:1.0
-20,0,3:1.0
-19,0,3:1.0
0,0,3:100.14
7,0,3:100.15
15,0,3:100.14
21,0,3:1.0
-20,1,3:1.0
-15,1,3:100.14
-14,1,3:99.14
-12,1,3:100.14
11,1,3:100.14
13,1,3:99.14
16,1,3:99.14
21,1,3:1.0
-20,2,3:1.0
0,2,3:100.14
2,2,3:100.14
5,2,3:100.14
8,2,3:99.14
14,2,3:100.14
21,2,3:1.0
-22,3,3:1.0
-21,3,3:1.0
-20,3,3:1.0
-3,3,3:100.15
11,3,3:99.14
21,3,3:1.0
-23,4,3:1.0
-22,4,3:1.0
-2,4,3:100.15
0,4,3:100.14
3,4,3:100.14
6,4,3:99.14
7,4,3:99.14
9,4,3:100.14
13,4,3:100.14
15,4,3:100.14
20,4,3:1.0
-23,5,3:1.0
2,5,3:99.14
7,5,3:100.14
11,5,3:100.14
19,5,3:1.0
-23,6,3:1.0
4,6,3:99.14
6,6,3:100.14
9,6,3:100.15
13,6,3:99.14
19,6,3:1.0
-23,7,3:1.0
-8,7,3:100.15
1,7,3:100.14
3,7,3:99.14
19,7,3:1.0
-23,8,3:1.0
6,8,3:100.14
9,8,3:99.14
11,8,3:99.14
16,8,3:1.0
17,8,3:1.0
18,8,3:1.0
-23,9,3:1.0
-4,9,3:100.15
6,9,3:99.14
11,9,3:99.14
15,9,3:1.0
-22,10,3:1.0
-6,10,3:99.14
8,10,3:100.14
15,10,3:1.0
-22,11,3:1.0
4,11,3:9.8
15,11,3:1.0
-22,12,3:1.0
-3,12,3:99.14
1,12,3:100.14
14,12,3:1.0
15,12,3:1.0
-22,13,3:1.0
-15,13,3:99.14
-12,13,3:99.14
-5,13,3:100.14
-1,13,3:99.14
14,13,3:1.0
-22,14,3:1.0
-10,14,3:100.14
-3,14,3:100.14
2,14,3:99.14
5,14,3:1.0
6,14,3:1.0
7,14,3:1.0
8,14,3:1.0
9,14,3:1.0
10,14,3:1.0
11,14,3:1.0
12,14,3:1.0
13,14,3:1.0
14,14,3:1.0
-22,15,3:1.0
-21,15,3:1.0
-13,15,3:100.14
-8,15,3:99.14
-5,15,3:99.14
5,15,3:1.0
-21,16,3:1.0
-20,16,3:1.0
-19,16,3:1.0
-11,16,3:99.14
-2,16,3:99.14
5,16,3:1.0
-19,17,3:1.0
-18,17,3:1.0
-17,17,3:1.0
-7,17,3:99.14
-5,17,3:100.14
2,17,3:1.0
3,17,3:1.0
4,17,3:1.0
-17,18,3:1.0
-16,18,3:1.0
-15,18,3:1.0
2,18,3:1.0
-15,19,3:1.0
-14,19,3:1.0
-13,19,3:1.0
-12,19,3:1.0
-3,19,3:99.14
2,19,3:1.0
3,19,3:1.0
-12,20,3:1.0
-11,20,3:1.0
-10,20,3:1.0
-9,20,3:1.0
1,20,3:1.0
2,20,3:1.0
-8,21,3:1.0
-7,21,3:1.0
-6,21,3:1.0
-5,21,3:1.0
-4,21,3:1.0
-3,21,3:1.0
-2,21,3:1.0
-1,21,3:1.0
0,21,3:1.0
2,-23,4:1.0
3,-23,4:1.0
4,-23,4:1.0
5,-23,4:1.0
6,-23,4:1.0
7,-23,4:1.0
8,-23,4:1.0
1,-22,4:1.0
9,-22,4:1.0
10,-22,4:1.0
11,-22,4:1.0
12,-22,4:1.0
13,-22,4:1.0
14,-22,4:1.0
0,-21,4:1.0
15,-21,4:1.0
16,-21,4:1.0
17,-21,4:1.0
-1,-20,4:1.0
18,-20,4:1.0
-2,-19,4:1.0
19,-19,4:1.0
20,-19,4:1.0
21,-19,4:1.0
-8,-18,4:1.0
-7,-18,4:1.0
-6,-18,4:1.0
-5,-18,4:1.0
-4,-18,4:1.0
-3,-18,4:1.0
-2,-18,4:1.0
22,-18,4:1.0
-9,-17,4:1.0
-8,-17,4:1.0
-3,-17,4:1.0
21,-17,4:1.0
-10,-16,4:1.0
-9,-16,4:1.0
-3,-16,4:1.0
4,-16,4:100.15
22,-16,4:1.0
-11,-15,4:1.0
-10,-15,4:1.0
22,-15,4:1.0
-12,-14,4:1.0
22,-14,4:1.0
-13,-13,4:1.0
22,-13,4:1.0
-14,-12,4:1.0
22,-12,4:1.0
-15,-11,4:1.0
22,-11,4:1.0
-15,-10,4:1.0
23,-10,4:1.0
-16,-9,4:1.0
23,-9,4:1.0
-16,-8,4:1.0
-11,-8,4:100.15
13,-8,4:100.15
23,-8,4:1.0
-17,-7,4:1.0
23,-7,4:1.0
-17,-6,4:1.0
23,-6,4:1.0
-17,-5,4:1.0
6,-5,4:100.15
7,-5,4:100.15
8,-5,4:100.15
23,-5,4:1.0
-18,-4,4:1.0
5,-4,4:100.15
6,-4,4:100.15
7,-4,4:100.15
8,-4,4:100.15
22,-4,4:1.0
-19,-3,4:1.0
6,-3,4:100.15
7,-3,4:100.15
8,-3,4:100.15
22,-3,4:1.0
-19,-2,4:1.0
6,-2,4:100.15
7,-2,4:100.15
8,-2,4:100.15
9,-2,4:100.15
10,-2,4:100.15
22,-2,4:1.0
-19,-1,4:1.0
7,-1,4:100.15
21,-1,4:1.0
-20,0,4:1.0
-19,0,4:1.0
21,0,4:1.0
-20,1,4:1.0
21,1,4:1.0
-20,2,4:1.0
21,2,4:1.0
-21,3,4:1.0
-20,3,4:1.0
-16,3,4:99.14
-15,3,4:99.14
-14,3,4:99.14
-13,3,4:99.14
-12,3,4:99.14
-11,3,4:99.14
-10,3,4:99.14
21,3,4:1.0
-23,4,4:1.0
-22,4,4:1.0
-17,4,4:99.14
-16,4,4:99.14
-10,4,4:99.14
-9,4,4:99.14
-3,4,4:100.15
21,4,4:1.0
-23,5,4:1.0
-17,5,4:99.14
-9,5,4:99.14
19,5,4:1.0
20,5,4:1.0
-23,6,4:1.0
-17,6,4:99.14
-9,6,4:99.14
-7,6,4:100.15
-5,6,4:100.15
9,6,4:100.15
19,6,4:1.0
20,6,4:1.0
-23,7,4:1.0
-17,7,4:99.14
-9,7,4:99.14
-5,7,4:100.15
-4,7,4:100.15
20,7,4:1.0
-23,8,4:1.0
-17,8,4:99.14
-9,8,4:99.14
-4,8,4:100.15
19,8,4:1.0
20,8,4:1.0
-23,9,4:1.0
-17,9,4:99.14
-9,9,4:99.14
16,9,4:1.0
17,9,4:1.0
18,9,4:1.0
-22,10,4:1.0
-17,10,4:99.14
-16,10,4:99.14
-10,10,4:99.14
-9,10,4:99.14
16,10,4:1.0
-22,11,4:1.0
-16,11,4:99.14
-15,11,4:99.14
-14,11,4:99.14
-13,11,4:99.14
-12,11,4:99.14
-11,11,4:99.14
-10,11,4:99.14
4,11,4:9.8
16,11,4:1.0
-22,12,4:1.0
-8,12,4:100.14
16,12,4:1.0
-22,13,4:1.0
-9,13,4:100.14
-7,13,4:100.14
15,13,4:1.0
16,13,4:1.0
-22,14,4:1.0
-8,14,4:100.14
15,14,4:1.0
-22,15,4:1.0
5,15,4:1.0
6,15,4:1.0
7,15,4:1.0
8,15,4:1.0
9,15,4:1.0
10,15,4:1.0
11,15,4:1.0
12,15,4:1.0
13,15,4:1.0
14,15,4:1.0
15,15,4:1.0
-22,16,4:1.0
6,16,4:1.0
7,16,4:1.0
-22,17,4:1.0
-21,17,4:1.0
-20,17,4:1.0
3,17,4:1.0
4,17,4:1.0
5,17,4:1.0
-20,18,4:1.0
-19,18,4:1.0
-18,18,4:1.0
3,18,4:1.0
-18,19,4:1.0
-17,19,4:1.0
-16,19,4:1.0
3,19,4:1.0
-16,20,4:1.0
-15,20,4:1.0
-14,20,4:1.0
-13,20,4:1.0
3,20,4:1.0
-13,21,4:1.0
-12,21,4:1.0
-11,21,4:1.0
-10,21,4:1.0
-9,21,4:1.0
-8,21,4:1.0
-7,21,4:1.0
1,21,4:1.0
2,21,4:1.0
-7,22,4:1.0
-6,22,4:1.0
-5,22,4:1.0
-4,22,4:1.0
-3,22,4:1.0
-2,22,4:1.0
-1,22,4:1.0
0,22,4:1.0
1,22,4:1.0
2,-22,5:1.0
3,-22,5:1.0
4,-22,5:1.0
5,-22,5:1.0
6,-22,5:1.0
7,-22,5:1.0
8,-22,5:1.0
1,-21,5:1.0
9,-21,5:1.0
10,-21,5:1.0
11,-21,5:1.0
12,-21,5:1.0
13,-21,5:1.0
14,-21,5:1.0
0,-20,5:1.0
15,-20,5:1.0
16,-20,5:1.0
17,-20,5:1.0
-1,-19,5:1.0
17,-19,5:1.0
18,-19,5:1.0
-8,-18,5:1.0
-7,-18,5:1.0
-6,-18,5:1.0
-5,-18,5:1.0
-4,-18,5:1.0
-1,-18,5:1.0
3,-18,5:100.14
4,-18,5:100.14
5,-18,5:100.14
18,-18,5:1.0
19,-18,5:1.0
20,-18,5:1.0
21,-18,5:1.0
-8,-17,5:1.0
-3,-17,5:1.0
-2,-17,5:1.0
2,-17,5:100.14
6,-17,5:100.14
20,-17,5:1.0
-10,-16,5:1.0
-9,-16,5:1.0
-8,-16,5:1.0
-3,-16,5:1.0
-2,-16,5:1.0
2,-16,5:100.14
4,-16,5:100.15
6,-16,5:100.14
20,-16,5:1.0
21,-16,5:1.0
-10,-15,5:1.0
-9,-15,5:1.0
-3,-15,5:1.0
2,-15,5:100.14
6,-15,5:100.14
21,-15,5:1.0
-11,-14,5:1.0
-10,-14,5:1.0
-3,-14,5:1.0
3,-14,5:100.14
4,-14,5:100.14
5,-14,5:100.14
21,-14,5:1.0
-12,-13,5:1.0
-3,-13,5:1.0
21,-13,5:1.0
-13,-12,5:1.0
21,-12,5:1.0
-14,-11,5:1.0
21,-11,5:1.0
-14,-10,5:1.0
-13,-10,5:100.15
-12,-10,5:100.15
-11,-10,5:100.15
-10,-10,5:100.15
21,-10,5:1.0
22,-10,5:1.0
-15,-9,5:1.0
-13,-9,5:100.15
-12,-9,5:100.15
-11,-9,5:100.15
-10,-9,5:100.15
-9,-9,5:100.15
22,-9,5:1.0
-15,-8,5:1.0
-13,-8,5:100.15
-12,-8,5:100.15
-11,-8,5:100.15
-10,-8,5:100.15
-9,-8,5:100.15
22,-8,5:1.0
-16,-7,5:1.0
-13,-7,5:100.15
-12,-7,5:100.15
-11,-7,5:100.15
-10,-7,5:100.15
-9,-7,5:100.15
22,-7,5:1.0
-16,-6,5:1.0
-12,-6,5:100.15
-11,-6,5:100.15
-10,-6,5:100.15
22,-6,5:1.0
-16,-5,5:1.0
7,-5,5:100.15
21,-5,5:1.0
22,-5,5:1.0
-17,-4,5:1.0
5,-4,5:100.15
6,-4,5:100.15
7,-4,5:100.15
8,-4,5:100.15
21,-4,5:1.0
-18,-3,5:1.0
6,-3,5:100.15
7,-3,5:100.15
8,-3,5:100.15
21,-3,5:1.0
-18,-2,5:1.0
7,-2,5:100.15
10,-2,5:100.15
20,-2,5:1.0
21,-2,5:1.0
-18,-1,5:1.0
20,-1,5:1.0
-18,0,5:1.0
20,0,5:1.0
-19,1,5:1.0
20,1,5:1.0
-19,2,5:1.0
20,2,5:1.0
-19,3,5:1.0
20,3,5:1.0
-21,4,5:1.0
-20,4,5:1.0
-15,4,5:99.14
-14,4,5:99.14
-13,4,5:99.14
-12,4,5:99.14
-11,4,5:99.14
8,4,5:100.15
9,4,5:100.15
10,4,5:100.15
18,4,5:1.0
19,4,5:1.0
20,4,5:1.0
-22,5,5:1.0
-16,5,5:99.14
-15,5,5:99.14
-11,5,5:99.14
-10,5,5:99.14
-5,5,5:100.15
-3,5,5:100.15
7,5,5:100.15
8,5,5:100.15
10,5,5:100.15
11,5,5:100.15
18,5,5:1.0
-22,6,5:1.0
-16,6,5:99.14
-13,6,5:99.14
-10,6,5:99.14
-6,6,5:100.15
-5,6,5:100.15
7,6,5:100.15
11,6,5:100.15
18,6,5:1.0
-22,7,5:1.0
-16,7,5:99.14
-14,7,5:99.14
-12,7,5:99.14
-10,7,5:99.14
7,7,5:100.15
8,7,5:100.15
10,7,5:100.15
11,7,5:100.15
18,7,5:1.0
19,7,5:1.0
-22,8,5:1.0
-16,8,5:99.14
-13,8,5:99.14
-10,8,5:99.14
8,8,5:100.15
9,8,5:100.15
10,8,5:100.15
15,8,5:1.0
16,8,5:1.0
17,8,5:1.0
18,8,5:1.0
-22,9,5:1.0
-16,9,5:99.14
-15,9,5:99.14
-11,9,5:99.14
-10,9,5:99.14
15,9,5:1.0
-21,10,5:1.0
-15,10,5:99.14
-14,10,5:99.14
-13,10,5:99.14
-12,10,5:99.14
-11,10,5:99.14
4,10,5:1.0
15,10,5:1.0
-21,11,5:1.0
3,11,5:1.0
4,11,5:9.0
5,11,5:1.0
15,11,5:1.0
-21,12,5:1.0
-8,12,5:100.14
4,12,5:1.0
14,12,5:1.0
15,12,5:1.0
-21,13,5:1.0
-9,13,5:100.14
-7,13,5:100.14
4,13,5:1.0
5,13,5:1.0
14,13,5:1.0
-21,14,5:1.0
-8,14,5:100.14
5,14,5:1.0
6,14,5:1.0
7,14,5:1.0
8,14,5:1.0
9,14,5:1.0
10,14,5:1.0
11,14,5:1.0
12,14,5:1.0
13,14,5:1.0
14,14,5:1.0
-21,15,5:1.0
5,15,5:1.0
-21,16,5:1.0
-20,16,5:1.0
-19,16,5:1.0
2,16,5:1.0
3,16,5:1.0
4,16,5:1.0
5,16,5:1.0
-19,17,5:1.0
-18,17,5:1.0
-17,17,5:1.0
2,17,5:1.0
-17,18,5:1.0
-16,18,5:1.0
-15,18,5:1.0
2,18,5:1.0
-15,19,5:1.0
-14,19,5:1.0
-13,19,5:1.0
-12,19,5:1.0
2,19,5:1.0
-12,20,5:1.0
-11,20,5:1.0
-10,20,5:1.0
-9,20,5:1.0
1,20,5:1.0
2,20,5:1.0
-8,21,5:1.0
-7,21,5:1.0
-6,21,5:1.0
-5,21,5:1.0
-4,21,5:1.0
-3,21,5:1.0
-2,21,5:1.0
-1,21,5:1.0
0,21,5:1.0
2,-21,6:1.0
3,-21,6:1.0
4,-21,6:1.0
5,-21,6:1.0
6,-21,6:1.0
7,-21,6:1.0
8,-21,6:1.0
1,-20,6:1.0
9,-20,6:1.0
10,-20,6:1.0
11,-20,6:1.0
12,-20,6:1.0
13,-20,6:1.0
14,-20,6:1.0
0,-19,6:1.0
11,-19,6:1.0
12,-19,6:1.0
13,-19,6:1.0
14,-19,6:1.0
15,-19,6:1.0
16,-19,6:1.0
0,-18,6:1.0
3,-18,6:100.14
4,-18,6:100.14
5,-18,6:100.14
16,-18,6:1.0
17,-18,6:1.0
-8,-17,6:1.0
-7,-17,6:1.0
-6,-17,6:1.0
-5,-17,6:1.0
-4,-17,6:1.0
-3,-17,6:1.0
-2,-17,6:1.0
-1,-17,6:1.0
2,-17,6:100.14
3,-17,6:100.14
4,-17,6:100.14
5,-17,6:100.14
6,-17,6:100.14
16,-17,6:1.0
17,-17,6:1.0
18,-17,6:1.0
19,-17,6:1.0
-8,-16,6:1.0
-7,-16,6:1.0
-6,-16,6:1.0
-5,-16,6:1.0
-4,-16,6:1.0
-3,-16,6:1.0
-2,-16,6:1.0
-1,-16,6:1.0
2,-16,6:100.14
3,-16,6:100.14
4,-16,6:100.14
5,-16,6:100.14
6,-16,6:100.14
19,-16,6:1.0
-8,-15,6:1.0
-7,-15,6:1.0
-4,-15,6:1.0
-3,-15,6:1.0
-2,-15,6:1.0
2,-15,6:100.14
3,-15,6:100.14
4,-15,6:100.14
5,-15,6:100.14
6,-15,6:100.14
19,-15,6:1.0
20,-15,6:1.0
-9,-14,6:1.0
-8,-14,6:1.0
-7,-14,6:1.0
-4,-14,6:1.0
-3,-14,6:1.0
-2,-14,6:1.0
3,-14,6:100.14
4,-14,6:100.14
5,-14,6:100.14
20,-14,6:1.0
-11,-13,6:1.0
-10,-13,6:1.0
-9,-13,6:1.0
-8,-13,6:1.0
-4,-13,6:1.0
-2,-13,6:1.0
20,-13,6:1.0
-12,-12,6:1.0
-3,-12,6:1.0
20,-12,6:1.0
-13,-11,6:1.0
-3,-11,6:1.0
8,-11,6:100.15
19,-11,6:1.0
20,-11,6:1.0
-13,-10,6:1.0
8,-10,6:100.15
19,-10,6:1.0
20,-10,6:1.0
-14,-9,6:1.0
8,-9,6:100.15
20,-9,6:1.0
21,-9,6:1.0
-14,-8,6:1.0
8,-8,6:100.15
21,-8,6:1.0
-15,-7,6:1.0
21,-7,6:1.0
-15,-6,6:1.0
20,-6,6:1.0
21,-6,6:1.0
-15,-5,6:1.0
7,-5,6:100.15
19,-5,6:1.0
20,-5,6:1.0
-16,-4,6:1.0
6,-4,6:100.15
7,-4,6:100.15
8,-4,6:100.15
19,-4,6:1.0
20,-4,6:1.0
-17,-3,6:1.0
-16,-3,6:1.0
7,-3,6:100.15
10,-3,6:100.14
19,-3,6:1.0
20,-3,6:1.0
-17,-2,6:1.0
-16,-2,6:1.0
5,-2,6:100.15
6,-2,6:100.15
7,-2,6:100.15
9,-2,6:100.14
10,-2,6:100.14
11,-2,6:100.14
19,-2,6:1.0
-17,-1,6:1.0
-16,-1,6:1.0
7,-1,6:100.15
10,-1,6:100.14
19,-1,6:1.0
-17,0,6:1.0
19,0,6:1.0
-18,1,6:1.0
-17,1,6:1.0
18,1,6:1.0
19,1,6:1.0
-18,2,6:1.0
-17,2,6:1.0
18,2,6:1.0
19,2,6:1.0
-18,3,6:1.0
17,3,6:1.0
18,3,6:1.0
19,3,6:1.0
-19,4,6:1.0
-18,4,6:1.0
17,4,6:1.0
-21,5,6:1.0
-20,5,6:1.0
-19,5,6:1.0
-18,5,6:1.0
-14,5,6:99.14
-13,5,6:99.14
-12,5,6:99.14
-6,5,6:1.0
-4,5,6:100.15
9,5,6:100.15
16,5,6:1.0
17,5,6:1.0
-21,6,6:1.0
-15,6,6:99.14
-14,6,6:99.14
-13,6,6:99.14
-12,6,6:99.14
-11,6,6:99.14
-5,6,6:1.0
-4,6,6:100.15
8,6,6:100.15
10,6,6:100.15
17,6,6:1.0
-21,7,6:1.0
-15,7,6:99.14
-14,7,6:99.14
-12,7,6:99.14
-11,7,6:99.14
-4,7,6:1.0
-3,7,6:1.0
9,7,6:100.15
14,7,6:1.0
15,7,6:1.0
16,7,6:1.0
17,7,6:1.0
-21,8,6:1.0
-20,8,6:1.0
-15,8,6:99.14
-14,8,6:99.14
-13,8,6:99.14
-12,8,6:99.14
-11,8,6:99.14
-4,8,6:1.0
-3,8,6:1.0
13,8,6:1.0
14,8,6:1.0
-21,9,6:1.0
-20,9,6:1.0
-14,9,6:99.14
-13,9,6:99.14
-12,9,6:99.14
-3,9,6:1.0
-2,9,6:1.0
-1,9,6:1.0
13,9,6:1.0
14,9,6:1.0
-20,10,6:1.0
-1,10,6:1.0
0,10,6:1.0
1,10,6:1.0
2,10,6:1.0
3,10,6:1.0
4,10,6:1.0
5,10,6:1.0
13,10,6:1.0
14,10,6:1.0
-20,11,6:1.0
2,11,6:1.0
3,11,6:1.0
4,11,6:1.0
5,11,6:1.0
6,11,6:1.0
13,11,6:1.0
14,11,6:1.0
-20,12,6:1.0
5,12,6:1.0
6,12,6:1.0
7,12,6:1.0
12,12,6:1.0
13,12,6:1.0
-20,13,6:1.0
-19,13,6:1.0
-8,13,6:100.14
6,13,6:1.0
7,13,6:1.0
8,13,6:1.0
9,13,6:1.0
10,13,6:1.0
11,13,6:1.0
12,13,6:1.0
13,13,6:1.0
-20,14,6:1.0
-19,14,6:1.0
-18,14,6:1.0
6,14,6:1.0
-20,15,6:1.0
-19,15,6:1.0
-18,15,6:1.0
-17,15,6:1.0
-16,15,6:1.0
5,15,6:1.0
-18,16,6:1.0
-17,16,6:1.0
-16,16,6:1.0
0,16,6:1.0
1,16,6:1.0
2,16,6:1.0
3,16,6:1.0
4,16,6:1.0
-16,17,6:1.0
-15,17,6:1.0
-14,17,6:1.0
0,17,6:1.0
1,17,6:1.0
-14,18,6:1.0
-13,18,6:1.0
-12,18,6:1.0
-11,18,6:1.0
-10,18,6:1.0
-9,18,6:1.0
-8,18,6:1.0
0,18,6:1.0
1,18,6:1.0
-11,19,6:1.0
-10,19,6:1.0
-9,19,6:1.0
-8,19,6:1.0
-7,19,6:1.0
0,19,6:1.0
1,19,6:1.0
-8,20,6:1.0
-7,20,6:1.0
-6,20,6:1.0
-5,20,6:1.0
-4,20,6:1.0
-3,20,6:1.0
-2,20,6:1.0
-1,20,6:1.0
0,20,6:1.0
2,-20,7:1.0
3,-20,7:1.0
4,-20,7:1.0
5,-20,7:1.0
6,-20,7:1.0
7,-20,7:1.0
8,-20,7:1.0
1,-19,7:1.0
2,-19,7:1.0
4,-19,7:1.0
5,-19,7:1.0
6,-19,7:1.0
7,-19,7:1.0
8,-19,7:1.0
9,-19,7:1.0
10,-19,7:1.0
1,-18,7:1.0
9,-18,7:1.0
10,-18,7:1.0
11,-18,7:1.0
12,-18,7:1.0
13,-18,7:1.0
14,-18,7:1.0
15,-18,7:1.0
0,-17,7:1.0
1,-17,7:1.0
15,-17,7:1.0
-3,-16,7:1.0
0,-16,7:1.0
15,-16,7:1.0
16,-16,7:1.0
17,-16,7:1.0
18,-16,7:1.0
-6,-15,7:1.0
-5,-15,7:1.0
-4,-15,7:1.0
-3,-15,7:1.0
-1,-15,7:1.0
0,-15,7:1.0
17,-15,7:1.0
18,-15,7:1.0
-6,-14,7:1.0
-5,-14,7:1.0
-4,-14,7:1.0
-3,-14,7:1.0
-1,-14,7:1.0
17,-14,7:1.0
18,-14,7:1.0
19,-14,7:1.0
-7,-13,7:1.0
-6,-13,7:1.0
-4,-13,7:1.0
-3,-13,7:1.0
-1,-13,7:1.0
7,-13,7:100.14
8,-13,7:100.14
9,-13,7:100.14
18,-13,7:1.0
19,-13,7:1.0
-11,-12,7:1.0
-10,-12,7:1.0
-9,-12,7:1.0
-8,-12,7:1.0
-7,-12,7:1.0
-4,-12,7:1.0
-3,-12,7:1.0
-2,-12,7:1.0
-1,-12,7:1.0
6,-12,7:100.14
7,-12,7:100.14
9,-12,7:100.14
10,-12,7:100.14
18,-12,7:1.0
19,-12,7:1.0
-12,-11,7:1.0
-11,-11,7:1.0
-4,-11,7:1.0
-3,-11,7:1.0
-2,-11,7:1.0
-1,-11,7:1.0
6,-11,7:100.14
10,-11,7:100.14
18,-11,7:1.0
-12,-10,7:1.0
-4,-10,7:1.0
-3,-10,7:1.0
-2,-10,7:1.0
-1,-10,7:1.0
6,-10,7:100.14
7,-10,7:100.14
9,-10,7:100.14
10,-10,7:100.14
18,-10,7:1.0
-13,-9,7:1.0
-12,-9,7:1.0
-4,-9,7:1.0
-3,-9,7:1.0
-2,-9,7:1.0
7,-9,7:100.14
8,-9,7:100.14
9,-9,7:100.14
18,-9,7:1.0
19,-9,7:1.0
-13,-8,7:1.0
-5,-8,7:1.0
-4,-8,7:1.0
-3,-8,7:1.0
-2,-8,7:1.0
8,-8,7:100.15
18,-8,7:1.0
19,-8,7:1.0
20,-8,7:1.0
-14,-7,7:1.0
-13,-7,7:1.0
-5,-7,7:1.0
-4,-7,7:1.0
-3,-7,7:1.0
7,-7,7:100.15
18,-7,7:1.0
19,-7,7:1.0
20,-7,7:1.0
-14,-6,7:1.0
-5,-6,7:1.0
-4,-6,7:1.0
-3,-6,7:1.0
7,-6,7:100.15
18,-6,7:1.0
19,-6,7:1.0
-14,-5,7:1.0
-5,-5,7:1.0
-4,-5,7:1.0
-3,-5,7:1.0
7,-5,7:100.15
18,-5,7:1.0
-15,-4,7:1.0
-14,-4,7:1.0
-5,-4,7:1.0
-4,-4,7:1.0
-3,-4,7:1.0
6,-4,7:100.15
7,-4,7:100.15
8,-4,7:100.15
18,-4,7:1.0
-15,-3,7:1.0
-14,-3,7:1.0
-5,-3,7:1.0
-4,-3,7:1.0
5,-3,7:100.14
7,-3,7:100.15
17,-3,7:1.0
18,-3,7:1.0
-15,-2,7:1.0
-14,-2,7:1.0
-6,-2,7:1.0
-5,-2,7:1.0
-4,-2,7:1.0
4,-2,7:100.14
5,-2,7:100.15
6,-2,7:100.14
8,-2,7:100.15
17,-2,7:1.0
18,-2,7:1.0
-15,-1,7:1.0
-6,-1,7:1.0
-5,-1,7:1.0
5,-1,7:100.14
7,-1,7:100.15
17,-1,7:1.0
18,-1,7:1.0
-16,0,7:1.0
-15,0,7:1.0
-6,0,7:1.0
17,0,7:1.0
18,0,7:1.0
-16,1,7:1.0
-6,1,7:1.0
17,1,7:1.0
-16,2,7:1.0
-6,2,7:1.0
16,2,7:1.0
17,2,7:1.0
-17,3,7:1.0
-16,3,7:1.0
-7,3,7:1.0
-6,3,7:1.0
-5,3,7:1.0
16,3,7:1.0
-17,4,7:1.0
-16,4,7:1.0
-7,4,7:1.0
-6,4,7:1.0
-5,4,7:1.0
15,4,7:1.0
16,4,7:1.0
-17,5,7:1.0
-7,5,7:1.0
-5,5,7:1.0
-4,5,7:1.0
-3,5,7:1.0
15,5,7:1.0
-20,6,7:1.0
-19,6,7:1.0
-18,6,7:1.0
-17,6,7:1.0
-13,6,7:99.14
-7,6,7:1.0
-6,6,7:1.0
-4,6,7:1.0
-3,6,7:1.0
-2,6,7:1.0
9,6,7:100.15
13,6,7:1.0
14,6,7:1.0
15,6,7:1.0
16,6,7:1.0
-20,7,7:1.0
-19,7,7:1.0
-18,7,7:1.0
-14,7,7:99.14
-13,7,7:99.14
-12,7,7:99.14
-6,7,7:1.0
-5,7,7:1.0
-2,7,7:1.0
12,7,7:1.0
13,7,7:1.0
-19,8,7:1.0
-13,8,7:99.14
-5,8,7:1.0
-2,8,7:1.0
-1,8,7:1.0
0,8,7:1.0
1,8,7:1.0
2,8,7:1.0
12,8,7:1.0
-19,9,7:1.0
-4,9,7:1.0
0,9,7:1.0
1,9,7:1.0
2,9,7:1.0
3,9,7:1.0
4,9,7:1.0
5,9,7:1.0
6,9,7:1.0
11,9,7:1.0
12,9,7:1.0
-19,10,7:1.0
-3,10,7:1.0
-2,10,7:1.0
6,10,7:1.0
7,10,7:1.0
11,10,7:1.0
12,10,7:1.0
-19,11,7:1.0
-18,11,7:1.0
-2,11,7:1.0
-1,11,7:1.0
0,11,7:1.0
1,11,7:1.0
7,11,7:1.0
8,11,7:1.0
9,11,7:1.0
10,11,7:1.0
11,11,7:1.0
12,11,7:1.0
-19,12,7:1.0
-18,12,7:1.0
0,12,7:1.0
1,12,7:1.0
2,12,7:1.0
3,12,7:1.0
4,12,7:1.0
8,12,7:1.0
9,12,7:1.0
10,12,7:1.0
11,12,7:1.0
-18,13,7:1.0
-17,13,7:1.0
-16,13,7:1.0
3,13,7:1.0
4,13,7:1.0
5,13,7:1.0
-17,14,7:1.0
-16,14,7:1.0
-15,14,7:1.0
4,14,7:1.0
5,14,7:1.0
-15,15,7:1.0
-1,15,7:1.0
0,15,7:1.0
1,15,7:1.0
2,15,7:1.0
3,15,7:1.0
4,15,7:1.0
-15,16,7:1.0
-14,16,7:1.0
-13,16,7:1.0
-12,16,7:1.0
-11,16,7:1.0
-1,16,7:1.0
-13,17,7:1.0
-12,17,7:1.0
-11,17,7:1.0
-10,17,7:1.0
-9,17,7:1.0
-8,17,7:1.0
-7,17,7:1.0
-2,17,7:1.0
-1,17,7:1.0
-7,18,7:1.0
-6,18,7:1.0
-2,18,7:1.0
-1,18,7:1.0
-6,19,7:1.0
-5,19,7:1.0
-4,19,7:1.0
-3,19,7:1.0
-2,19,7:1.0
-1,19,7:1.0
-5,20,7:1.0
-4,20,7:1.0
-3,20,7:1.0
-2,20,7:1.0
3,-19,8:1.0
2,-18,8:1.0
3,-18,8:1.0
4,-18,8:1.0
5,-18,8:1.0
6,-18,8:1.0
7,-18,8:1.0
8,-18,8:1.0
2,-17,8:1.0
8,-17,8:1.0
9,-17,8:1.0
10,-17,8:1.0
11,-17,8:1.0
12,-17,8:1.0
13,-17,8:1.0
14,-17,8:1.0
1,-16,8:1.0
2,-16,8:1.0
14,-16,8:1.0
1,-15,8:1.0
14,-15,8:1.0
15,-15,8:1.0
16,-15,8:1.0
0,-14,8:1.0
1,-14,8:1.0
16,-14,8:1.0
-5,-13,8:1.0
0,-13,8:1.0
16,-13,8:1.0
17,-13,8:1.0
-6,-12,8:1.0
-5,-12,8:1.0
-3,-12,8:1.0
0,-12,8:1.0
8,-12,8:100.14
17,-12,8:1.0
-10,-11,8:1.0
-9,-11,8:1.0
-8,-11,8:1.0
-7,-11,8:1.0
-6,-11,8:1.0
-5,-11,8:1.0
0,-11,8:1.0
7,-11,8:100.14
8,-11,8:100.15
9,-11,8:100.14
17,-11,8:1.0
-11,-10,8:1.0
-10,-10,8:1.0
-6,-10,8:1.0
-5,-10,8:1.0
-4,-10,8:1.0
-3,-10,8:1.0
0,-10,8:1.0
8,-10,8:100.14
17,-10,8:1.0
-11,-9,8:1.0
-6,-9,8:1.0
-5,-9,8:1.0
-1,-9,8:1.0
0,-9,8:1.0
17,-9,8:1.0
-12,-8,8:1.0
-11,-8,8:1.0
-6,-8,8:1.0
-5,-8,8:1.0
-1,-8,8:1.0
8,-8,8:100.15
17,-8,8:1.0
-12,-7,8:1.0
-6,-7,8:1.0
-2,-7,8:1.0
-1,-7,8:1.0
7,-7,8:100.15
8,-7,8:100.15
17,-7,8:1.0
-13,-6,8:1.0
-12,-6,8:1.0
-6,-6,8:1.0
-5,-6,8:1.0
-2,-6,8:1.0
17,-6,8:1.0
-13,-5,8:1.0
-6,-5,8:1.0
-2,-5,8:1.0
7,-5,8:100.15
17,-5,8:1.0
-13,-4,8:1.0
-6,-4,8:1.0
-2,-4,8:1.0
6,-4,8:100.15
7,-4,8:100.15
8,-4,8:100.15
16,-4,8:1.0
17,-4,8:1.0
-13,-3,8:1.0
-7,-3,8:1.0
-6,-3,8:1.0
-3,-3,8:1.0
-2,-3,8:1.0
7,-3,8:100.15
16,-3,8:1.0
-13,-2,8:1.0
-7,-2,8:1.0
-3,-2,8:1.0
5,-2,8:100.14
7,-2,8:100.15
16,-2,8:1.0
-14,-1,8:1.0
-13,-1,8:1.0
-7,-1,8:1.0
-4,-1,8:1.0
-3,-1,8:1.0
7,-1,8:99.14
16,-1,8:1.0
-14,0,8:1.0
-7,0,8:1.0
-5,0,8:1.0
-4,0,8:1.0
6,0,8:99.14
7,0,8:100.15
8,0,8:99.14
16,0,8:1.0
-15,1,8:1.0
-14,1,8:1.0
-7,1,8:1.0
-5,1,8:1.0
7,1,8:99.14
15,1,8:1.0
16,1,8:1.0
-15,2,8:1.0
-7,2,8:1.0
-5,2,8:1.0
-4,2,8:1.0
15,2,8:1.0
-15,3,8:1.0
-7,3,8:1.0
-4,3,8:1.0
14,3,8:1.0
15,3,8:1.0
-15,4,8:1.0
-7,4,8:1.0
-4,4,8:1.0
-3,4,8:1.0
-2,4,8:1.0
14,4,8:1.0
-16,5,8:1.0
-15,5,8:1.0
-7,5,8:1.0
-2,5,8:1.0
-1,5,8:1.0
12,5,8:1.0
13,5,8:1.0
14,5,8:1.0
-16,6,8:1.0
-7,6,8:1.0
-1,6,8:1.0
11,6,8:1.0
12,6,8:1.0
-17,7,8:1.0
-16,7,8:1.0
-13,7,8:99.14
-7,7,8:1.0
-1,7,8:1.0
0,7,8:1.0
1,7,8:1.0
2,7,8:1.0
3,7,8:1.0
11,7,8:1.0
-18,8,8:1.0
-17,8,8:1.0
-7,8,8:1.0
-6,8,8:1.0
3,8,8:1.0
4,8,8:1.0
5,8,8:1.0
6,8,8:1.0
7,8,8:1.0
10,8,8:1.0
11,8,8:1.0
-18,9,8:1.0
-6,9,8:1.0
-5,9,8:1.0
7,9,8:1.0
8,9,8:1.0
10,9,8:1.0
-18,10,8:1.0
-17,10,8:1.0
-6,10,8:1.0
-5,10,8:1.0
-4,10,8:1.0
8,10,8:1.0
9,10,8:1.0
10,10,8:1.0
-17,11,8:1.0
-5,11,8:1.0
-4,11,8:1.0
-3,11,8:1.0
-17,12,8:1.0
-16,12,8:1.0
-15,12,8:1.0
-3,12,8:1.0
-2,12,8:1.0
-1,12,8:1.0
-15,13,8:1.0
-14,13,8:1.0
-1,13,8:1.0
0,13,8:1.0
1,13,8:1.0
2,13,8:1.0
-14,14,8:1.0
-2,14,8:1.0
-1,14,8:1.0
0,14,8:1.0
1,14,8:1.0
2,14,8:1.0
3,14,8:1.0
-14,15,8:1.0
-13,15,8:1.0
-12,15,8:1.0
-11,15,8:1.0
-10,15,8:1.0
-9,15,8:1.0
-8,15,8:1.0
-2,15,8:1.0
-10,16,8:1.0
-9,16,8:1.0
-8,16,8:1.0
-7,16,8:1.0
-6,16,8:1.0
-3,16,8:1.0
-2,16,8:1.0
-6,17,8:1.0
-5,17,8:1.0
-3,17,8:1.0
-5,18,8:1.0
-4,18,8:1.0
-3,18,8:1.0
3,-17,9:1.0
4,-17,9:1.0
5,-17,9:1.0
6,-17,9:1.0
7,-17,9:1.0
3,-16,9:1.0
4,-16,9:1.0
6,-16,9:1.0
7,-16,9:1.0
8,-16,9:1.0
9,-16,9:1.0
10,-16,9:1.0
11,-16,9:1.0
12,-16,9:1.0
13,-16,9:1.0
2,-15,9:1.0
3,-15,9:1.0
12,-15,9:1.0
13,-15,9:1.0
2,-14,9:1.0
13,-14,9:1.0
14,-14,9:1.0
15,-14,9:1.0
1,-13,9:1.0
2,-13,9:1.0
14,-13,9:1.0
15,-13,9:1.0
1,-12,9:1.0
2,-12,9:1.0
15,-12,9:1.0
16,-12,9:1.0
1,-11,9:1.0
2,-11,9:1.0
8,-11,9:100.14
15,-11,9:1.0
16,-11,9:1.0
-9,-10,9:1.0
-8,-10,9:1.0
-7,-10,9:1.0
1,-10,9:1.0
16,-10,9:1.0
-10,-9,9:1.0
-8,-9,9:1.0
-7,-9,9:1.0
-6,-9,9:1.0
1,-9,9:1.0
16,-9,9:1.0
-10,-8,9:1.0
-8,-8,9:1.0
-7,-8,9:1.0
0,-8,9:1.0
1,-8,9:1.0
16,-8,9:1.0
-11,-7,9:1.0
-10,-7,9:1.0
-8,-7,9:1.0
-7,-7,9:1.0
-6,-7,9:1.0
0,-7,9:1.0
1,-7,9:1.0
15,-7,9:1.0
16,-7,9:1.0
-11,-6,9:1.0
-9,-6,9:1.0
-8,-6,9:1.0
-7,-6,9:1.0
-1,-6,9:1.0
0,-6,9:1.0
1,-6,9:1.0
15,-6,9:1.0
16,-6,9:1.0
-12,-5,9:1.0
-11,-5,9:1.0
-9,-5,9:1.0
-8,-5,9:1.0
-7,-5,9:1.0
-1,-5,9:1.0
0,-5,9:1.0
7,-5,9:100.15
15,-5,9:1.0
16,-5,9:1.0
-12,-4,9:1.0
-11,-4,9:1.0
-9,-4,9:1.0
-8,-4,9:1.0
-7,-4,9:1.0
-1,-4,9:1.0
6,-4,9:100.15
7,-4,9:100.15
8,-4,9:100.15
15,-4,9:1.0
16,-4,9:1.0
-12,-3,9:1.0
-11,-3,9:1.0
-9,-3,9:1.0
-8,-3,9:1.0
-7,-3,9:1.0
-1,-3,9:1.0
7,-3,9:100.15
15,-3,9:1.0
-12,-2,9:1.0
-8,-2,9:1.0
-2,-2,9:1.0
-1,-2,9:1.0
15,-2,9:1.0
-12,-1,9:1.0
-8,-1,9:1.0
-2,-1,9:1.0
-1,-1,9:1.0
15,-1,9:1.0
-13,0,9:1.0
-12,0,9:1.0
-8,0,9:1.0
-3,0,9:1.0
-2,0,9:1.0
7,0,9:99.14
14,0,9:1.0
15,0,9:1.0
-13,1,9:1.0
-12,1,9:1.0
-8,1,9:1.0
-4,1,9:1.0
-3,1,9:1.0
13,1,9:1.0
14,1,9:1.0
-14,2,9:1.0
-13,2,9:1.0
-12,2,9:1.0
-8,2,9:1.0
-3,2,9:1.0
13,2,9:1.0
14,2,9:1.0
-14,3,9:1.0
-13,3,9:1.0
-8,3,9:1.0
-3,3,9:1.0
-2,3,9:1.0
-1,3,9:1.0
12,3,9:1.0
13,3,9:1.0
-14,4,9:1.0
-8,4,9:1.0
-1,4,9:1.0
11,4,9:1.0
12,4,9:1.0
13,4,9:1.0
-14,5,9:1.0
-8,5,9:1.0
0,5,9:1.0
2,5,9:1.0
3,5,9:1.0
10,5,9:1.0
11,5,9:1.0
-15,6,9:1.0
-14,6,9:1.0
-8,6,9:1.0
0,6,9:1.0
1,6,9:1.0
2,6,9:1.0
3,6,9:1.0
4,6,9:1.0
5,6,9:1.0
9,6,9:1.0
10,6,9:1.0
-15,7,9:1.0
-14,7,9:1.0
-8,7,9:1.0
3,7,9:1.0
4,7,9:1.0
5,7,9:1.0
6,7,9:1.0
7,7,9:1.0
8,7,9:1.0
9,7,9:1.0
10,7,9:1.0
-16,8,9:1.0
-15,8,9:1.0
-8,8,9:1.0
8,8,9:1.0
9,8,9:1.0
-17,9,9:1.0
-16,9,9:1.0
-8,9,9:1.0
-7,9,9:1.0
9,9,9:1.0
-16,10,9:1.0
-7,10,9:1.0
-16,11,9:1.0
-15,11,9:1.0
-14,11,9:1.0
-7,11,9:1.0
-6,11,9:1.0
-14,12,9:1.0
-7,12,9:1.0
-6,12,9:1.0
-5,12,9:1.0
-4,12,9:1.0
-13,13,9:1.0
-11,13,9:1.0
-10,13,9:1.0
-9,13,9:1.0
-8,13,9:1.0
-5,13,9:1.0
-4,13,9:1.0
-3,13,9:1.0
-2,13,9:1.0
-13,14,9:1.0
-12,14,9:1.0
-11,14,9:1.0
-10,14,9:1.0
-9,14,9:1.0
-8,14,9:1.0
-7,14,9:1.0
-3,14,9:1.0
-10,15,9:1.0
-9,15,9:1.0
-8,15,9:1.0
-7,15,9:1.0
-6,15,9:1.0
-4,15,9:1.0
-3,15,9:1.0
-5,16,9:1.0
-4,16,9:1.0
-4,17,9:1.0
5,-16,10:1.0
4,-15,10:1.0
5,-15,10:1.0
6,-15,10:1.0
7,-15,10:1.0
8,-15,10:1.0
9,-15,10:1.0
10,-15,10:1.0
11,-15,10:1.0
3,-14,10:1.0
4,-14,10:1.0
8,-14,10:1.0
9,-14,10:1.0
10,-14,10:1.0
11,-14,10:1.0
12,-14,10:1.0
3,-13,10:1.0
10,-13,10:1.0
11,-13,10:1.0
12,-13,10:1.0
13,-13,10:1.0
3,-12,10:1.0
11,-12,10:1.0
12,-12,10:1.0
13,-12,10:1.0
14,-12,10:1.0
3,-11,10:1.0
4,-11,10:1.0
13,-11,10:1.0
14,-11,10:1.0
2,-10,10:1.0
3,-10,10:1.0
13,-10,10:1.0
14,-10,10:1.0
15,-10,10:1.0
-9,-9,10:1.0
1,-9,10:1.0
2,-9,10:1.0
14,-9,10:1.0
15,-9,10:1.0
-9,-8,10:1.0
2,-8,10:1.0
14,-8,10:1.0
15,-8,10:1.0
-10,-7,10:1.0
-9,-7,10:1.0
2,-7,10:1.0
14,-7,10:1.0
-10,-6,10:1.0
2,-6,10:1.0
14,-6,10:1.0
-10,-5,10:1.0
1,-5,10:1.0
2,-5,10:1.0
7,-5,10:100.15
13,-5,10:1.0
14,-5,10:1.0
-10,-4,10:1.0
0,-4,10:1.0
1,-4,10:1.0
5,-4,10:100.15
6,-4,10:100.15
7,-4,10:100.15
8,-4,10:100.15
9,-4,10:100.15
12,-4,10:1.0
13,-4,10:1.0
14,-4,10:1.0
-10,-3,10:1.0
-9,-3,10:1.0
0,-3,10:1.0
1,-3,10:1.0
7,-3,10:100.15
12,-3,10:1.0
13,-3,10:1.0
14,-3,10:1.0
-11,-2,10:1.0
-10,-2,10:1.0
-9,-2,10:1.0
0,-2,10:1.0
1,-2,10:1.0
12,-2,10:1.0
13,-2,10:1.0
14,-2,10:1.0
-12,-1,10:1.0
-11,-1,10:1.0
-9,-1,10:1.0
0,-1,10:1.0
12,-1,10:1.0
13,-1,10:1.0
14,-1,10:1.0
-11,0,10:1.0
-9,0,10:1.0
-1,0,10:1.0
0,0,10:1.0
12,0,10:1.0
13,0,10:1.0
-11,1,10:1.0
-9,1,10:1.0
-2,1,10:1.0
-1,1,10:1.0
12,1,10:1.0
-11,2,10:1.0
-9,2,10:1.0
-2,2,10:1.0
-1,2,10:1.0
0,2,10:1.0
11,2,10:1.0
12,2,10:1.0
-12,3,10:1.0
-11,3,10:1.0
-9,3,10:1.0
0,3,10:1.0
10,3,10:1.0
11,3,10:1.0
-13,4,10:1.0
-12,4,10:1.0
-9,4,10:1.0
0,4,10:1.0
1,4,10:1.0
2,4,10:1.0
3,4,10:1.0
4,4,10:1.0
9,4,10:1.0
10,4,10:1.0
-13,5,10:1.0
-12,5,10:1.0
-9,5,10:1.0
1,5,10:1.0
4,5,10:1.0
5,5,10:1.0
6,5,10:1.0
8,5,10:1.0
9,5,10:1.0
-13,6,10:1.0
-12,6,10:1.0
-9,6,10:1.0
6,6,10:1.0
7,6,10:1.0
8,6,10:1.0
-13,7,10:1.0
-9,7,10:1.0
-14,8,10:1.0
-13,8,10:1.0
-9,8,10:1.0
-15,9,10:1.0
-14,9,10:1.0
-9,9,10:1.0
-15,10,10:1.0
-14,10,10:1.0
-13,10,10:1.0
-9,10,10:1.0
-8,10,10:1.0
-13,11,10:1.0
-9,11,10:1.0
-8,11,10:1.0
-13,12,10:1.0
-12,12,10:1.0
-11,12,10:1.0
-10,12,10:1.0
-9,12,10:1.0
-8,12,10:1.0
-12,13,10:1.0
-7,13,10:1.0
-6,13,10:1.0
-7,14,10:1.0
-6,14,10:1.0
-5,14,10:1.0
-4,14,10:1.0
-5,15,10:1.0
5,-14,11:1.0
6,-14,11:1.0
7,-14,11:1.0
4,-13,11:1.0
5,-13,11:1.0
6,-13,11:1.0
7,-13,11:1.0
8,-13,11:1.0
9,-13,11:1.0
4,-12,11:1.0
5,-12,11:1.0
9,-12,11:1.0
10,-12,11:1.0
5,-11,11:1.0
10,-11,11:1.0
11,-11,11:1.0
12,-11,11:1.0
4,-10,11:1.0
5,-10,11:1.0
11,-10,11:1.0
12,-10,11:1.0
3,-9,11:1.0
4,-9,11:1.0
11,-9,11:1.0
12,-9,11:1.0
13,-9,11:1.0
3,-8,11:1.0
4,-8,11:1.0
12,-8,11:1.0
13,-8,11:1.0
3,-7,11:1.0
13,-7,11:1.0
3,-6,11:1.0
7,-6,11:100.15
11,-6,11:1.0
12,-6,11:1.0
13,-6,11:1.0
3,-5,11:1.0
10,-5,11:1.0
11,-5,11:1.0
12,-5,11:1.0
2,-4,11:1.0
3,-4,11:1.0
4,-4,11:100.15
6,-4,11:100.15
7,-4,11:100.15
8,-4,11:100.15
10,-4,11:100.15
11,-4,11:1.0
2,-3,11:1.0
3,-3,11:1.0
7,-3,11:100.15
11,-3,11:1.0
2,-2,11:1.0
10,-2,11:1.0
11,-2,11:1.0
-10,-1,11:1.0
1,-1,11:1.0
2,-1,11:1.0
10,-1,11:1.0
11,-1,11:1.0
-10,0,11:1.0
1,0,11:1.0
2,0,11:1.0
10,0,11:1.0
11,0,11:1.0
-10,1,11:1.0
0,1,11:1.0
1,1,11:1.0
2,1,11:1.0
10,1,11:1.0
11,1,11:1.0
-10,2,11:1.0
1,2,11:1.0
2,2,11:1.0
9,2,11:1.0
10,2,11:1.0
-10,3,11:1.0
1,3,11:1.0
2,3,11:1.0
3,3,11:1.0
4,3,11:1.0
5,3,11:1.0
6,3,11:1.0
8,3,11:1.0
9,3,11:1.0
-11,4,11:1.0
-10,4,11:1.0
5,4,11:1.0
6,4,11:1.0
7,4,11:1.0
8,4,11:1.0
-11,5,11:1.0
-10,5,11:1.0
7,5,11:1.0
-11,6,11:1.0
-9,6,11:1.0
-12,7,11:1.0
-11,7,11:1.0
-9,7,11:1.0
-12,8,11:1.0
-11,8,11:1.0
-9,8,11:1.0
-13,9,11:1.0
-12,9,11:1.0
-11,9,11:1.0
-9,9,11:1.0
-12,10,11:1.0
-11,10,11:1.0
-9,10,11:1.0
-12,11,11:1.0
-11,11,11:1.0
-10,11,11:1.0
6,-12,12:1.0
7,-12,12:1.0
8,-12,12:1.0
6,-11,12:1.0
8,-11,12:1.0
9,-11,12:1.0
6,-10,12:1.0
9,-10,12:1.0
10,-10,12:1.0
5,-9,12:1.0
6,-9,12:1.0
10,-9,12:1.0
5,-8,12:1.0
10,-8,12:1.0
11,-8,12:1.0
4,-7,12:1.0
5,-7,12:1.0
7,-7,12:100.15
10,-7,12:1.0
11,-7,12:1.0
12,-7,12:1.0
4,-6,12:1.0
9,-6,12:1.0
10,-6,12:1.0
4,-5,12:1.0
7,-5,12:100.14
9,-5,12:1.0
4,-4,12:1.0
6,-4,12:100.14
7,-4,12:91.2
8,-4,12:100.14
9,-4,12:1.0
10,-4,12:1.0
4,-3,12:1.0
7,-3,12:100.14
9,-3,12:1.0
10,-3,12:1.0
3,-2,12:1.0
4,-2,12:1.0
7,-2,12:100.15
9,-2,12:1.0
3,-1,12:1.0
4,-1,12:1.0
9,-1,12:1.0
3,0,12:1.0
4,0,12:1.0
9,0,12:1.0
3,1,12:1.0
4,1,12:1.0
7,1,12:1.0
8,1,12:1.0
9,1,12:1.0
3,2,12:1.0
4,2,12:1.0
5,2,12:1.0
6,2,12:1.0
7,2,12:1.0
8,2,12:1.0
7,3,12:1.0
-10,6,12:1.0
-10,7,12:1.0
-10,8,12:1.0
-10,9,12:1.0
-10,10,12:1.0
7,-11,13:1.0
7,-10,13:1.0
8,-10,13:1.0
6,-9,13:1.0
7,-9,13:1.0
8,-9,13:1.0
9,-9,13:1.0
6,-8,13:1.0
7,-8,13:100.15
8,-8,13:1.0
9,-8,13:1.0
5,-7,13:1.0
8,-7,13:1.0
9,-7,13:1.0
5,-6,13:1.0
8,-6,13:1.0
5,-5,13:1.0
8,-5,13:1.0
5,-4,13:1.0
8,-4,13:1.0
5,-3,13:1.0
8,-3,13:1.0
5,-2,13:1.0
7,-2,13:1.0
8,-2,13:1.0
5,-1,13:1.0
7,-1,13:1.0
8,-1,13:1.0
5,0,13:1.0
6,0,13:1.0
7,0,13:1.0
8,0,13:1.0
5,1,13:1.0
6,1,13:1.0
7,-8,14:1.0
5,-7,14:1.0
6,-7,14:1.0
7,-7,14:1.0
6,-6,14:1.0
7,-6,14:1.0
6,-5,14:1.0
7,-5,14:1.0
6,-4,14:1.0
7,-4,14:1.0
6,-3,14:1.0
7,-3,14:1.0
6,-2,14:1.0
6,-1,14:1.0
7,-4,13:78.0
7,-6,12:40.0
9,-4,11:40.0
7,-1,9:39.0
5,-2,9:40.0
8,-7,9:39.0
-12,7,8:39.0
9,6,8:39.0
7,-6,8:40.0
-13,9,7:40.0
-14,6,7:39.0
-12,5,7:39.0
10,-2,7:40.0
7,-2,7:91.5
8,-10,7:91.4
9,-11,7:78.0
8,-11,7:78.0
7,-11,7:78.0
8,-12,7:78.0
3,-15,7:39.0
5,-17,7:39.0
-11,9,6:39.0
-10,8,6:40.0
-13,7,6:91.5
11,6,6:39.0
9,6,6:91.5
-3,5,6:39.0
-10,5,6:40.0
-12,4,6:40.0
8,-3,6:40.0
-11,-7,6:40.0
-9,-8,6:40.0
-8,13,5:91.5
-12,11,5:39.0
-16,11,5:39.0
-16,10,5:39.0
-4,8,5:39.0
-17,8,5:39.0
9,7,5:78.0
-13,7,5:85.0
10,6,5:78.0
9,6,5:85.0
8,6,5:78.0
-7,6,5:39.0
9,5,5:78.0
-3,4,5:39.0
-10,4,5:39.0
-12,3,5:39.0
-16,3,5:40.0
7,-1,5:39.0
6,-2,5:40.0
8,-5,5:40.0
13,-8,5:40.0
-3,19,4:39.0
-7,17,4:39.0
-13,15,4:40.0
-1,13,4:39.0
-8,13,4:85.0
-12,13,4:39.0
-15,13,4:39.0
1,12,4:39.0
-6,10,4:40.0
-13,7,4:85.0
13,6,4:39.0
15,4,4:40.0
0,4,4:39.0
-2,4,4:39.0
11,3,4:39.0
-3,3,4:40.0
14,2,4:40.0
13,1,4:40.0
-12,1,4:40.0
-14,1,4:40.0
-15,1,4:40.0
7,0,4:39.0
5,-1,4:39.0
16,-2,4:40.0
13,-2,4:40.0
4,-2,4:39.0
-12,-2,4:40.0
-11,-3,4:39.0
15,-4,4:40.0
-13,-4,4:40.0
16,-5,4:40.0
-9,-5,4:39.0
14,-6,4:40.0
9,-6,4:39.0
12,-7,4:40.0
-9,-7,4:40.0
18,-8,4:39.0
4,-8,4:39.0
-2,-8,4:39.0
14,-9,4:40.0
8,-9,4:40.0
-7,-9,4:39.0
9,-11,4:39.0
6,-11,4:40.0
-9,-11,4:40.0
11,-12,4:39.0
0,-12,4:40.0
-4,-13,4:39.0
15,-14,4:40.0
10,-14,4:39.0
7,-14,4:40.0
12,-16,4:40.0
9,-16,4:39.0
14,-17,4:39.0
6,-17,4:39.0
10,-18,4:39.0
-1,19,3:39.0
-10,19,3:39.0
0,18,3:39.0
-1,18,3:39.0
-5,18,3:39.0
-8,18,3:39.0
1,17,3:39.0
-3,17,3:39.0
-3,16,3:40.0
-4,16,3:39.0
-8,16,3:39.0
-13,16,3:40.0
3,15,3:39.0
-1,15,3:39.0
-2,15,3:40.0
-3,15,3:40.0
-4,15,3:40.0
-7,15,3:40.0
-10,15,3:39.0
1,14,3:39.0
0,14,3:40.0
-2,14,3:40.0
-4,14,3:39.0
-5,14,3:40.0
-7,14,3:40.0
-15,14,3:40.0
-16,14,3:40.0
3,13,3:39.0
1,13,3:39.0
0,13,3:40.0
-2,13,3:39.0
-6,13,3:40.0
-7,13,3:40.0
-8,13,3:85.0
-10,13,3:39.0
-11,13,3:39.0
-14,13,3:39.0
2,12,3:39.0
0,12,3:40.0
-1,12,3:40.0
-2,12,3:40.0
-6,12,3:40.0
-9,12,3:39.0
-10,12,3:39.0
-14,12,3:40.0
-17,12,3:40.0
8,11,3:39.0
1,11,3:40.0
-1,11,3:40.0
-2,11,3:39.0
-4,11,3:39.0
-6,11,3:40.0
-16,11,3:40.0
-18,11,3:40.0
-8,10,3:40.0
-19,10,3:40.0
9,9,3:39.0
2,9,3:39.0
-5,9,3:39.0
-17,9,3:40.0
-18,9,3:39.0
-19,9,3:39.0
13,8,3:39.0
5,8,3:39.0
4,8,3:39.0
-6,8,3:39.0
-19,8,3:39.0
-20,8,3:40.0
12,7,3:39.0
2,7,3:39.0
0,7,3:39.0
-13,7,3:85.0
-17,7,3:40.0
-18,7,3:40.0
5,6,3:39.0
2,6,3:40.0
-1,6,3:39.0
-3,6,3:39.0
-16,6,3:39.0
-18,6,3:39.0
12,5,3:39.0
4,5,3:40.0
1,5,3:39.0
0,5,3:39.0
-1,5,3:39.0
-16,5,3:39.0
14,4,3:40.0
4,4,3:39.0
1,4,3:40.0
-1,4,3:39.0
20,3,3:39.0
12,3,3:40.0
6,3,3:39.0
5,3,3:40.0
2,3,3:40.0
0,3,3:40.0
-10,3,3:40.0
-15,3,3:39.0
-16,3,3:40.0
-17,3,3:40.0
12,2,3:40.0
10,2,3:39.0
9,2,3:39.0
6,2,3:40.0
1,2,3:40.0
-2,2,3:39.0
-11,2,3:40.0
-13,2,3:39.0
-16,2,3:40.0
-17,2,3:40.0
14,1,3:40.0
9,1,3:39.0
8,1,3:40.0
5,1,3:39.0
3,1,3:40.0
1,1,3:40.0
0,1,3:40.0
-13,1,3:40.0
-16,1,3:39.0
12,0,3:40.0
11,0,3:39.0
9,0,3:39.0
3,0,3:40.0
-12,0,3:40.0
14,-1,3:39.0
13,-1,3:40.0
12,-1,3:39.0
11,-1,3:39.0
4,-1,3:39.0
2,-1,3:39.0
-15,-1,3:39.0
-17,-1,3:39.0
17,-2,3:40.0
15,-2,3:40.0
14,-2,3:40.0
12,-2,3:39.0
17,-3,3:40.0
16,-3,3:40.0
15,-3,3:40.0
14,-3,3:40.0
13,-3,3:40.0
12,-3,3:39.0
4,-3,3:39.0
-10,-3,3:39.0
-13,-3,3:39.0
21,-4,3:39.0
16,-4,3:40.0
14,-4,3:39.0
3,-4,3:39.0
2,-4,3:39.0
0,-4,3:40.0
-9,-4,3:40.0
-11,-4,3:39.0
17,-5,3:39.0
15,-5,3:40.0
11,-5,3:39.0
1,-5,3:39.0
0,-5,3:40.0
-1,-5,3:39.0
-10,-5,3:40.0
-12,-5,3:40.0
-13,-5,3:40.0
-14,-5,3:40.0
15,-6,3:40.0
10,-6,3:40.0
3,-6,3:39.0
2,-6,3:39.0
0,-6,3:40.0
-1,-6,3:39.0
-3,-6,3:39.0
16,-7,3:39.0
15,-7,3:40.0
14,-7,3:40.0
8,-7,3:40.0
3,-7,3:39.0
0,-7,3:40.0
-1,-7,3:40.0
-2,-7,3:40.0
-8,-7,3:39.0
19,-8,3:39.0
17,-8,3:39.0
16,-8,3:39.0
12,-8,3:40.0
11,-8,3:39.0
6,-8,3:39.0
3,-8,3:39.0
1,-8,3:39.0
0,-8,3:40.0
-1,-8,3:40.0
-7,-8,3:39.0
16,-9,3:39.0
11,-9,3:39.0
6,-9,3:39.0
1,-9,3:40.0
-9,-9,3:40.0
-12,-9,3:40.0
-13,-9,3:40.0
15,-10,3:39.0
11,-10,3:39.0
6,-10,3:40.0
5,-10,3:40.0
3,-10,3:40.0
1,-10,3:40.0
-11,-10,3:40.0
-12,-10,3:39.0
17,-11,3:39.0
13,-11,3:39.0
0,-11,3:40.0
-8,-11,3:39.0
-10,-11,3:40.0
16,-12,3:40.0
15,-12,3:39.0
12,-12,3:39.0
8,-12,3:40.0
7,-12,3:40.0
4,-12,3:39.0
1,-12,3:40.0
-6,-12,3:39.0
-9,-12,3:40.0
-10,-12,3:40.0
7,-13,3:40.0
6,-13,3:40.0
5,-13,3:40.0
-5,-13,3:40.0
-8,-13,3:40.0
14,-14,3:40.0
9,-14,3:40.0
6,-14,3:40.0
1,-14,3:40.0
0,-14,3:39.0
-4,-14,3:40.0
-5,-14,3:40.0
-6,-14,3:39.0
-7,-14,3:40.0
14,-15,3:40.0
13,-15,3:39.0
9,-15,3:40.0
7,-15,3:40.0
6,-15,3:40.0
1,-15,3:40.0
-5,-15,3:40.0
13,-16,3:39.0
7,-16,3:40.0
13,-17,3:39.0
12,-17,3:39.0
11,-17,3:39.0
10,-17,3:40.0
2,-17,3:40.0
9,-18,3:40.0
