[META]
version=2.0
spawnOnBlockType=12,1,3
spawnSunlight=True
spawnDarkness=True
spawnWater=True
spawnLava=False
underFill=True
randomRotation=True
spawnAboveGround=True
dig=true
tree=False
branch=False
needsFoundation=True
rarity=50
collisionPercentage=1
spawnElevationMin=30
spawnElevationMax=50
spawnInBiome=Ocean,Ocean2,FrozenOcean
[DATA]
-2,-3,0:12.0
-1,-3,0:12.0
0,-3,0:12.0
1,-3,0:12.0
2,-3,0:12.0
3,-3,0:12.0
4,-3,0:12.0
-2,-2,0:12.0
-1,-2,0:12.0
0,-2,0:12.0
1,-2,0:12.0
2,-2,0:12.0
3,-2,0:12.0
4,-2,0:12.0
-2,-1,0:12.0
-1,-1,0:12.0
0,-1,0:12.0
1,-1,0:12.0
2,-1,0:12.0
3,-1,0:12.0
4,-1,0:12.0
-2,0,0:12.0
-1,0,0:12.0
0,0,0:12.0
1,0,0:12.0
2,0,0:12.0
3,0,0:12.0
4,0,0:12.0
-2,1,0:12.0
-1,1,0:12.0
0,1,0:12.0
1,1,0:12.0
2,1,0:12.0
3,1,0:12.0
4,1,0:12.0
-2,-3,1:9.0
-1,-3,1:19.0
0,-3,1:9.0
1,-3,1:19.0
2,-3,1:9.0
3,-3,1:9.0
4,-3,1:9.0
-2,-2,1:19.0
-1,-2,1:19.0
0,-2,1:19.0
1,-2,1:121.0
2,-2,1:19.0
3,-2,1:19.0
4,-2,1:9.0
-2,-1,1:9.0
-1,-1,1:19.0
0,-1,1:121.0
1,-1,1:121.0
2,-1,1:121.0
3,-1,1:121.0
4,-1,1:19.0
-2,0,1:9.0
-1,0,1:19.0
0,0,1:121.0
1,0,1:121.0
2,0,1:121.0
3,0,1:19.0
4,0,1:9.0
-2,1,1:9.0
-1,1,1:9.0
0,1,1:19.0
1,1,1:19.0
2,1,1:19.0
3,1,1:9.0
4,1,1:9.0
-2,-3,2:9.8
-1,-3,2:9.0
0,-3,2:9.0
1,-3,2:9.0
2,-3,2:9.0
3,-3,2:9.0
4,-3,2:9.0
-2,-2,2:9.0
-1,-2,2:19.0
0,-2,2:19.0
1,-2,2:19.0
2,-2,2:19.0
3,-2,2:9.0
4,-2,2:9.0
-2,-1,2:9.0
-1,-1,2:19.0
0,-1,2:121.0
1,-1,2:121.0
2,-1,2:9.0
3,-1,2:19.0
4,-1,2:9.0
-2,0,2:9.0
-1,0,2:9.0
0,0,2:19.0
1,0,2:19.0
2,0,2:19.0
3,0,2:9.0
4,0,2:9.0
-2,1,2:9.0
-1,1,2:9.0
0,1,2:9.0
1,1,2:9.0
2,1,2:9.0
3,1,2:9.0
4,1,2:9.0
-2,-3,3:9.0
-1,-3,3:9.0
0,-3,3:9.0
1,-3,3:9.0
2,-3,3:9.0
3,-3,3:9.0
4,-3,3:9.0
-2,-2,3:9.0
-1,-2,3:9.0
0,-2,3:9.0
1,-2,3:19.0
2,-2,3:9.0
3,-2,3:9.0
4,-2,3:9.0
-2,-1,3:9.0
-1,-1,3:9.0
0,-1,3:19.0
1,-1,3:91.0
2,-1,3:19.0
3,-1,3:9.0
4,-1,3:9.0
-2,0,3:9.0
-1,0,3:9.0
0,0,3:9.0
1,0,3:19.0
2,0,3:9.0
3,0,3:9.0
4,0,3:9.0
-2,1,3:9.8
-1,1,3:9.0
0,1,3:9.0
1,1,3:9.0
2,1,3:9.0
3,1,3:9.0
4,1,3:9.0
-2,-3,4:9.0
-1,-3,4:9.0
0,-3,4:9.0
1,-3,4:9.0
2,-3,4:9.0
3,-3,4:9.0
4,-3,4:9.0
-2,-2,4:9.0
-1,-2,4:9.0
0,-2,4:9.0
1,-2,4:9.0
2,-2,4:9.0
3,-2,4:9.0
4,-2,4:9.0
-2,-1,4:9.0
-1,-1,4:9.0
0,-1,4:9.0
1,-1,4:18.14
2,-1,4:9.0
3,-1,4:9.0
4,-1,4:9.0
-2,0,4:9.0
-1,0,4:9.0
0,0,4:9.0
1,0,4:9.0
2,0,4:9.0
3,0,4:9.0
4,0,4:9.0
-2,1,4:9.8
-1,1,4:9.0
0,1,4:9.0
1,1,4:9.0
2,1,4:9.0
3,1,4:9.0
4,1,4:9.0
-2,-3,5:9.0
-1,-3,5:9.0
0,-3,5:9.0
1,-3,5:9.0
2,-3,5:9.0
3,-3,5:9.0
4,-3,5:9.0
-2,-2,5:9.0
-1,-2,5:9.0
0,-2,5:9.0
1,-2,5:18.14
2,-2,5:9.0
3,-2,5:9.0
4,-2,5:9.0
-2,-1,5:9.0
-1,-1,5:9.0
0,-1,5:18.14
2,-1,5:18.14
3,-1,5:9.0
4,-1,5:9.0
-2,0,5:9.0
-1,0,5:9.0
0,0,5:9.0
1,0,5:18.14
2,0,5:9.0
3,0,5:9.0
4,0,5:9.0
-2,1,5:9.8
-1,1,5:9.0
0,1,5:9.0
1,1,5:9.0
2,1,5:9.0
3,1,5:9.0
4,1,5:9.0
-2,-3,6:9.0
-1,-3,6:9.0
0,-3,6:9.0
1,-3,6:18.14
2,-3,6:9.0
3,-3,6:9.0
4,-3,6:9.0
-2,-2,6:9.0
-1,-2,6:9.0
0,-2,6:9.0
1,-2,6:9.0
2,-2,6:9.0
3,-2,6:9.0
4,-2,6:9.0
-2,-1,6:9.0
-1,-1,6:18.14
0,-1,6:9.0
1,-1,6:9.0
2,-1,6:9.0
3,-1,6:18.14
4,-1,6:9.0
-2,0,6:9.0
-1,0,6:9.0
0,0,6:9.0
1,0,6:9.0
2,0,6:9.0
3,0,6:9.0
4,0,6:9.0
-2,1,6:9.8
-1,1,6:9.0
0,1,6:9.0
1,1,6:18.14
2,1,6:9.0
3,1,6:9.0
4,1,6:9.0
1,-1,5:81.0
