[META]
version=2.0
spawnOnBlockType=12,1,3
spawnSunlight=True
spawnDarkness=True
spawnWater=True
spawnLava=False
underFill=True
randomRotation=True
spawnAboveGround=True
dig=true
tree=False
branch=False
needsFoundation=True
rarity=200
collisionPercentage=1
spawnElevationMin=30
spawnElevationMax=50
spawnInBiome=Ocean,Ocean2,FrozenOcean
[DATA]
-7,-7,0:12.0
-6,-7,0:12.0
-5,-7,0:12.0
-4,-7,0:12.0
-3,-7,0:12.0
-2,-7,0:12.0
-1,-7,0:12.0
0,-7,0:12.0
1,-7,0:12.0
2,-7,0:12.0
3,-7,0:12.0
4,-7,0:12.0
5,-7,0:12.0
6,-7,0:12.0
-7,-6,0:12.0
-6,-6,0:12.0
-5,-6,0:12.0
-4,-6,0:12.0
-3,-6,0:12.0
-2,-6,0:12.0
-1,-6,0:12.0
0,-6,0:12.0
1,-6,0:12.0
2,-6,0:12.0
3,-6,0:12.0
4,-6,0:12.0
5,-6,0:12.0
6,-6,0:12.0
-7,-5,0:12.0
-6,-5,0:12.0
-5,-5,0:12.0
-4,-5,0:12.0
-3,-5,0:12.0
-2,-5,0:12.0
-1,-5,0:12.0
0,-5,0:12.0
1,-5,0:12.0
2,-5,0:12.0
3,-5,0:12.0
4,-5,0:12.0
5,-5,0:12.0
6,-5,0:12.0
-7,-4,0:12.0
-6,-4,0:12.0
-5,-4,0:12.0
-4,-4,0:12.0
-3,-4,0:12.0
-2,-4,0:12.0
-1,-4,0:12.0
0,-4,0:12.0
1,-4,0:12.0
2,-4,0:12.0
3,-4,0:12.0
4,-4,0:12.0
5,-4,0:12.0
6,-4,0:12.0
-7,-3,0:12.0
-6,-3,0:12.0
-5,-3,0:12.0
-4,-3,0:12.0
-3,-3,0:12.0
-2,-3,0:12.0
-1,-3,0:12.0
0,-3,0:12.0
1,-3,0:12.0
2,-3,0:12.0
3,-3,0:12.0
4,-3,0:12.0
5,-3,0:12.0
6,-3,0:12.0
-7,-2,0:12.0
-6,-2,0:12.0
-5,-2,0:12.0
-4,-2,0:12.0
-3,-2,0:12.0
-2,-2,0:12.0
-1,-2,0:12.0
0,-2,0:12.0
1,-2,0:12.0
2,-2,0:12.0
3,-2,0:12.0
4,-2,0:12.0
5,-2,0:12.0
6,-2,0:12.0
-7,-1,0:12.0
-6,-1,0:12.0
-5,-1,0:12.0
-4,-1,0:12.0
-3,-1,0:12.0
-2,-1,0:12.0
-1,-1,0:12.0
0,-1,0:12.0
1,-1,0:12.0
2,-1,0:12.0
3,-1,0:12.0
4,-1,0:12.0
5,-1,0:12.0
6,-1,0:12.0
-7,0,0:12.0
-6,0,0:12.0
-5,0,0:12.0
-4,0,0:12.0
-3,0,0:12.0
-2,0,0:12.0
-1,0,0:12.0
0,0,0:12.0
1,0,0:12.0
2,0,0:12.0
3,0,0:12.0
4,0,0:12.0
5,0,0:12.0
6,0,0:12.0
-7,1,0:12.0
-6,1,0:12.0
-5,1,0:12.0
-4,1,0:12.0
-3,1,0:12.0
-2,1,0:12.0
-1,1,0:12.0
0,1,0:12.0
1,1,0:12.0
2,1,0:12.0
3,1,0:12.0
4,1,0:12.0
5,1,0:12.0
6,1,0:12.0
-7,2,0:12.0
-6,2,0:12.0
-5,2,0:12.0
-4,2,0:12.0
-3,2,0:12.0
-2,2,0:12.0
-1,2,0:12.0
0,2,0:12.0
1,2,0:12.0
2,2,0:12.0
3,2,0:12.0
4,2,0:12.0
5,2,0:12.0
6,2,0:12.0
-7,3,0:12.0
-6,3,0:12.0
-5,3,0:12.0
-4,3,0:12.0
-3,3,0:12.0
-2,3,0:12.0
-1,3,0:12.0
0,3,0:12.0
1,3,0:12.0
2,3,0:12.0
3,3,0:12.0
4,3,0:12.0
5,3,0:12.0
6,3,0:12.0
-7,4,0:12.0
-6,4,0:12.0
-5,4,0:12.0
-4,4,0:12.0
-3,4,0:12.0
-2,4,0:12.0
-1,4,0:12.0
0,4,0:12.0
1,4,0:12.0
2,4,0:12.0
3,4,0:12.0
4,4,0:12.0
5,4,0:12.0
6,4,0:12.0
-7,5,0:12.0
-6,5,0:12.0
-5,5,0:12.0
-4,5,0:12.0
-3,5,0:12.0
-2,5,0:12.0
-1,5,0:12.0
0,5,0:12.0
1,5,0:12.0
2,5,0:12.0
3,5,0:12.0
4,5,0:12.0
5,5,0:12.0
6,5,0:12.0
-7,6,0:12.0
-6,6,0:12.0
-5,6,0:12.0
-4,6,0:12.0
-3,6,0:12.0
-2,6,0:12.0
-1,6,0:12.0
0,6,0:12.0
1,6,0:12.0
2,6,0:12.0
3,6,0:12.0
4,6,0:12.0
5,6,0:12.0
6,6,0:12.0
-7,7,0:12.0
-6,7,0:12.0
-5,7,0:12.0
-4,7,0:12.0
-3,7,0:12.0
-2,7,0:12.0
-1,7,0:12.0
0,7,0:12.0
1,7,0:12.0
2,7,0:12.0
3,7,0:12.0
4,7,0:12.0
5,7,0:12.0
6,7,0:12.0
-7,-7,1:9.0
-6,-7,1:9.0
-5,-7,1:9.0
-4,-7,1:9.0
-3,-7,1:9.0
-2,-7,1:9.0
-1,-7,1:9.0
0,-7,1:48.0
1,-7,1:48.0
2,-7,1:9.0
3,-7,1:9.0
4,-7,1:9.0
5,-7,1:9.0
6,-7,1:9.0
-7,-6,1:9.0
-6,-6,1:9.0
-5,-6,1:9.0
-4,-6,1:9.0
-3,-6,1:9.0
-2,-6,1:48.0
-1,-6,1:48.0
0,-6,1:48.0
1,-6,1:9.0
2,-6,1:9.0
3,-6,1:9.0
4,-6,1:9.0
5,-6,1:9.0
6,-6,1:9.0
-7,-5,1:9.0
-6,-5,1:9.0
-5,-5,1:9.0
-4,-5,1:48.0
-3,-5,1:9.0
-2,-5,1:48.0
-1,-5,1:121.0
0,-5,1:48.0
1,-5,1:9.0
2,-5,1:48.0
3,-5,1:48.0
4,-5,1:9.0
5,-5,1:9.0
6,-5,1:9.0
-7,-4,1:9.0
-6,-4,1:9.0
-5,-4,1:48.0
-4,-4,1:9.0
-3,-4,1:121.0
-2,-4,1:121.0
-1,-4,1:121.0
0,-4,1:9.0
1,-4,1:121.0
2,-4,1:9.0
3,-4,1:48.0
4,-4,1:48.0
5,-4,1:9.0
6,-4,1:9.0
-7,-3,1:9.0
-6,-3,1:9.0
-5,-3,1:9.0
-4,-3,1:121.0
-3,-3,1:9.0
-2,-3,1:9.0
-1,-3,1:9.0
0,-3,1:121.0
1,-3,1:9.0
2,-3,1:9.0
3,-3,1:48.0
4,-3,1:9.0
5,-3,1:9.0
6,-3,1:9.0
-7,-2,1:9.0
-6,-2,1:48.0
-5,-2,1:9.0
-4,-2,1:9.0
-3,-2,1:9.0
-2,-2,1:9.0
-1,-2,1:121.0
0,-2,1:9.0
1,-2,1:9.0
2,-2,1:9.0
3,-2,1:48.0
4,-2,1:9.0
5,-2,1:48.0
6,-2,1:48.0
-7,-1,1:9.0
-6,-1,1:9.0
-5,-1,1:9.0
-4,-1,1:9.0
-3,-1,1:121.0
-2,-1,1:9.0
-1,-1,1:121.0
0,-1,1:9.0
1,-1,1:9.0
2,-1,1:9.0
3,-1,1:121.0
4,-1,1:9.0
5,-1,1:9.0
6,-1,1:9.0
-7,0,1:48.0
-6,0,1:48.0
-5,0,1:121.0
-4,0,1:121.0
-3,0,1:9.0
-2,0,1:121.0
-1,0,1:9.0
0,0,1:121.0
1,0,1:121.0
2,0,1:121.0
3,0,1:121.0
4,0,1:9.0
5,0,1:9.0
6,0,1:48.0
-7,1,1:9.0
-6,1,1:48.0
-5,1,1:121.0
-4,1,1:9.0
-3,1,1:9.0
-2,1,1:121.0
-1,1,1:121.0
0,1,1:121.0
1,1,1:121.0
2,1,1:9.0
3,1,1:121.0
4,1,1:9.0
5,1,1:9.0
6,1,1:48.0
-7,2,1:48.0
-6,2,1:48.0
-5,2,1:9.0
-4,2,1:9.0
-3,2,1:9.0
-2,2,1:9.0
-1,2,1:9.0
0,2,1:9.0
1,2,1:121.0
2,2,1:9.0
3,2,1:121.0
4,2,1:9.0
5,2,1:9.0
6,2,1:9.0
-7,3,1:9.0
-6,3,1:9.0
-5,3,1:9.0
-4,3,1:9.0
-3,3,1:48.0
-2,3,1:9.0
-1,3,1:9.0
0,3,1:121.0
1,3,1:9.0
2,3,1:48.0
3,3,1:9.0
4,3,1:9.0
5,3,1:48.0
6,3,1:9.0
-7,4,1:9.0
-6,4,1:9.0
-5,4,1:48.0
-4,4,1:9.0
-3,4,1:9.0
-2,4,1:9.0
-1,4,1:48.0
0,4,1:121.0
1,4,1:9.0
2,4,1:9.0
3,4,1:9.0
4,4,1:9.0
5,4,1:9.0
6,4,1:9.0
-7,5,1:9.0
-6,5,1:9.0
-5,5,1:48.0
-4,5,1:9.0
-3,5,1:48.0
-2,5,1:9.0
-1,5,1:9.0
0,5,1:121.0
1,5,1:9.0
2,5,1:48.0
3,5,1:9.0
4,5,1:9.0
5,5,1:9.0
6,5,1:9.0
-7,6,1:9.0
-6,6,1:48.0
-5,6,1:9.0
-4,6,1:9.0
-3,6,1:48.0
-2,6,1:48.0
-1,6,1:9.0
0,6,1:9.0
1,6,1:121.0
2,6,1:9.0
3,6,1:48.0
4,6,1:9.0
5,6,1:9.0
6,6,1:9.0
-7,7,1:9.0
-6,7,1:9.0
-5,7,1:9.0
-4,7,1:9.0
-3,7,1:9.0
-2,7,1:9.0
-1,7,1:48.0
0,7,1:121.0
1,7,1:9.0
2,7,1:9.0
3,7,1:9.0
4,7,1:9.0
5,7,1:9.0
6,7,1:9.0
-7,-7,2:9.0
-6,-7,2:9.0
-5,-7,2:9.0
-4,-7,2:9.0
-3,-7,2:9.0
-2,-7,2:9.0
-1,-7,2:9.0
0,-7,2:48.0
1,-7,2:48.0
2,-7,2:9.0
3,-7,2:9.0
4,-7,2:9.0
5,-7,2:9.0
6,-7,2:9.8
-7,-6,2:9.0
-6,-6,2:9.0
-5,-6,2:9.0
-4,-6,2:9.0
-3,-6,2:9.0
-2,-6,2:48.0
-1,-6,2:9.0
0,-6,2:9.0
1,-6,2:9.0
2,-6,2:9.0
3,-6,2:9.0
4,-6,2:9.0
5,-6,2:9.0
6,-6,2:9.0
-7,-5,2:9.0
-6,-5,2:9.0
-5,-5,2:9.0
-4,-5,2:9.0
-3,-5,2:9.0
-2,-5,2:9.0
-1,-5,2:9.0
0,-5,2:9.0
1,-5,2:9.0
2,-5,2:9.0
3,-5,2:9.0
4,-5,2:9.0
5,-5,2:9.0
6,-5,2:9.0
-7,-4,2:9.0
-6,-4,2:9.0
-5,-4,2:9.0
-4,-4,2:9.0
-3,-4,2:9.0
-2,-4,2:9.0
-1,-4,2:9.0
0,-4,2:9.0
1,-4,2:9.0
2,-4,2:9.0
3,-4,2:9.0
4,-4,2:9.0
5,-4,2:9.0
6,-4,2:9.0
-7,-3,2:9.0
-6,-3,2:9.0
-5,-3,2:9.0
-4,-3,2:9.0
-3,-3,2:9.0
-2,-3,2:9.0
-1,-3,2:9.0
0,-3,2:121.0
1,-3,2:9.0
2,-3,2:9.0
3,-3,2:9.0
4,-3,2:9.0
5,-3,2:9.0
6,-3,2:9.0
-7,-2,2:9.0
-6,-2,2:9.0
-5,-2,2:9.0
-4,-2,2:9.0
-3,-2,2:9.0
-2,-2,2:9.0
-1,-2,2:9.0
0,-2,2:9.0
1,-2,2:9.0
2,-2,2:9.0
3,-2,2:9.0
4,-2,2:9.0
5,-2,2:48.0
6,-2,2:9.0
-7,-1,2:9.0
-6,-1,2:9.0
-5,-1,2:9.0
-4,-1,2:9.0
-3,-1,2:9.0
-2,-1,2:9.0
-1,-1,2:9.0
0,-1,2:9.0
1,-1,2:9.0
2,-1,2:9.0
3,-1,2:9.0
4,-1,2:9.0
5,-1,2:9.0
6,-1,2:9.0
-7,0,2:9.0
-6,0,2:9.0
-5,0,2:9.0
-4,0,2:9.0
-3,0,2:9.0
-2,0,2:121.0
-1,0,2:9.0
0,0,2:9.0
1,0,2:9.0
2,0,2:9.0
3,0,2:9.0
4,0,2:9.0
5,0,2:9.0
6,0,2:9.0
-7,1,2:9.0
-6,1,2:9.0
-5,1,2:9.0
-4,1,2:9.0
-3,1,2:9.0
-2,1,2:9.0
-1,1,2:9.0
0,1,2:121.0
1,1,2:9.0
2,1,2:9.0
3,1,2:9.0
4,1,2:9.0
5,1,2:9.0
6,1,2:9.0
-7,2,2:9.0
-6,2,2:48.0
-5,2,2:9.0
-4,2,2:9.0
-3,2,2:9.0
-2,2,2:9.0
-1,2,2:9.0
0,2,2:9.0
1,2,2:9.0
2,2,2:9.0
3,2,2:9.0
4,2,2:9.0
5,2,2:9.0
6,2,2:9.0
-7,3,2:9.0
-6,3,2:9.0
-5,3,2:9.0
-4,3,2:9.0
-3,3,2:9.0
-2,3,2:9.0
-1,3,2:9.0
0,3,2:9.0
1,3,2:9.0
2,3,2:9.0
3,3,2:9.0
4,3,2:9.0
5,3,2:9.0
6,3,2:9.0
-7,4,2:9.0
-6,4,2:9.0
-5,4,2:9.0
-4,4,2:9.0
-3,4,2:9.0
-2,4,2:9.0
-1,4,2:48.0
0,4,2:9.0
1,4,2:9.0
2,4,2:9.0
3,4,2:9.0
4,4,2:9.0
5,4,2:9.0
6,4,2:9.0
-7,5,2:9.0
-6,5,2:9.0
-5,5,2:9.0
-4,5,2:9.0
-3,5,2:48.0
-2,5,2:9.0
-1,5,2:9.0
0,5,2:9.0
1,5,2:9.0
2,5,2:9.0
3,5,2:9.0
4,5,2:9.0
5,5,2:9.0
6,5,2:9.0
-7,6,2:9.0
-6,6,2:9.0
-5,6,2:9.0
-4,6,2:9.0
-3,6,2:9.0
-2,6,2:9.0
-1,6,2:9.0
0,6,2:9.0
1,6,2:9.0
2,6,2:9.0
3,6,2:9.0
4,6,2:9.0
5,6,2:9.0
6,6,2:9.0
-7,7,2:9.0
-6,7,2:9.0
-5,7,2:9.0
-4,7,2:9.0
-3,7,2:9.0
-2,7,2:9.0
-1,7,2:9.0
0,7,2:9.0
1,7,2:9.0
2,7,2:9.0
3,7,2:9.0
4,7,2:9.0
5,7,2:9.0
6,7,2:9.0
-7,-7,3:9.0
-6,-7,3:9.0
-5,-7,3:9.0
-4,-7,3:9.0
-3,-7,3:9.0
-2,-7,3:9.0
-1,-7,3:9.0
0,-7,3:48.0
1,-7,3:9.0
2,-7,3:9.0
3,-7,3:9.0
4,-7,3:9.0
5,-7,3:9.0
6,-7,3:9.8
-7,-6,3:9.0
-6,-6,3:9.0
-5,-6,3:9.0
-4,-6,3:9.0
-3,-6,3:9.0
-2,-6,3:9.0
-1,-6,3:9.0
0,-6,3:9.0
1,-6,3:9.0
2,-6,3:9.0
3,-6,3:9.0
4,-6,3:9.0
5,-6,3:9.0
6,-6,3:9.0
-7,-5,3:9.0
-6,-5,3:9.0
-5,-5,3:9.0
-4,-5,3:9.0
-3,-5,3:9.0
-2,-5,3:9.0
-1,-5,3:9.0
0,-5,3:9.0
1,-5,3:9.0
2,-5,3:9.0
3,-5,3:9.0
4,-5,3:9.0
5,-5,3:9.0
6,-5,3:9.0
-7,-4,3:9.0
-6,-4,3:9.0
-5,-4,3:9.0
-4,-4,3:9.0
-3,-4,3:9.0
-2,-4,3:9.0
-1,-4,3:9.0
0,-4,3:9.0
1,-4,3:9.0
2,-4,3:9.0
3,-4,3:9.0
4,-4,3:9.0
5,-4,3:9.0
6,-4,3:9.0
-7,-3,3:9.0
-6,-3,3:9.0
-5,-3,3:9.0
-4,-3,3:9.0
-3,-3,3:9.0
-2,-3,3:9.0
-1,-3,3:9.0
0,-3,3:9.0
1,-3,3:9.0
2,-3,3:9.0
3,-3,3:9.0
4,-3,3:9.0
5,-3,3:9.0
6,-3,3:9.0
-7,-2,3:9.0
-6,-2,3:9.0
-5,-2,3:9.0
-4,-2,3:9.0
-3,-2,3:9.0
-2,-2,3:9.0
-1,-2,3:9.0
0,-2,3:9.0
1,-2,3:9.0
2,-2,3:9.0
3,-2,3:9.0
4,-2,3:9.0
5,-2,3:9.0
6,-2,3:9.0
-7,-1,3:9.0
-6,-1,3:9.0
-5,-1,3:9.0
-4,-1,3:9.0
-3,-1,3:9.0
-2,-1,3:9.0
-1,-1,3:9.0
0,-1,3:9.0
1,-1,3:9.0
2,-1,3:9.0
3,-1,3:9.0
4,-1,3:9.0
5,-1,3:9.0
6,-1,3:9.0
-7,0,3:9.0
-6,0,3:9.0
-5,0,3:9.0
-4,0,3:9.0
-3,0,3:9.0
-2,0,3:9.0
-1,0,3:9.0
0,0,3:9.0
1,0,3:9.0
2,0,3:9.0
3,0,3:9.0
4,0,3:9.0
5,0,3:9.0
6,0,3:9.0
-7,1,3:9.0
-6,1,3:9.0
-5,1,3:9.0
-4,1,3:9.0
-3,1,3:9.0
-2,1,3:9.0
-1,1,3:9.0
0,1,3:9.0
1,1,3:9.0
2,1,3:9.0
3,1,3:9.0
4,1,3:9.0
5,1,3:9.0
6,1,3:9.0
-7,2,3:9.0
-6,2,3:9.0
-5,2,3:9.0
-4,2,3:9.0
-3,2,3:9.0
-2,2,3:9.0
-1,2,3:9.0
0,2,3:9.0
1,2,3:9.0
2,2,3:9.0
3,2,3:9.0
4,2,3:9.0
5,2,3:9.0
6,2,3:9.0
-7,3,3:9.0
-6,3,3:9.0
-5,3,3:9.0
-4,3,3:9.0
-3,3,3:9.0
-2,3,3:9.0
-1,3,3:9.0
0,3,3:9.0
1,3,3:9.0
2,3,3:9.0
3,3,3:9.0
4,3,3:9.0
5,3,3:9.0
6,3,3:9.0
-7,4,3:9.0
-6,4,3:9.0
-5,4,3:9.0
-4,4,3:9.0
-3,4,3:9.0
-2,4,3:9.0
-1,4,3:9.0
0,4,3:9.0
1,4,3:9.0
2,4,3:9.0
3,4,3:9.0
4,4,3:9.0
5,4,3:9.0
6,4,3:9.0
-7,5,3:9.0
-6,5,3:9.0
-5,5,3:9.0
-4,5,3:9.0
-3,5,3:9.0
-2,5,3:9.0
-1,5,3:9.0
0,5,3:9.0
1,5,3:9.0
2,5,3:9.0
3,5,3:9.0
4,5,3:9.0
5,5,3:9.0
6,5,3:9.0
-7,6,3:9.0
-6,6,3:9.0
-5,6,3:9.0
-4,6,3:9.0
-3,6,3:9.0
-2,6,3:9.0
-1,6,3:9.0
0,6,3:9.0
1,6,3:9.0
2,6,3:9.0
3,6,3:9.0
4,6,3:9.0
5,6,3:9.0
6,6,3:9.0
-7,7,3:9.0
-6,7,3:9.0
-5,7,3:9.0
-4,7,3:9.0
-3,7,3:9.0
-2,7,3:9.0
-1,7,3:9.0
0,7,3:9.0
1,7,3:9.0
2,7,3:9.0
3,7,3:9.0
4,7,3:9.0
5,7,3:9.0
6,7,3:9.0
