[META]
version=2.0
spawnOnBlockType=12,1,3
spawnSunlight=True
spawnDarkness=True
spawnWater=True
spawnLava=False
underFill=True
randomRotation=True
spawnAboveGround=True
dig=true
tree=False
branch=False
needsFoundation=True
rarity=200
collisionPercentage=1
spawnElevationMin=30
spawnElevationMax=50
spawnInBiome=Ocean,Ocean2,FrozenOcean
[DATA]
-5,-5,0:12.0
-4,-5,0:5.1
-3,-5,0:12.0
-2,-5,0:5.1
-1,-5,0:12.0
0,-5,0:12.0
1,-5,0:12.0
2,-5,0:12.0
3,-5,0:12.0
4,-5,0:12.0
-5,-4,0:5.1
-4,-4,0:12.0
-3,-4,0:12.0
-2,-4,0:12.0
-1,-4,0:12.0
0,-4,0:5.1
1,-4,0:12.0
2,-4,0:12.0
3,-4,0:12.0
4,-4,0:12.0
-5,-3,0:12.0
-4,-3,0:12.0
-3,-3,0:12.0
-2,-3,0:12.0
-1,-3,0:12.0
0,-3,0:12.0
1,-3,0:12.0
2,-3,0:5.1
3,-3,0:12.0
4,-3,0:12.0
-5,-2,0:5.1
-4,-2,0:12.0
-3,-2,0:12.0
-2,-2,0:12.0
-1,-2,0:12.0
0,-2,0:12.0
1,-2,0:12.0
2,-2,0:12.0
3,-2,0:12.0
4,-2,0:5.1
-5,-1,0:12.0
-4,-1,0:5.1
-3,-1,0:12.0
-2,-1,0:12.0
-1,-1,0:12.0
0,-1,0:12.0
1,-1,0:12.0
2,-1,0:12.0
3,-1,0:12.0
4,-1,0:12.0
-5,0,0:12.0
-4,0,0:12.0
-3,0,0:12.0
-2,0,0:12.0
-1,0,0:12.0
0,0,0:12.0
1,0,0:12.0
2,0,0:12.0
3,0,0:12.0
4,0,0:5.1
-5,1,0:5.1
-4,1,0:12.0
-3,1,0:12.0
-2,1,0:12.0
-1,1,0:12.0
0,1,0:12.0
1,1,0:12.0
2,1,0:5.1
3,1,0:12.0
4,1,0:12.0
-5,2,0:12.0
-4,2,0:5.1
-3,2,0:5.1
-2,2,0:12.0
-1,2,0:12.0
0,2,0:12.0
1,2,0:5.1
2,2,0:12.0
3,2,0:12.0
4,2,0:12.0
-5,3,0:12.0
-4,3,0:5.1
-3,3,0:12.0
-2,3,0:12.0
-1,3,0:12.0
0,3,0:12.0
1,3,0:12.0
2,3,0:12.0
3,3,0:12.0
4,3,0:12.0
-5,4,0:12.0
-4,4,0:12.0
-3,4,0:12.0
-2,4,0:5.1
-1,4,0:12.0
0,4,0:5.1
1,4,0:12.0
2,4,0:12.0
3,4,0:12.0
4,4,0:12.0
-5,-5,1:9.0
-4,-5,1:9.0
-3,-5,1:9.0
-2,-5,1:9.0
-1,-5,1:9.0
0,-5,1:9.0
1,-5,1:9.0
2,-5,1:9.0
3,-5,1:9.0
4,-5,1:9.0
-5,-4,1:9.0
-4,-4,1:9.0
-3,-4,1:5.1
-2,-4,1:9.0
-1,-4,1:9.0
0,-4,1:9.0
1,-4,1:9.0
2,-4,1:9.0
3,-4,1:9.0
4,-4,1:9.0
-5,-3,1:9.0
-4,-3,1:9.0
-3,-3,1:9.0
-2,-3,1:5.1
-1,-3,1:5.1
0,-3,1:9.0
1,-3,1:9.0
2,-3,1:9.0
3,-3,1:9.0
4,-3,1:9.0
-5,-2,1:9.0
-4,-2,1:9.0
-3,-2,1:5.1
-2,-2,1:18.14
-1,-2,1:18.14
0,-2,1:5.1
1,-2,1:5.1
2,-2,1:9.0
3,-2,1:9.0
4,-2,1:9.0
-5,-1,1:9.0
-4,-1,1:9.0
-3,-1,1:9.0
-2,-1,1:5.1
-1,-1,1:5.1
0,-1,1:18.14
1,-1,1:18.14
2,-1,1:5.1
3,-1,1:5.1
4,-1,1:9.0
-5,0,1:9.0
-4,0,1:9.0
-3,0,1:9.0
-2,0,1:5.1
-1,0,1:18.14
0,0,1:5.1
1,0,1:5.1
2,0,1:9.0
3,0,1:9.0
4,0,1:9.0
-5,1,1:9.0
-4,1,1:9.0
-3,1,1:9.0
-2,1,1:5.1
-1,1,1:18.14
0,1,1:5.1
1,1,1:9.0
2,1,1:9.0
3,1,1:9.0
4,1,1:9.0
-5,2,1:9.0
-4,2,1:9.0
-3,2,1:9.0
-2,2,1:9.0
-1,2,1:5.1
0,2,1:9.0
1,2,1:9.0
2,2,1:9.0
3,2,1:9.0
4,2,1:9.0
-5,3,1:9.0
-4,3,1:9.0
-3,3,1:9.0
-2,3,1:9.0
-1,3,1:5.1
0,3,1:9.0
1,3,1:9.0
2,3,1:9.0
3,3,1:9.0
4,3,1:9.0
-5,4,1:9.0
-4,4,1:9.0
-3,4,1:9.0
-2,4,1:9.0
-1,4,1:9.0
0,4,1:9.0
1,4,1:9.0
2,4,1:9.0
3,4,1:9.0
4,4,1:9.0
-5,-5,2:9.0
-4,-5,2:9.0
-3,-5,2:9.0
-2,-5,2:9.0
-1,-5,2:9.0
0,-5,2:9.0
1,-5,2:9.0
2,-5,2:9.0
3,-5,2:9.0
4,-5,2:9.0
-5,-4,2:9.0
-4,-4,2:9.0
-3,-4,2:9.0
-2,-4,2:9.0
-1,-4,2:9.0
0,-4,2:9.0
1,-4,2:9.0
2,-4,2:9.0
3,-4,2:9.0
4,-4,2:9.0
-5,-3,2:9.0
-4,-3,2:9.0
-3,-3,2:9.8
-2,-3,2:5.1
-1,-3,2:9.0
0,-3,2:9.0
1,-3,2:9.0
2,-3,2:9.0
3,-3,2:9.0
4,-3,2:9.0
-5,-2,2:9.0
-4,-2,2:9.0
-3,-2,2:18.14
-2,-2,2:18.14
-1,-2,2:9.0
0,-2,2:9.0
1,-2,2:9.0
2,-2,2:9.0
3,-2,2:9.0
4,-2,2:9.0
-5,-1,2:9.0
-4,-1,2:9.0
-3,-1,2:9.0
-2,-1,2:5.1
-1,-1,2:9.0
0,-1,2:9.0
1,-1,2:18.14
2,-1,2:5.1
3,-1,2:9.0
4,-1,2:9.0
-5,0,2:9.0
-4,0,2:9.0
-3,0,2:9.0
-2,0,2:9.0
-1,0,2:9.0
0,0,2:9.0
1,0,2:9.0
2,0,2:9.0
3,0,2:9.0
4,0,2:9.0
-5,1,2:9.0
-4,1,2:9.0
-3,1,2:9.0
-2,1,2:9.0
-1,1,2:18.14
0,1,2:9.0
1,1,2:9.0
2,1,2:9.0
3,1,2:9.0
4,1,2:9.0
-5,2,2:9.0
-4,2,2:9.0
-3,2,2:9.0
-2,2,2:9.0
-1,2,2:5.1
0,2,2:9.0
1,2,2:9.0
2,2,2:9.0
3,2,2:9.0
4,2,2:9.0
-5,3,2:9.0
-4,3,2:9.0
-3,3,2:9.0
-2,3,2:9.0
-1,3,2:9.0
0,3,2:9.0
1,3,2:9.0
2,3,2:9.0
3,3,2:9.0
4,3,2:9.0
-5,4,2:9.8
-4,4,2:9.0
-3,4,2:9.0
-2,4,2:9.0
-1,4,2:9.0
0,4,2:9.0
1,4,2:9.0
2,4,2:9.0
3,4,2:9.0
4,4,2:9.0
-5,-5,3:9.0
-4,-5,3:9.0
-3,-5,3:9.0
-2,-5,3:9.8
-1,-5,3:9.0
0,-5,3:9.0
1,-5,3:9.0
2,-5,3:9.0
3,-5,3:9.0
4,-5,3:9.0
-5,-4,3:9.0
-4,-4,3:9.0
-3,-4,3:9.0
-2,-4,3:9.0
-1,-4,3:9.0
0,-4,3:9.0
1,-4,3:9.0
2,-4,3:9.0
3,-4,3:9.0
4,-4,3:9.0
-5,-3,3:9.0
-4,-3,3:9.0
-3,-3,3:9.8
-2,-3,3:9.0
-1,-3,3:9.0
0,-3,3:9.0
1,-3,3:9.0
2,-3,3:9.0
3,-3,3:9.0
4,-3,3:9.0
-5,-2,3:9.0
-4,-2,3:9.0
-3,-2,3:18.14
-2,-2,3:9.0
-1,-2,3:9.0
0,-2,3:9.0
1,-2,3:9.0
2,-2,3:9.0
3,-2,3:9.0
4,-2,3:9.0
-5,-1,3:9.0
-4,-1,3:9.0
-3,-1,3:9.0
-2,-1,3:9.0
-1,-1,3:9.0
0,-1,3:9.8
1,-1,3:18.14
2,-1,3:9.0
3,-1,3:9.0
4,-1,3:9.0
-5,0,3:9.0
-4,0,3:9.0
-3,0,3:9.0
-2,0,3:9.0
-1,0,3:9.0
0,0,3:9.0
1,0,3:9.1
2,0,3:9.0
3,0,3:9.0
4,0,3:9.0
-5,1,3:9.0
-4,1,3:9.0
-3,1,3:9.0
-2,1,3:9.0
-1,1,3:18.14
0,1,3:9.0
1,1,3:9.0
2,1,3:9.0
3,1,3:9.0
4,1,3:9.0
-5,2,3:9.0
-4,2,3:9.0
-3,2,3:9.0
-2,2,3:9.0
-1,2,3:9.0
0,2,3:9.0
1,2,3:9.0
2,2,3:9.0
3,2,3:9.0
4,2,3:9.0
-5,3,3:9.0
-4,3,3:9.0
-3,3,3:9.0
-2,3,3:9.0
-1,3,3:9.0
0,3,3:9.0
1,3,3:9.0
2,3,3:9.0
3,3,3:9.0
4,3,3:9.0
-5,4,3:9.0
-4,4,3:9.0
-3,4,3:9.0
-2,4,3:9.0
-1,4,3:9.0
0,4,3:9.0
1,4,3:9.0
2,4,3:9.0
3,4,3:9.0
4,4,3:9.0
-5,-5,4:9.8
-4,-5,4:9.0
-3,-5,4:9.0
-2,-5,4:9.0
-1,-5,4:9.0
0,-5,4:9.0
1,-5,4:9.0
2,-5,4:9.0
3,-5,4:9.0
4,-5,4:9.0
-5,-4,4:9.0
-4,-4,4:9.0
-3,-4,4:9.0
-2,-4,4:9.0
-1,-4,4:9.0
0,-4,4:9.0
1,-4,4:9.0
2,-4,4:9.0
3,-4,4:9.0
4,-4,4:9.0
-5,-3,4:9.0
-4,-3,4:9.0
-3,-3,4:9.0
-2,-3,4:9.0
-1,-3,4:9.0
0,-3,4:9.0
1,-3,4:9.0
2,-3,4:9.0
3,-3,4:9.0
4,-3,4:9.0
-5,-2,4:9.0
-4,-2,4:9.1
-3,-2,4:18.14
-2,-2,4:9.0
-1,-2,4:9.0
0,-2,4:18.14
1,-2,4:9.0
2,-2,4:9.0
3,-2,4:9.0
4,-2,4:9.0
-5,-1,4:9.0
-4,-1,4:9.0
-3,-1,4:9.0
-2,-1,4:9.0
-1,-1,4:9.0
0,-1,4:9.8
1,-1,4:9.0
2,-1,4:9.0
3,-1,4:9.0
4,-1,4:9.0
-5,0,4:9.0
-4,0,4:9.0
-3,0,4:9.0
-2,0,4:9.0
-1,0,4:9.0
0,0,4:9.0
1,0,4:18.14
2,0,4:9.0
3,0,4:9.0
4,0,4:9.0
-5,1,4:9.0
-4,1,4:9.0
-3,1,4:9.0
-2,1,4:9.1
-1,1,4:18.14
0,1,4:9.0
1,1,4:9.0
2,1,4:9.0
3,1,4:9.0
4,1,4:9.0
-5,2,4:9.0
-4,2,4:9.0
-3,2,4:9.0
-2,2,4:9.0
-1,2,4:9.0
0,2,4:9.0
1,2,4:9.0
2,2,4:9.0
3,2,4:9.0
4,2,4:9.0
-5,3,4:9.0
-4,3,4:9.0
-3,3,4:9.0
-2,3,4:9.0
-1,3,4:9.0
0,3,4:9.0
1,3,4:9.0
2,3,4:9.0
3,3,4:9.0
4,3,4:9.0
-5,4,4:9.8
-4,4,4:9.0
-3,4,4:9.0
-2,4,4:9.0
-1,4,4:9.0
0,4,4:9.0
1,4,4:9.0
2,4,4:9.0
3,4,4:9.0
4,4,4:9.0
-5,-5,5:9.8
-4,-5,5:9.0
-3,-5,5:9.0
-2,-5,5:9.0
-1,-5,5:9.0
0,-5,5:9.0
1,-5,5:9.0
2,-5,5:9.0
3,-5,5:9.0
4,-5,5:9.0
-5,-4,5:9.0
-4,-4,5:9.0
-3,-4,5:9.0
-2,-4,5:9.0
-1,-4,5:9.0
0,-4,5:9.0
1,-4,5:9.0
2,-4,5:9.0
3,-4,5:9.0
4,-4,5:9.0
-5,-3,5:9.0
-4,-3,5:9.8
-3,-3,5:18.14
-2,-3,5:9.0
-1,-3,5:9.0
0,-3,5:9.0
1,-3,5:9.0
2,-3,5:9.0
3,-3,5:9.0
4,-3,5:9.0
-5,-2,5:9.0
-4,-2,5:18.14
-3,-2,5:9.0
-2,-2,5:9.0
-1,-2,5:9.0
0,-2,5:18.14
1,-2,5:9.1
2,-2,5:9.0
3,-2,5:9.0
4,-2,5:9.0
-5,-1,5:9.0
-4,-1,5:9.0
-3,-1,5:9.0
-2,-1,5:9.0
-1,-1,5:9.0
0,-1,5:9.0
1,-1,5:9.0
2,-1,5:9.0
3,-1,5:9.0
4,-1,5:9.0
-5,0,5:9.0
-4,0,5:9.0
-3,0,5:18.14
-2,0,5:9.0
-1,0,5:9.0
0,0,5:18.14
1,0,5:9.0
2,0,5:9.0
3,0,5:9.0
4,0,5:9.0
-5,1,5:9.0
-4,1,5:9.0
-3,1,5:9.8
-2,1,5:18.14
-1,1,5:9.0
0,1,5:9.0
1,1,5:9.0
2,1,5:9.0
3,1,5:9.0
4,1,5:9.0
-5,2,5:9.0
-4,2,5:9.0
-3,2,5:9.0
-2,2,5:18.14
-1,2,5:9.0
0,2,5:9.0
1,2,5:9.0
2,2,5:9.0
3,2,5:9.0
4,2,5:9.0
-5,3,5:9.0
-4,3,5:9.0
-3,3,5:9.0
-2,3,5:9.0
-1,3,5:9.0
0,3,5:9.0
1,3,5:9.0
2,3,5:9.0
3,3,5:9.0
4,3,5:9.0
-5,4,5:9.8
-4,4,5:9.0
-3,4,5:9.0
-2,4,5:9.0
-1,4,5:9.0
0,4,5:9.0
1,4,5:9.0
2,4,5:9.0
3,4,5:9.0
4,4,5:9.0
-5,-5,6:9.8
-4,-5,6:9.0
-3,-5,6:9.0
-2,-5,6:9.0
-1,-5,6:9.0
0,-5,6:9.0
1,-5,6:9.0
2,-5,6:9.0
3,-5,6:9.0
4,-5,6:9.0
-5,-4,6:9.0
-4,-4,6:9.0
-3,-4,6:9.0
-2,-4,6:9.0
-1,-4,6:9.0
0,-4,6:9.0
1,-4,6:9.0
2,-4,6:9.0
3,-4,6:9.0
4,-4,6:9.0
-5,-3,6:9.0
-4,-3,6:9.0
-3,-3,6:9.0
-2,-3,6:9.0
-1,-3,6:9.0
0,-3,6:9.0
1,-3,6:9.8
2,-3,6:9.0
3,-3,6:9.0
4,-3,6:9.0
-5,-2,6:9.0
-4,-2,6:18.14
-3,-2,6:9.0
-2,-2,6:9.0
-1,-2,6:9.0
0,-2,6:9.0
1,-2,6:18.14
2,-2,6:9.0
3,-2,6:9.0
4,-2,6:9.0
-5,-1,6:9.0
-4,-1,6:9.0
-3,-1,6:9.0
-2,-1,6:9.0
-1,-1,6:9.0
0,-1,6:9.0
1,-1,6:9.0
2,-1,6:9.0
3,-1,6:9.0
4,-1,6:9.0
-5,0,6:9.0
-4,0,6:9.0
-3,0,6:18.14
-2,0,6:9.0
-1,0,6:9.0
0,0,6:18.6
1,0,6:9.0
2,0,6:9.0
3,0,6:9.0
4,0,6:9.0
-5,1,6:9.0
-4,1,6:9.0
-3,1,6:9.0
-2,1,6:9.0
-1,1,6:9.0
0,1,6:9.0
1,1,6:9.0
2,1,6:9.0
3,1,6:9.0
4,1,6:9.0
-5,2,6:9.0
-4,2,6:9.0
-3,2,6:9.1
-2,2,6:9.0
-1,2,6:9.0
0,2,6:9.0
1,2,6:9.0
2,2,6:9.0
3,2,6:9.0
4,2,6:9.0
-5,3,6:9.0
-4,3,6:9.0
-3,3,6:9.0
-2,3,6:18.14
-1,3,6:9.0
0,3,6:9.0
1,3,6:9.0
2,3,6:9.0
3,3,6:9.0
4,3,6:9.0
-5,4,6:9.0
-4,4,6:9.0
-3,4,6:9.0
-2,4,6:9.0
-1,4,6:9.0
0,4,6:9.0
1,4,6:9.0
2,4,6:9.0
3,4,6:9.0
4,4,6:9.0
-5,-5,7:9.8
-4,-5,7:9.0
-3,-5,7:9.0
-2,-5,7:9.0
-1,-5,7:9.0
0,-5,7:9.0
1,-5,7:9.0
2,-5,7:9.0
3,-5,7:9.0
4,-5,7:9.0
-5,-4,7:9.0
-4,-4,7:9.0
-3,-4,7:9.0
-2,-4,7:9.0
-1,-4,7:9.0
0,-4,7:9.0
1,-4,7:9.0
2,-4,7:9.0
3,-4,7:9.0
4,-4,7:9.0
-5,-3,7:9.0
-4,-3,7:9.0
-3,-3,7:9.0
-2,-3,7:9.0
-1,-3,7:9.0
0,-3,7:9.0
1,-3,7:9.0
2,-3,7:9.0
3,-3,7:9.0
4,-3,7:9.0
-5,-2,7:9.0
-4,-2,7:9.0
-3,-2,7:9.0
-2,-2,7:9.0
-1,-2,7:9.0
0,-2,7:9.0
1,-2,7:18.14
2,-2,7:9.0
3,-2,7:9.0
4,-2,7:9.0
-5,-1,7:9.0
-4,-1,7:9.0
-3,-1,7:9.0
-2,-1,7:9.0
-1,-1,7:9.0
0,-1,7:9.0
1,-1,7:9.0
2,-1,7:9.0
3,-1,7:9.0
4,-1,7:9.0
-5,0,7:9.0
-4,0,7:9.0
-3,0,7:18.14
-2,0,7:9.0
-1,0,7:9.0
0,0,7:9.0
1,0,7:9.0
2,0,7:9.0
3,0,7:9.0
4,0,7:9.0
-5,1,7:9.0
-4,1,7:9.0
-3,1,7:9.0
-2,1,7:9.0
-1,1,7:9.0
0,1,7:9.0
1,1,7:9.0
2,1,7:9.0
3,1,7:9.0
4,1,7:9.0
-5,2,7:9.0
-4,2,7:9.0
-3,2,7:18.14
-2,2,7:9.0
-1,2,7:9.0
0,2,7:9.0
1,2,7:9.0
2,2,7:9.0
3,2,7:9.0
4,2,7:9.0
-5,3,7:9.0
-4,3,7:9.0
-3,3,7:9.8
-2,3,7:18.14
-1,3,7:18.14
0,3,7:9.0
1,3,7:9.0
2,3,7:9.0
3,3,7:9.0
4,3,7:9.0
-5,4,7:9.8
-4,4,7:9.0
-3,4,7:9.0
-2,4,7:9.0
-1,4,7:9.0
0,4,7:9.0
1,4,7:9.0
2,4,7:9.0
3,4,7:9.0
4,4,7:9.0
-5,-5,8:9.8
-4,-5,8:9.0
-3,-5,8:9.0
-2,-5,8:9.0
-1,-5,8:9.0
0,-5,8:9.0
1,-5,8:9.0
2,-5,8:9.0
3,-5,8:9.0
4,-5,8:9.0
-5,-4,8:9.0
-4,-4,8:9.0
-3,-4,8:9.0
-2,-4,8:9.0
-1,-4,8:9.0
0,-4,8:9.0
1,-4,8:9.0
2,-4,8:9.0
3,-4,8:9.0
4,-4,8:9.0
-5,-3,8:9.0
-4,-3,8:9.0
-3,-3,8:9.0
-2,-3,8:9.0
-1,-3,8:9.0
0,-3,8:9.0
1,-3,8:9.0
2,-3,8:9.0
3,-3,8:9.0
4,-3,8:9.0
-5,-2,8:9.0
-4,-2,8:9.0
-3,-2,8:9.0
-2,-2,8:9.0
-1,-2,8:9.0
0,-2,8:9.0
1,-2,8:9.0
2,-2,8:9.0
3,-2,8:9.0
4,-2,8:9.0
-5,-1,8:9.0
-4,-1,8:9.0
-3,-1,8:18.14
-2,-1,8:9.0
-1,-1,8:9.0
0,-1,8:9.0
1,-1,8:9.0
2,-1,8:9.0
3,-1,8:9.0
4,-1,8:9.0
-5,0,8:9.0
-4,0,8:9.0
-3,0,8:9.0
-2,0,8:9.0
-1,0,8:9.0
0,0,8:9.0
1,0,8:9.0
2,0,8:9.0
3,0,8:9.0
4,0,8:9.0
-5,1,8:9.0
-4,1,8:9.0
-3,1,8:9.0
-2,1,8:9.0
-1,1,8:9.0
0,1,8:9.0
1,1,8:9.0
2,1,8:9.0
3,1,8:9.0
4,1,8:9.0
-5,2,8:9.0
-4,2,8:18.14
-3,2,8:9.0
-2,2,8:9.0
-1,2,8:9.0
0,2,8:9.0
1,2,8:9.0
2,2,8:9.0
3,2,8:9.0
4,2,8:9.0
-5,3,8:9.0
-4,3,8:9.0
-3,3,8:9.0
-2,3,8:9.0
-1,3,8:18.14
0,3,8:9.0
1,3,8:9.0
2,3,8:9.0
3,3,8:9.0
4,3,8:9.0
-5,4,8:9.8
-4,4,8:9.0
-3,4,8:9.0
-2,4,8:9.0
-1,4,8:9.0
0,4,8:9.0
1,4,8:9.0
2,4,8:9.0
3,4,8:9.0
4,4,8:9.0
