[META]
version=2.0
spawnOnBlockType=1
spawnSunlight=false
spawnDarkness=True
spawnWater=False
spawnLava=False
spawnAboveGround=False
spawnUnderGround=true
underFill=false
randomRotation=True
dig=True
tree=False
branch=False
needsFoundation=true
rarity=600
collisionPercentage=10
collisionBlockType=1
spawnElevationMin=6
spawnElevationMax=55
spawnInBiome=Beach,Desert,DesertHills,DesertOasis,Extreme Hills Edge, Extreme Hills, Forest,ForestHills,FrozenOcean,FrozenRiver,Glacier,Ice Mountains,Ice Plains,Jungle,JungleHills,Ocean2,Ocean,Plains,River2,River,Summits2,Summits,Swampland,Taiga,TaigaHills,Urwald2,Urwald
[DATA]
-1,0,2:121.0
-1,-1,3:121.0
-2,0,3:121.0
-1,0,3:9.0
0,0,3:121.0
-1,1,3:121.0
-1,-2,4:121.0
-2,-1,4:121.0
-1,-1,4:121.0
0,-1,4:121.0
-3,0,4:121.0
-2,0,4:121.0
-1,0,4:121.0
0,0,4:121.0
1,0,4:121.0
-2,1,4:121.0
-1,1,4:121.0
0,1,4:121.0
-1,2,4:121.0
-2,2,4:121.4
-3,1,4:121.8
1,-1,4:121.1
-3,-1,4:121.1
-2,-2,4:121.1
-1,-3,4:121.1
-1,2,3:121.4
-2,2,3:121.4
-2,1,3:121.8
1,0,3:121.2
0,-1,3:121.1
-1,1,2:121.4
1,0,2:121.2
0,0,2:121.2
-2,0,2:121.8
0,-1,2:121.1
-1,-1,2:121.1
0,0,1:121.2
-2,0,1:121.8
