[META]
version=2.0
spawnOnBlockType=12,1,3
spawnSunlight=True
spawnDarkness=True
spawnWater=True
spawnLava=False
underFill=True
randomRotation=True
spawnAboveGround=True
dig=true
tree=False
branch=False
needsFoundation=True
rarity=200
collisionPercentage=1
spawnElevationMin=30
spawnElevationMax=50
spawnInBiome=Ocean,Ocean2,FrozenOcean
[DATA]
-4,-2,0:12.0
-3,-2,0:12.0
-2,-2,0:12.0
-1,-2,0:12.0
0,-2,0:12.0
-4,-1,0:12.0
-3,-1,0:12.0
-2,-1,0:12.0
-1,-1,0:12.0
0,-1,0:12.0
-4,0,0:12.0
-3,0,0:12.0
-2,0,0:12.0
-1,0,0:12.0
0,0,0:12.0
-4,1,0:12.0
-3,1,0:12.0
-2,1,0:12.0
-1,1,0:12.0
0,1,0:12.0
-4,2,0:12.0
-3,2,0:12.0
-2,2,0:12.0
-1,2,0:12.0
0,2,0:12.0
-4,3,0:12.0
-3,3,0:12.0
-2,3,0:12.0
-1,3,0:12.0
0,3,0:12.0
-4,4,0:12.0
-3,4,0:12.0
-2,4,0:12.0
-1,4,0:12.0
0,4,0:12.0
-4,5,0:12.0
-3,5,0:12.0
-2,5,0:12.0
-1,5,0:12.0
0,5,0:12.0
-4,6,0:12.0
-3,6,0:12.0
-2,6,0:12.0
-1,6,0:12.0
0,6,0:12.0
-4,-2,1:9.0
-3,-2,1:9.0
-2,-2,1:9.0
-1,-2,1:9.0
0,-2,1:9.0
-4,-1,1:9.0
-3,-1,1:18.3
-2,-1,1:18.3
-1,-1,1:9.0
0,-1,1:9.0
-4,0,1:18.15
-3,0,1:9.0
-2,0,1:17.3
-1,0,1:18.3
0,0,1:9.0
-4,1,1:18.3
-3,1,1:17.3
-2,1,1:17.3
-1,1,1:18.15
0,1,1:9.0
-4,2,1:18.15
-3,2,1:17.3
-2,2,1:17.3
-1,2,1:18.15
0,2,1:9.0
-4,3,1:18.15
-3,3,1:18.15
-2,3,1:18.3
-1,3,1:18.15
0,3,1:9.0
-4,4,1:9.0
-3,4,1:18.15
-2,4,1:18.15
-1,4,1:18.7
0,4,1:9.0
-4,5,1:9.0
-3,5,1:18.15
-2,5,1:18.15
-1,5,1:9.0
0,5,1:9.0
-4,6,1:9.0
-3,6,1:9.0
-2,6,1:9.0
-1,6,1:9.0
0,6,1:9.0
-4,-2,2:9.0
-3,-2,2:9.0
-2,-2,2:9.0
-1,-2,2:9.0
0,-2,2:9.8
-4,-1,2:9.0
-3,-1,2:9.0
-2,-1,2:9.0
-1,-1,2:9.0
0,-1,2:9.0
-4,0,2:9.0
-3,0,2:18.3
-2,0,2:18.15
-1,0,2:9.0
0,0,2:9.0
-4,1,2:9.0
-3,1,2:18.15
-2,1,2:18.3
-1,1,2:9.0
0,1,2:9.0
-4,2,2:9.0
-3,2,2:18.15
-2,2,2:18.15
-1,2,2:18.15
0,2,2:9.0
-4,3,2:9.0
-3,3,2:18.3
-2,3,2:18.3
-1,3,2:9.0
0,3,2:9.0
-4,4,2:9.0
-3,4,2:9.0
-2,4,2:9.0
-1,4,2:9.0
0,4,2:9.0
-4,5,2:9.0
-3,5,2:9.0
-2,5,2:9.0
-1,5,2:9.0
0,5,2:9.0
-4,6,2:9.0
-3,6,2:9.0
-2,6,2:9.0
-1,6,2:9.0
0,6,2:9.0
-4,-2,3:9.0
-3,-2,3:9.0
-2,-2,3:9.0
-1,-2,3:9.0
0,-2,3:9.8
-4,-1,3:9.0
-3,-1,3:9.0
-2,-1,3:9.0
-1,-1,3:9.0
0,-1,3:9.0
-4,0,3:9.0
-3,0,3:9.0
-2,0,3:9.0
-1,0,3:9.0
0,0,3:9.0
-4,1,3:9.0
-3,1,3:18.7
-2,1,3:9.0
-1,1,3:9.0
0,1,3:9.0
-4,2,3:9.0
-3,2,3:9.0
-2,2,3:18.15
-1,2,3:9.0
0,2,3:9.0
-4,3,3:9.0
-3,3,3:9.0
-2,3,3:9.0
-1,3,3:9.0
0,3,3:9.0
-4,4,3:9.0
-3,4,3:9.0
-2,4,3:9.0
-1,4,3:9.0
0,4,3:9.0
-4,5,3:9.0
-3,5,3:9.0
-2,5,3:9.0
-1,5,3:9.0
0,5,3:9.0
-4,6,3:9.0
-3,6,3:9.0
-2,6,3:9.0
-1,6,3:9.0
0,6,3:9.0
